<?xml version="1.0" ?>
<!-- Generated using onshape-to-robot -->
<!-- Onshape document_id: 821537de265f690cd6a7463f -->
<mujoco model="project1">
  <compiler angle="radian" meshdir="assets" autolimits="true"/>
  <default>
    <default class="project1">
      <joint frictionloss="0.1" armature="0.005"/>
      <position kp="50" dampratio="1"/>
      <default class="visual">
        <geom type="mesh" contype="0" conaffinity="0" group="2"/>
      </default>
      <default class="collision">
        <geom group="3"/>
      </default>
    </default>
  </default>
  <worldbody>
    <!-- Link torso_kidsize25 -->
    <body name="torso_kidsize25" pos="0 0 0" quat="1 0 0 0" childclass="project1">
      <freejoint name="torso_kidsize25_freejoint"/>
      <inertial pos="0.103344 0.0750782 0.0323184" mass="2.16719" fullinertia="0.00982507 0.00929033 0.00934245 -9.38024e-07 0.000706149 8.09787e-07"/>
      <!-- Part mx_64t_mir1 -->
      <geom type="mesh" class="visual" pos="0.0981628 0.0255728 0.0855046" quat="6.65327e-15 0.707107 -0.707107 2.95374e-15" mesh="mx_64t_mir1" material="mx_64t_mir1_material"/>
      <geom type="mesh" class="collision" pos="0.0981628 0.0255728 0.0855046" quat="6.65327e-15 0.707107 -0.707107 2.95374e-15" mesh="mx_64t_mir1" material="mx_64t_mir1_material"/>
      <!-- Part mx_64t -->
      <geom type="mesh" class="visual" pos="0.0981644 0.124573 0.0855046" quat="0.707107 -2.94881e-15 6.43929e-15 0.707107" mesh="mx_64t" material="mx_64t_material"/>
      <geom type="mesh" class="collision" pos="0.0981644 0.124573 0.0855046" quat="0.707107 -2.94881e-15 6.43929e-15 0.707107" mesh="mx_64t" material="mx_64t_material"/>
      <!-- Part mx_28 -->
      <geom type="mesh" class="visual" pos="0.167821 0.118573 -0.0392008" quat="7.48372e-15 0.707107 -5.32907e-15 -0.707107" mesh="mx_28" material="mx_28_material"/>
      <geom type="mesh" class="collision" pos="0.167821 0.118573 -0.0392008" quat="7.48372e-15 0.707107 -5.32907e-15 -0.707107" mesh="mx_28" material="mx_28_material"/>
      <!-- Part mx_28_2 -->
      <geom type="mesh" class="visual" pos="0.0625405 0.0828915 -0.0259091" quat="0.5 0.5 0.5 0.5" mesh="mx_28" material="mx_28_material"/>
      <geom type="mesh" class="collision" pos="0.0625405 0.0828915 -0.0259091" quat="0.5 0.5 0.5 0.5" mesh="mx_28" material="mx_28_material"/>
      <!-- Part mx_28_3 -->
      <geom type="mesh" class="visual" pos="0.167821 0.0315724 -0.02339" quat="0.707107 -3.13102e-15 -0.707107 4.94049e-15" mesh="mx_28" material="mx_28_material"/>
      <geom type="mesh" class="collision" pos="0.167821 0.0315724 -0.02339" quat="0.707107 -3.13102e-15 -0.707107 4.94049e-15" mesh="mx_28" material="mx_28_material"/>
      <!-- Part upper_floor -->
      <geom type="mesh" class="visual" pos="0.145966 0.139451 -0.0104954" quat="0.707107 0.707107 2.33147e-15 -1.42866e-15" mesh="upper_floor" material="upper_floor_material"/>
      <geom type="mesh" class="collision" pos="0.145966 0.139451 -0.0104954" quat="0.707107 0.707107 2.33147e-15 -1.42866e-15" mesh="upper_floor" material="upper_floor_material"/>
      <!-- Part 2nd_floor -->
      <geom type="mesh" class="visual" pos="0.145966 0.0106948 0.0585046" quat="1.38778e-15 2.42809e-15 -0.707107 0.707107" mesh="2nd_floor" material="2nd_floor_material"/>
      <geom type="mesh" class="collision" pos="0.145966 0.0106948 0.0585046" quat="1.38778e-15 2.42809e-15 -0.707107 0.707107" mesh="2nd_floor" material="2nd_floor_material"/>
      <!-- Part front_pillar -->
      <geom type="mesh" class="visual" pos="0.0369649 0.147073 0.0505046" quat="0.5 -0.5 0.5 -0.5" mesh="front_pillar" material="front_pillar_material"/>
      <geom type="mesh" class="collision" pos="0.0369649 0.147073 0.0505046" quat="0.5 -0.5 0.5 -0.5" mesh="front_pillar" material="front_pillar_material"/>
      <!-- Part front_pillar_2 -->
      <geom type="mesh" class="visual" pos="0.0439649 0.00307279 0.0505046" quat="0.5 -0.5 -0.5 0.5" mesh="front_pillar" material="front_pillar_material"/>
      <geom type="mesh" class="collision" pos="0.0439649 0.00307279 0.0505046" quat="0.5 -0.5 -0.5 0.5" mesh="front_pillar" material="front_pillar_material"/>
      <!-- Part front_pillar_3 -->
      <geom type="mesh" class="visual" pos="0.153965 0.00307279 0.0505046" quat="0.5 -0.5 -0.5 0.5" mesh="front_pillar" material="front_pillar_material"/>
      <geom type="mesh" class="collision" pos="0.153965 0.00307279 0.0505046" quat="0.5 -0.5 -0.5 0.5" mesh="front_pillar" material="front_pillar_material"/>
      <!-- Part front_pillar_4 -->
      <geom type="mesh" class="visual" pos="0.146965 0.147073 -0.00249543" quat="0.707107 0.707107 2.55351e-15 -1.39847e-15" mesh="front_pillar" material="front_pillar_material"/>
      <geom type="mesh" class="collision" pos="0.146965 0.147073 -0.00249543" quat="0.707107 0.707107 2.55351e-15 -1.39847e-15" mesh="front_pillar" material="front_pillar_material"/>
      <!-- Part pcnel_exch -->
      <geom type="mesh" class="visual" pos="0.0974649 0.0750728 -0.00749543" quat="0.707107 0.707107 2.33147e-15 -1.48836e-15" mesh="pcnel_exch" material="pcnel_exch_material"/>
      <geom type="mesh" class="collision" pos="0.0974649 0.0750728 -0.00749543" quat="0.707107 0.707107 2.33147e-15 -1.48836e-15" mesh="pcnel_exch" material="pcnel_exch_material"/>
      <!-- Part spacer_bracket_id_1_19_2_mir -->
      <geom type="mesh" class="visual" pos="0.124012 0.0383861 -0.0282569" quat="0.5 -0.5 -0.5 0.5" mesh="spacer_bracket_id_1_19_2_mir" material="spacer_bracket_id_1_19_2_mir_material"/>
      <geom type="mesh" class="collision" pos="0.124012 0.0383861 -0.0282569" quat="0.5 -0.5 -0.5 0.5" mesh="spacer_bracket_id_1_19_2_mir" material="spacer_bracket_id_1_19_2_mir_material"/>
      <!-- Part handle_bracket_kidsize -->
      <geom type="mesh" class="visual" pos="0.074666 0.00707279 -0.0144954" quat="0.707107 0.707107 2.22045e-15 -1.60109e-15" mesh="handle_bracket_kidsize" material="handle_bracket_kidsize_material"/>
      <geom type="mesh" class="collision" pos="0.074666 0.00707279 -0.0144954" quat="0.707107 0.707107 2.22045e-15 -1.60109e-15" mesh="handle_bracket_kidsize" material="handle_bracket_kidsize_material"/>
      <!-- Part almi_5mm_bracket_servo_1_2_left -->
      <geom type="mesh" class="visual" pos="0.128758 0.0339361 -0.0333577" quat="0.5 -0.5 -0.5 0.5" mesh="almi_5mm_bracket_servo_1_2_left" material="almi_5mm_bracket_servo_1_2_left_material"/>
      <geom type="mesh" class="collision" pos="0.128758 0.0339361 -0.0333577" quat="0.5 -0.5 -0.5 0.5" mesh="almi_5mm_bracket_servo_1_2_left" material="almi_5mm_bracket_servo_1_2_left_material"/>
      <!-- Part handle -->
      <geom type="mesh" class="visual" pos="0.025166 0.0750728 -0.0674949" quat="0.5 -0.5 -0.5 -0.5" mesh="handle" material="handle_material"/>
      <geom type="mesh" class="collision" pos="0.025166 0.0750728 -0.0674949" quat="0.5 -0.5 -0.5 -0.5" mesh="handle" material="handle_material"/>
      <!-- Part holder_bumper_upper -->
      <geom type="mesh" class="visual" pos="0.0210947 0.141786 -0.0837461" quat="0.5 -0.5 -0.5 0.5" mesh="holder_bumper_upper" material="holder_bumper_upper_material"/>
      <geom type="mesh" class="collision" pos="0.0210947 0.141786 -0.0837461" quat="0.5 -0.5 -0.5 0.5" mesh="holder_bumper_upper" material="holder_bumper_upper_material"/>
      <!-- Part handler_holder_siber -->
      <geom type="mesh" class="visual" pos="0.142666 0.133573 0.027505" quat="1.66533e-15 2.09755e-15 -0.707107 0.707107" mesh="handler_holder_siber" material="handler_holder_siber_material"/>
      <geom type="mesh" class="collision" pos="0.142666 0.133573 0.027505" quat="1.66533e-15 2.09755e-15 -0.707107 0.707107" mesh="handler_holder_siber" material="handler_holder_siber_material"/>
      <!-- Part bracket_1_2_lower_left -->
      <geom type="mesh" class="visual" pos="0.129015 0.00858607 -0.0350437" quat="0.5 -0.5 0.5 -0.5" mesh="bracket_1_2_lower_left" material="bracket_1_2_lower_left_material"/>
      <geom type="mesh" class="collision" pos="0.129015 0.00858607 -0.0350437" quat="0.5 -0.5 0.5 -0.5" mesh="bracket_1_2_lower_left" material="bracket_1_2_lower_left_material"/>
      <!-- Part front_upper_bumper -->
      <geom type="mesh" class="visual" pos="0.174531 0.146286 -0.0308954" quat="0.5 -0.5 0.5 -0.5" mesh="front_upper_bumper" material="front_upper_bumper_material"/>
      <geom type="mesh" class="collision" pos="0.174531 0.146286 -0.0308954" quat="0.5 -0.5 0.5 -0.5" mesh="front_upper_bumper" material="front_upper_bumper_material"/>
      <!-- Part petg_5_19_mx28_seating -->
      <geom type="mesh" class="visual" pos="0.140931 0.0625825 -0.0177454" quat="0.5 0.5 -0.5 -0.5" mesh="petg_5_19_mx28_seating" material="petg_5_19_mx28_seating_material"/>
      <geom type="mesh" class="collision" pos="0.140931 0.0625825 -0.0177454" quat="0.5 0.5 -0.5 -0.5" mesh="petg_5_19_mx28_seating" material="petg_5_19_mx28_seating_material"/>
      <!-- Part almi_5mm_bracket_servo_1_2 -->
      <geom type="mesh" class="visual" pos="0.128758 0.11621 -0.0333577" quat="0.5 -0.5 0.5 -0.5" mesh="almi_5mm_bracket_servo_1_2" material="almi_5mm_bracket_servo_1_2_material"/>
      <geom type="mesh" class="collision" pos="0.128758 0.11621 -0.0333577" quat="0.5 -0.5 0.5 -0.5" mesh="almi_5mm_bracket_servo_1_2" material="almi_5mm_bracket_servo_1_2_material"/>
      <!-- Part spacer_bracket_id_1_19_2 -->
      <geom type="mesh" class="visual" pos="0.124012 0.11176 -0.0282569" quat="0.5 -0.5 0.5 -0.5" mesh="spacer_bracket_id_1_19_2" material="spacer_bracket_id_1_19_2_material"/>
      <geom type="mesh" class="collision" pos="0.124012 0.11176 -0.0282569" quat="0.5 -0.5 0.5 -0.5" mesh="spacer_bracket_id_1_19_2" material="spacer_bracket_id_1_19_2_material"/>
      <!-- Part handler_holder_siber_2 -->
      <geom type="mesh" class="visual" pos="0.142666 0.00657279 0.027505" quat="1.9984e-15 1.75899e-15 -0.707107 0.707107" mesh="handler_holder_siber" material="handler_holder_siber_material"/>
      <geom type="mesh" class="collision" pos="0.142666 0.00657279 0.027505" quat="1.9984e-15 1.75899e-15 -0.707107 0.707107" mesh="handler_holder_siber" material="handler_holder_siber_material"/>
      <!-- Part front_upper_bumper_mir -->
      <geom type="mesh" class="visual" pos="0.174531 0.00408607 -0.0308954" quat="0.5 -0.5 -0.5 0.5" mesh="front_upper_bumper_mir" material="front_upper_bumper_mir_material"/>
      <geom type="mesh" class="collision" pos="0.174531 0.00408607 -0.0308954" quat="0.5 -0.5 -0.5 0.5" mesh="front_upper_bumper_mir" material="front_upper_bumper_mir_material"/>
      <!-- Part handle_bracket_kidsize_2 -->
      <geom type="mesh" class="visual" pos="0.074666 0.143073 -0.0144954" quat="0.707107 0.707107 2.22045e-15 -1.49305e-15" mesh="handle_bracket_kidsize" material="handle_bracket_kidsize_material"/>
      <geom type="mesh" class="collision" pos="0.074666 0.143073 -0.0144954" quat="0.707107 0.707107 2.22045e-15 -1.49305e-15" mesh="handle_bracket_kidsize" material="handle_bracket_kidsize_material"/>
      <!-- Part bracket_1_2_lower -->
      <geom type="mesh" class="visual" pos="0.129015 0.14156 -0.0350437" quat="0.5 -0.5 -0.5 0.5" mesh="bracket_1_2_lower" material="bracket_1_2_lower_material"/>
      <geom type="mesh" class="collision" pos="0.129015 0.14156 -0.0350437" quat="0.5 -0.5 -0.5 0.5" mesh="bracket_1_2_lower" material="bracket_1_2_lower_material"/>
      <!-- Part bumper_front_lower_mir -->
      <geom type="mesh" class="visual" pos="0.177163 0.00657279 0.0805404" quat="0.5 -0.5 -0.5 0.5" mesh="bumper_front_lower_mir" material="bumper_front_lower_mir_material"/>
      <geom type="mesh" class="collision" pos="0.177163 0.00657279 0.0805404" quat="0.5 -0.5 -0.5 0.5" mesh="bumper_front_lower_mir" material="bumper_front_lower_mir_material"/>
      <!-- Part spacer_106_64_mir2 -->
      <geom type="mesh" class="visual" pos="0.123822 0.122909 0.0685046" quat="0.707107 -5.28062e-15 0.707107 -4.35763e-15" mesh="spacer_106_64_mir2" material="spacer_106_64_mir2_material"/>
      <geom type="mesh" class="collision" pos="0.123822 0.122909 0.0685046" quat="0.707107 -5.28062e-15 0.707107 -4.35763e-15" mesh="spacer_106_64_mir2" material="spacer_106_64_mir2_material"/>
      <!-- Part holder_lower_bracket_mir -->
      <geom type="mesh" class="visual" pos="0.148663 0.0342753 0.0388323" quat="0.5 0.5 0.5 0.5" mesh="holder_lower_bracket_mir" material="holder_lower_bracket_mir_material"/>
      <geom type="mesh" class="collision" pos="0.148663 0.0342753 0.0388323" quat="0.5 0.5 0.5 0.5" mesh="holder_lower_bracket_mir" material="holder_lower_bracket_mir_material"/>
      <!-- Part almi_2mm_floor_2nd__1 -->
      <geom type="mesh" class="visual" pos="0.0992116 0.0787323 0.102505" quat="0.5 0.5 -0.5 0.5" mesh="almi_2mm_floor_2nd__1" material="almi_2mm_floor_2nd__1_material"/>
      <geom type="mesh" class="collision" pos="0.0992116 0.0787323 0.102505" quat="0.5 0.5 -0.5 0.5" mesh="almi_2mm_floor_2nd__1" material="almi_2mm_floor_2nd__1_material"/>
      <!-- Part spacer_106_64_mir2_mir -->
      <geom type="mesh" class="visual" pos="0.12382 0.0272362 0.0685046" quat="5.18651e-15 0.707107 -4.55191e-15 -0.707107" mesh="spacer_106_64_mir2_mir" material="spacer_106_64_mir2_mir_material"/>
      <geom type="mesh" class="collision" pos="0.12382 0.0272362 0.0685046" quat="5.18651e-15 0.707107 -4.55191e-15 -0.707107" mesh="spacer_106_64_mir2_mir" material="spacer_106_64_mir2_mir_material"/>
      <!-- Part back_bumper -->
      <geom type="mesh" class="visual" pos="0.0544633 0.0103728 0.0815046" quat="1.44329e-15 2.29381e-15 -0.707107 0.707107" mesh="back_bumper" material="back_bumper_material"/>
      <geom type="mesh" class="collision" pos="0.0544633 0.0103728 0.0815046" quat="1.44329e-15 2.29381e-15 -0.707107 0.707107" mesh="back_bumper" material="back_bumper_material"/>
      <!-- Part xt_bracket -->
      <geom type="mesh" class="visual" pos="0.0414633 0.0442728 0.102505" quat="2.97397e-15 0.707107 0.707107 -6.63349e-15" mesh="xt_bracket" material="xt_bracket_material"/>
      <geom type="mesh" class="collision" pos="0.0414633 0.0442728 0.102505" quat="2.97397e-15 0.707107 0.707107 -6.63349e-15" mesh="xt_bracket" material="xt_bracket_material"/>
      <!-- Part battery_holder -->
      <geom type="mesh" class="visual" pos="0.153463 0.0750728 0.107505" quat="1.30451e-15 2.3257e-15 -0.707107 0.707107" mesh="battery_holder" material="battery_holder_material"/>
      <geom type="mesh" class="collision" pos="0.153463 0.0750728 0.107505" quat="1.30451e-15 2.3257e-15 -0.707107 0.707107" mesh="battery_holder" material="battery_holder_material"/>
      <!-- Part back_bumper_2 -->
      <geom type="mesh" class="visual" pos="0.0544633 0.139773 0.0815046" quat="2.10942e-15 -1.4894e-15 -0.707107 -0.707107" mesh="back_bumper" material="back_bumper_material"/>
      <geom type="mesh" class="collision" pos="0.0544633 0.139773 0.0815046" quat="2.10942e-15 -1.4894e-15 -0.707107 -0.707107" mesh="back_bumper" material="back_bumper_material"/>
      <!-- Part bracket_back_bumper -->
      <geom type="mesh" class="visual" pos="0.0524633 0.0298728 0.0805046" quat="0.5 -0.5 -0.5 0.5" mesh="bracket_back_bumper" material="bracket_back_bumper_material"/>
      <geom type="mesh" class="collision" pos="0.0524633 0.0298728 0.0805046" quat="0.5 -0.5 -0.5 0.5" mesh="bracket_back_bumper" material="bracket_back_bumper_material"/>
      <!-- Part holder_lower_bracket -->
      <geom type="mesh" class="visual" pos="0.148664 0.11587 0.0388323" quat="0.5 0.5 -0.5 -0.5" mesh="holder_lower_bracket" material="holder_lower_bracket_material"/>
      <geom type="mesh" class="collision" pos="0.148664 0.11587 0.0388323" quat="0.5 0.5 -0.5 -0.5" mesh="holder_lower_bracket" material="holder_lower_bracket_material"/>
      <!-- Part xt_bracket_2 -->
      <geom type="mesh" class="visual" pos="0.0454633 0.105873 0.102505" quat="6.62383e-15 0.707107 -0.707107 2.9243e-15" mesh="xt_bracket" material="xt_bracket_material"/>
      <geom type="mesh" class="collision" pos="0.0454633 0.105873 0.102505" quat="6.62383e-15 0.707107 -0.707107 2.9243e-15" mesh="xt_bracket" material="xt_bracket_material"/>
      <!-- Part bumper_front_lower -->
      <geom type="mesh" class="visual" pos="0.177164 0.143573 0.0805404" quat="0.5 -0.5 0.5 -0.5" mesh="bumper_front_lower" material="bumper_front_lower_material"/>
      <geom type="mesh" class="collision" pos="0.177164 0.143573 0.0805404" quat="0.5 -0.5 0.5 -0.5" mesh="bumper_front_lower" material="bumper_front_lower_material"/>
      <!-- Part bracket_back_bumper_mir -->
      <geom type="mesh" class="visual" pos="0.0524633 0.120273 0.0805046" quat="0.5 -0.5 0.5 -0.5" mesh="bracket_back_bumper_mir" material="bracket_back_bumper_mir_material"/>
      <geom type="mesh" class="collision" pos="0.0524633 0.120273 0.0805046" quat="0.5 -0.5 0.5 -0.5" mesh="bracket_back_bumper_mir" material="bracket_back_bumper_mir_material"/>
      <!-- Link neck -->
      <body name="neck" pos="0.12793 0.0749861 -0.0546954" quat="1.33227e-15 -2.85189e-15 -5.21805e-15 -1">
        <!-- Joint from torso_kidsize25 to neck -->
        <joint axis="0 0 1" name="head_yaw" type="hinge"/>
        <inertial pos="2.39298e-07 -1.6286e-17 -0.00879985" mass="0.0128985" fullinertia="5.01235e-06 2.39998e-06 4.13467e-06 -2.63324e-11 9.38605e-13 -4.12929e-21"/>
        <!-- Part almi_4mm_neck_bracket -->
        <geom type="mesh" class="visual" pos="0.0128945 0.0185 0" quat="0.707107 -0.707107 -0 5.44735e-34" mesh="almi_4mm_neck_bracket" material="almi_4mm_neck_bracket_material"/>
        <geom type="mesh" class="collision" pos="0.0128945 0.0185 0" quat="0.707107 -0.707107 -0 5.44735e-34" mesh="almi_4mm_neck_bracket" material="almi_4mm_neck_bracket_material"/>
        <!-- Part carbon_2mm_neck_side_plate -->
        <geom type="mesh" class="visual" pos="5e-07 0.0205 -0.02" quat="0.707107 -0.707107 1.55431e-15 -9.64135e-16" mesh="carbon_2mm_neck_side_plate" material="carbon_2mm_neck_side_plate_material"/>
        <geom type="mesh" class="collision" pos="5e-07 0.0205 -0.02" quat="0.707107 -0.707107 1.55431e-15 -9.64135e-16" mesh="carbon_2mm_neck_side_plate" material="carbon_2mm_neck_side_plate_material"/>
        <!-- Part carbon_2mm_neck_side_plate_2 -->
        <geom type="mesh" class="visual" pos="-2.77556e-17 -0.0225 -0.02" quat="0.707107 -0.707107 9.99201e-16 -7.18808e-16" mesh="carbon_2mm_neck_side_plate" material="carbon_2mm_neck_side_plate_material"/>
        <geom type="mesh" class="collision" pos="-2.77556e-17 -0.0225 -0.02" quat="0.707107 -0.707107 9.99201e-16 -7.18808e-16" mesh="carbon_2mm_neck_side_plate" material="carbon_2mm_neck_side_plate_material"/>
        <!-- Link head -->
        <body name="head" pos="5e-07 0.0205 -0.037" quat="0.5 -0.5 0.5 0.5">
          <!-- Joint from neck to head -->
          <joint axis="0 0 1" name="head_pitch" type="hinge"/>
          <inertial pos="0.0315459 0.00214801 -0.0205645" mass="0.371554" fullinertia="0.000238323 0.000308835 0.000217343 -4.47308e-05 2.28198e-07 -2.79152e-07"/>
          <!-- Part petg_2mm_headbracket_old -->
          <geom type="mesh" class="visual" pos="-0.0064 -0.0265 -0.0386" quat="0.5 -0.5 -0.5 -0.5" mesh="petg_2mm_headbracket_old" material="petg_2mm_headbracket_old_material"/>
          <geom type="mesh" class="collision" pos="-0.0064 -0.0265 -0.0386" quat="0.5 -0.5 -0.5 -0.5" mesh="petg_2mm_headbracket_old" material="petg_2mm_headbracket_old_material"/>
          <!-- Part camera_logitech_c920_offset_2mm -->
          <geom type="mesh" class="visual" pos="0.0256 -0.00182638 -0.06759" quat="0.5 -0.5 -0.5 -0.5" mesh="camera_logitech_c920_offset_2mm" material="camera_logitech_c920_offset_2mm_material"/>
          <geom type="mesh" class="collision" pos="0.0256 -0.00182638 -0.06759" quat="0.5 -0.5 -0.5 -0.5" mesh="camera_logitech_c920_offset_2mm" material="camera_logitech_c920_offset_2mm_material"/>
          <!-- Part camera_frame -->
          <geom type="mesh" class="visual" pos="0.0251 0.0215 -0.0535485" quat="0.707107 -2.55189e-15 -3.88578e-16 -0.707107" mesh="camera_frame" material="camera_frame_material"/>
          <geom type="mesh" class="collision" pos="0.0251 0.0215 -0.0535485" quat="0.707107 -2.55189e-15 -3.88578e-16 -0.707107" mesh="camera_frame" material="camera_frame_material"/>
          <!-- Part mx_28_4 -->
          <geom type="mesh" class="visual" pos="0.0079054 -0.0653899 -0.0287863" quat="0.707107 -0.707107 -0 -1.17009e-30" mesh="mx_28" material="mx_28_material"/>
          <geom type="mesh" class="collision" pos="0.0079054 -0.0653899 -0.0287863" quat="0.707107 -0.707107 -0 -1.17009e-30" mesh="mx_28" material="mx_28_material"/>
          <!-- Part petg_2mm_rotatingheadbracket -->
          <geom type="mesh" class="visual" pos="-0.0064 -0.0265 -0.0386" quat="0.5 -0.5 -0.5 -0.5" mesh="petg_2mm_rotatingheadbracket" material="petg_2mm_rotatingheadbracket_material"/>
          <geom type="mesh" class="collision" pos="-0.0064 -0.0265 -0.0386" quat="0.5 -0.5 -0.5 -0.5" mesh="petg_2mm_rotatingheadbracket" material="petg_2mm_rotatingheadbracket_material"/>
        </body>
      </body>
      <!-- Link almi2_view_6_7__arm_bracket -->
      <body name="almi2_view_6_7__arm_bracket" pos="0.102431 0.14736 -0.0312954" quat="0.707107 0.707107 2.9976e-15 -8.58455e-16">
        <!-- Joint from torso_kidsize25 to almi2_view_6_7__arm_bracket -->
        <joint axis="0 0 1" name="right_shoulder_pitch" type="hinge"/>
        <inertial pos="-9.36751e-17 0.00223841 -0.00829596" mass="0.0151289" fullinertia="2.57897e-06 5.57377e-06 5.85595e-06 5.42452e-37 9.2965e-37 4.04961e-07"/>
        <!-- Part almi2_view_6_7__arm_bracket -->
        <geom type="mesh" class="visual" pos="0.0185 -0.012 -0.002" quat="0.707107 0.707107 -0 2.84897e-31" mesh="almi2_view_6_7__arm_bracket" material="almi2_view_6_7__arm_bracket_material"/>
        <geom type="mesh" class="collision" pos="0.0185 -0.012 -0.002" quat="0.707107 0.707107 -0 2.84897e-31" mesh="almi2_view_6_7__arm_bracket" material="almi2_view_6_7__arm_bracket_material"/>
        <!-- Link right_upperhand -->
        <body name="right_upperhand" pos="0.0205 0.0147498 -0.0268034" quat="0.5 0.5 0.5 0.5">
          <!-- Joint from almi2_view_6_7__arm_bracket to right_upperhand -->
          <joint axis="0 0 1" name="right_shoulder_roll" type="hinge"/>
          <inertial pos="-4.16556e-05 -0.0497057 -0.0229115" mass="0.178" fullinertia="0.000293103 3.4849e-05 0.00029267 -7.35413e-07 -2.0111e-08 -1.67161e-05"/>
          <!-- Part mx_28_5 -->
          <geom type="mesh" class="visual" pos="0.00818918 -0.0341201 -0.0335054" quat="0.5 0.5 0.5 -0.5" mesh="mx_28" material="mx_28_material"/>
          <geom type="mesh" class="collision" pos="0.00818918 -0.0341201 -0.0335054" quat="0.5 0.5 0.5 -0.5" mesh="mx_28" material="mx_28_material"/>
          <!-- Part mx_28_6 -->
          <geom type="mesh" class="visual" pos="0.0079054 -0.0653899 -0.0287863" quat="0.707107 -0.707107 0 -4.09641e-31" mesh="mx_28" material="mx_28_material"/>
          <geom type="mesh" class="collision" pos="0.0079054 -0.0653899 -0.0287863" quat="0.707107 -0.707107 0 -4.09641e-31" mesh="mx_28" material="mx_28_material"/>
          <!-- Part almi2_view_13__14__arm -->
          <geom type="mesh" class="visual" pos="-0.0819971 -0.058605 -0.0256" quat="1 1.04645e-16 -2.22045e-16 8.29198e-16" mesh="almi2_view_13__14__arm" material="almi2_view_13__14__arm_material"/>
          <geom type="mesh" class="collision" pos="-0.0819971 -0.058605 -0.0256" quat="1 1.04645e-16 -2.22045e-16 8.29198e-16" mesh="almi2_view_13__14__arm" material="almi2_view_13__14__arm_material"/>
          <!-- Link right_lowerhand -->
          <body name="right_lowerhand" pos="-0.0205971 -0.09951 -0.0256" quat="0.707107 -6.81639e-16 0.707107 4.44089e-16">
            <!-- Joint from right_upperhand to right_lowerhand -->
            <joint axis="0 0 1" name="right_elbow" type="hinge"/>
            <inertial pos="-0.00130389 -0.103918 0.0103596" mass="0.149258" fullinertia="0.000225269 5.61474e-05 0.000240431 -7.02224e-06 -1.20544e-07 -3.26703e-05"/>
            <!-- Part almi_4_5mm_connector_lower_arm_kidsize -->
            <geom type="mesh" class="visual" pos="0.00225 -0.0405 1.04083e-16" quat="3.33067e-16 -3.92523e-17 0.707107 0.707107" mesh="almi_4_5mm_connector_lower_arm_kidsize" material="almi_4_5mm_connector_lower_arm_kidsize_material"/>
            <geom type="mesh" class="collision" pos="0.00225 -0.0405 1.04083e-16" quat="3.33067e-16 -3.92523e-17 0.707107 0.707107" mesh="almi_4_5mm_connector_lower_arm_kidsize" material="almi_4_5mm_connector_lower_arm_kidsize_material"/>
            <!-- Part carbon_2mm_arm_kidsize_1 -->
            <geom type="mesh" class="visual" pos="0 0 0" quat="0.5 0.5 0.5 -0.5" mesh="carbon_2mm_arm_kidsize_1" material="carbon_2mm_arm_kidsize_1_material"/>
            <geom type="mesh" class="collision" pos="0 0 0" quat="0.5 0.5 0.5 -0.5" mesh="carbon_2mm_arm_kidsize_1" material="carbon_2mm_arm_kidsize_1_material"/>
            <!-- Part tpu_arm_kidsize_telapak -->
            <geom type="mesh" class="visual" pos="-2.77556e-17 -0.14 0.0728" quat="0.707107 0.707107 0 3.18925e-17" mesh="tpu_arm_kidsize_telapak" material="tpu_arm_kidsize_telapak_material"/>
            <geom type="mesh" class="collision" pos="-2.77556e-17 -0.14 0.0728" quat="0.707107 0.707107 0 3.18925e-17" mesh="tpu_arm_kidsize_telapak" material="tpu_arm_kidsize_telapak_material"/>
            <!-- Part carbon_2mm_arm_kidsize_2 -->
            <geom type="mesh" class="visual" pos="0 0 0.043" quat="0.707107 4.21962e-16 0.707107 3.60822e-16" mesh="carbon_2mm_arm_kidsize_2" material="carbon_2mm_arm_kidsize_2_material"/>
            <geom type="mesh" class="collision" pos="0 0 0.043" quat="0.707107 4.21962e-16 0.707107 3.60822e-16" mesh="carbon_2mm_arm_kidsize_2" material="carbon_2mm_arm_kidsize_2_material"/>
          </body>
        </body>
      </body>
      <!-- Link almi2_view_6_7__arm_bracket_2 -->
      <body name="almi2_view_6_7__arm_bracket_2" pos="0.102431 0.00278607 -0.0312954" quat="1.34337e-14 9.45625e-15 -0.707107 -0.707107">
        <!-- Joint from torso_kidsize25 to almi2_view_6_7__arm_bracket_2 -->
        <joint axis="0 0 1" name="left_shoulder_pitch" type="hinge"/>
        <inertial pos="-1.07553e-16 0.00223841 -0.00829596" mass="0.0151289" fullinertia="2.57897e-06 5.57377e-06 5.85595e-06 -3.05654e-36 1.88736e-35 4.04961e-07"/>
        <!-- Part almi2_view_6_7__arm_bracket_2 -->
        <geom type="mesh" class="visual" pos="0.0185 -0.012 -0.002" quat="0.707107 0.707107 0 2.7772e-30" mesh="almi2_view_6_7__arm_bracket" material="almi2_view_6_7__arm_bracket_material"/>
        <geom type="mesh" class="collision" pos="0.0185 -0.012 -0.002" quat="0.707107 0.707107 0 2.7772e-30" mesh="almi2_view_6_7__arm_bracket" material="almi2_view_6_7__arm_bracket_material"/>
        <!-- Link left_upperhand -->
        <body name="left_upperhand" pos="-0.0205 0.0147498 -0.0268034" quat="0.707107 0 -0.707107 -0">
          <!-- Joint from almi2_view_6_7__arm_bracket_2 to left_upperhand -->
          <joint axis="0 0 1" name="left_shoulder_roll" type="hinge"/>
          <inertial pos="-0.0497057 -4.16564e-05 -0.0182021" mass="0.178" fullinertia="3.47766e-05 0.00029303 0.00029267 -7.35406e-07 1.52286e-05 1.94701e-08"/>
          <!-- Part mx_28_7 -->
          <geom type="mesh" class="visual" pos="-0.0341201 0.00818918 -0.0076946" quat="0.707107 1.17429e-15 -0.707107 3.94129e-15" mesh="mx_28" material="mx_28_material"/>
          <geom type="mesh" class="collision" pos="-0.0341201 0.00818918 -0.0076946" quat="0.707107 1.17429e-15 -0.707107 3.94129e-15" mesh="mx_28" material="mx_28_material"/>
          <!-- Part almi2_view_13__14__arm_2 -->
          <geom type="mesh" class="visual" pos="-0.058605 -0.0819971 -0.0156" quat="3.54528e-15 -0.707107 -0.707107 2.7179e-15" mesh="almi2_view_13__14__arm" material="almi2_view_13__14__arm_material"/>
          <geom type="mesh" class="collision" pos="-0.058605 -0.0819971 -0.0156" quat="3.54528e-15 -0.707107 -0.707107 2.7179e-15" mesh="almi2_view_13__14__arm" material="almi2_view_13__14__arm_material"/>
          <!-- Part mx_28_8 -->
          <geom type="mesh" class="visual" pos="-0.0653899 -0.0079054 -0.0287863" quat="0.5 -0.5 0.5 -0.5" mesh="mx_28" material="mx_28_material"/>
          <geom type="mesh" class="collision" pos="-0.0653899 -0.0079054 -0.0287863" quat="0.5 -0.5 0.5 -0.5" mesh="mx_28" material="mx_28_material"/>
          <!-- Link left_lowerhand -->
          <body name="left_lowerhand" pos="-0.09951 -0.0205971 -0.0156" quat="0.5 -0.5 -0.5 -0.5">
            <!-- Joint from left_upperhand to left_lowerhand -->
            <joint axis="0 0 1" name="left_elbow" type="hinge"/>
            <inertial pos="-0.00130389 -0.103918 0.0103596" mass="0.149258" fullinertia="0.000225269 5.61474e-05 0.000240431 -7.02224e-06 -1.20544e-07 -3.26703e-05"/>
            <!-- Part carbon_2mm_arm_kidsize_1_2 -->
            <geom type="mesh" class="visual" pos="1.38778e-17 -2.77556e-17 1.38778e-17" quat="0.5 0.5 0.5 -0.5" mesh="carbon_2mm_arm_kidsize_1" material="carbon_2mm_arm_kidsize_1_material"/>
            <geom type="mesh" class="collision" pos="1.38778e-17 -2.77556e-17 1.38778e-17" quat="0.5 0.5 0.5 -0.5" mesh="carbon_2mm_arm_kidsize_1" material="carbon_2mm_arm_kidsize_1_material"/>
            <!-- Part tpu_arm_kidsize_telapak_2 -->
            <geom type="mesh" class="visual" pos="-3.33067e-16 -0.14 0.0728" quat="0.707107 0.707107 -1.33227e-15 4.90654e-16" mesh="tpu_arm_kidsize_telapak" material="tpu_arm_kidsize_telapak_material"/>
            <geom type="mesh" class="collision" pos="-3.33067e-16 -0.14 0.0728" quat="0.707107 0.707107 -1.33227e-15 4.90654e-16" mesh="tpu_arm_kidsize_telapak" material="tpu_arm_kidsize_telapak_material"/>
            <!-- Part almi_4_5mm_connector_lower_arm_kidsize_2 -->
            <geom type="mesh" class="visual" pos="0.00225 -0.0405 1.17961e-16" quat="5.10703e-15 -2.65689e-15 0.707107 0.707107" mesh="almi_4_5mm_connector_lower_arm_kidsize" material="almi_4_5mm_connector_lower_arm_kidsize_material"/>
            <geom type="mesh" class="collision" pos="0.00225 -0.0405 1.17961e-16" quat="5.10703e-15 -2.65689e-15 0.707107 0.707107" mesh="almi_4_5mm_connector_lower_arm_kidsize" material="almi_4_5mm_connector_lower_arm_kidsize_material"/>
            <!-- Part carbon_2mm_arm_kidsize_2_2 -->
            <geom type="mesh" class="visual" pos="-2.63678e-16 1.6237e-15 0.043" quat="0.707107 1.17266e-15 0.707107 3.05311e-16" mesh="carbon_2mm_arm_kidsize_2" material="carbon_2mm_arm_kidsize_2_material"/>
            <geom type="mesh" class="collision" pos="-2.63678e-16 1.6237e-15 0.043" quat="0.707107 1.17266e-15 0.707107 3.05311e-16" mesh="carbon_2mm_arm_kidsize_2" material="carbon_2mm_arm_kidsize_2_material"/>
          </body>
        </body>
      </body>
      <!-- Link stainless_steel_2mm_upper_leg_bracket -->
      <body name="stainless_steel_2mm_upper_leg_bracket" pos="0.0981644 0.124573 0.109005" quat="9.98507e-15 1 5.55112e-16 -4.1564e-15">
        <!-- Joint from torso_kidsize25 to stainless_steel_2mm_upper_leg_bracket -->
        <joint axis="0 0 1" name="right_hip_yaw" type="hinge"/>
        <inertial pos="-0.00421162 -1.80642e-07 -0.00839045" mass="0.0521561" fullinertia="1.13163e-05 2.97089e-05 2.98236e-05 -2.66522e-10 -2.03733e-07 3.66542e-11"/>
        <!-- Part stainless_steel_2mm_upper_leg_bracket -->
        <geom type="mesh" class="visual" pos="-0.03298 0.016 0" quat="0 1 0 0" mesh="stainless_steel_2mm_upper_leg_bracket" material="stainless_steel_2mm_upper_leg_bracket_material"/>
        <geom type="mesh" class="collision" pos="-0.03298 0.016 0" quat="0 1 0 0" mesh="stainless_steel_2mm_upper_leg_bracket" material="stainless_steel_2mm_upper_leg_bracket_material"/>
        <!-- Link foot_right_1 -->
        <body name="foot_right_1" pos="-0.0335 3.55965e-14 -0.032" quat="0.5 0.5 0.5 0.5">
          <!-- Joint from stainless_steel_2mm_upper_leg_bracket to foot_right_1 -->
          <joint axis="0 0 1" name="right_hip_roll" type="hinge"/>
          <inertial pos="-0.000121825 -0.0144674 0.00397654" mass="0.292396" fullinertia="0.000302471 0.00026243 0.000113113 -1.95767e-07 7.69534e-07 -1.25976e-05"/>
          <!-- Part mx_64t_2 -->
          <geom type="mesh" class="visual" pos="0 -5.55112e-17 -0.0235" quat="1 -0 0 1.66533e-16" mesh="mx_64t_2" material="mx_64t_2_material"/>
          <geom type="mesh" class="collision" pos="0 -5.55112e-17 -0.0235" quat="1 -0 0 1.66533e-16" mesh="mx_64t_2" material="mx_64t_2_material"/>
          <!-- Part almi_2mm_fr05_f101k_set -->
          <geom type="mesh" class="visual" pos="-2.63678e-16 -5.55112e-16 0.04958" quat="0.5 -0.5 -0.5 0.5" mesh="almi_2mm_fr05_f101k_set" material="almi_2mm_fr05_f101k_set_material"/>
          <geom type="mesh" class="collision" pos="-2.63678e-16 -5.55112e-16 0.04958" quat="0.5 -0.5 -0.5 0.5" mesh="almi_2mm_fr05_f101k_set" material="almi_2mm_fr05_f101k_set_material"/>
          <!-- Part almi_2mm_connector_mx64 -->
          <geom type="mesh" class="visual" pos="-0.019 -0.043 0.01058" quat="0.707107 4.95664e-18 3.28296e-15 -0.707107" mesh="almi_2mm_connector_mx64" material="almi_2mm_connector_mx64_material"/>
          <geom type="mesh" class="collision" pos="-0.019 -0.043 0.01058" quat="0.707107 4.95664e-18 3.28296e-15 -0.707107" mesh="almi_2mm_connector_mx64" material="almi_2mm_connector_mx64_material"/>
          <!-- Part almi_2mm_connector_mx64_2 -->
          <geom type="mesh" class="visual" pos="0.019 -0.015 0.01058" quat="0.707107 3.05432e-15 -1.11022e-16 0.707107" mesh="almi_2mm_connector_mx64" material="almi_2mm_connector_mx64_material"/>
          <geom type="mesh" class="collision" pos="0.019 -0.015 0.01058" quat="0.707107 3.05432e-15 -1.11022e-16 0.707107" mesh="almi_2mm_connector_mx64" material="almi_2mm_connector_mx64_material"/>
          <!-- Part fr05_f101k_set -->
          <geom type="mesh" class="visual" pos="-4.996e-16 -4.996e-16 0.04938" quat="0.707107 1.47447e-16 3.10862e-15 -0.707107" mesh="fr05_f101k_set" material="fr05_f101k_set_material"/>
          <geom type="mesh" class="collision" pos="-4.996e-16 -4.996e-16 0.04938" quat="0.707107 1.47447e-16 3.10862e-15 -0.707107" mesh="fr05_f101k_set" material="fr05_f101k_set_material"/>
          <!-- Part mx_64t_2_2 -->
          <geom type="mesh" class="visual" pos="-2.63678e-16 -3.05311e-16 0.02558" quat="0.707107 -3.31927e-15 0.707107 6.95277e-15" mesh="mx_64t_2" material="mx_64t_2_material"/>
          <geom type="mesh" class="collision" pos="-2.63678e-16 -3.05311e-16 0.02558" quat="0.707107 -3.31927e-15 0.707107 6.95277e-15" mesh="mx_64t_2" material="mx_64t_2_material"/>
          <!-- Part mf128zz_1 -->
          <geom type="mesh" class="visual" pos="-4.996e-16 -4.996e-16 0.0516" quat="0.5 0.5 0.5 0.5" mesh="mf128zz_1" material="mf128zz_1_material"/>
          <geom type="mesh" class="collision" pos="-4.996e-16 -4.996e-16 0.0516" quat="0.5 0.5 0.5 0.5" mesh="mf128zz_1" material="mf128zz_1_material"/>
          <!-- Part rx64_cap_1 -->
          <geom type="mesh" class="visual" pos="-4.996e-16 -5.55112e-16 0.05508" quat="0.707107 2.76974e-15 -4.44089e-16 0.707107" mesh="rx64_cap_1" material="rx64_cap_1_material"/>
          <geom type="mesh" class="collision" pos="-4.996e-16 -5.55112e-16 0.05508" quat="0.707107 2.76974e-15 -4.44089e-16 0.707107" mesh="rx64_cap_1" material="rx64_cap_1_material"/>
          <!-- Part hn05_i101_1 -->
          <geom type="mesh" class="visual" pos="-5.13478e-16 -5.55112e-16 0.05532" quat="0.5 0.5 0.5 0.5" mesh="hn05_i101_1" material="hn05_i101_1_material"/>
          <geom type="mesh" class="collision" pos="-5.13478e-16 -5.55112e-16 0.05532" quat="0.5 0.5 0.5 0.5" mesh="hn05_i101_1" material="hn05_i101_1_material"/>
          <!-- Part rx64_cap_1_2 -->
          <geom type="mesh" class="visual" pos="-0.0232 -9.71445e-16 0.02558" quat="3.62473e-15 0.707107 6.66134e-15 -0.707107" mesh="rx64_cap_1" material="rx64_cap_1_material"/>
          <geom type="mesh" class="collision" pos="-0.0232 -9.71445e-16 0.02558" quat="3.62473e-15 0.707107 6.66134e-15 -0.707107" mesh="rx64_cap_1" material="rx64_cap_1_material"/>
          <!-- Part hn05_i101_1_2 -->
          <geom type="mesh" class="visual" pos="-0.02344 -9.71445e-16 0.02558" quat="0.5 -0.5 0.5 0.5" mesh="hn05_i101_1" material="hn05_i101_1_material"/>
          <geom type="mesh" class="collision" pos="-0.02344 -9.71445e-16 0.02558" quat="0.5 -0.5 0.5 0.5" mesh="hn05_i101_1" material="hn05_i101_1_material"/>
          <!-- Part mf128zz_1_2 -->
          <geom type="mesh" class="visual" pos="-0.01972 -8.88178e-16 0.02558" quat="0.5 -0.5 0.5 0.5" mesh="mf128zz_1" material="mf128zz_1_material"/>
          <geom type="mesh" class="collision" pos="-0.01972 -8.88178e-16 0.02558" quat="0.5 -0.5 0.5 0.5" mesh="mf128zz_1" material="mf128zz_1_material"/>
          <!-- Link foot_right_2 -->
          <body name="foot_right_2" pos="0.0235 6.66134e-16 0.02558" quat="0.707107 -3.61239e-15 -0.707107 1.26565e-14">
            <!-- Joint from foot_right_1 to foot_right_2 -->
            <joint axis="0 0 1" name="right_hip_pitch" type="hinge"/>
            <inertial pos="0.00189202 -0.0890217 0.0236304" mass="0.273181" fullinertia="0.00054925 0.000131243 0.000472641 -3.23355e-06 6.73937e-08 8.86444e-07"/>
            <!-- Part stainless_steel_2mm__femur -->
            <geom type="mesh" class="visual" pos="-0.014 -0.07746 0.047" quat="0.707107 0.707107 0 -2.47548e-17" mesh="stainless_steel_2mm__femur" material="stainless_steel_2mm__femur_material"/>
            <geom type="mesh" class="collision" pos="-0.014 -0.07746 0.047" quat="0.707107 0.707107 0 -2.47548e-17" mesh="stainless_steel_2mm__femur" material="stainless_steel_2mm__femur_material"/>
            <!-- Part stainless_steel_2mm__femur_2 -->
            <geom type="mesh" class="visual" pos="-0.014 -0.07746 -0.003" quat="0.707107 0.707107 -0 -1.52526e-32" mesh="stainless_steel_2mm__femur" material="stainless_steel_2mm__femur_material"/>
            <geom type="mesh" class="collision" pos="-0.014 -0.07746 -0.003" quat="0.707107 0.707107 -0 -1.52526e-32" mesh="stainless_steel_2mm__femur" material="stainless_steel_2mm__femur_material"/>
            <!-- Part almi_6_5mm_l_mx64 -->
            <geom type="mesh" class="visual" pos="-0.0134121 -0.0859 0.047" quat="5.15187e-17 2.86864e-16 0.707107 -0.707107" mesh="almi_6_5mm_l_mx64" material="almi_6_5mm_l_mx64_material"/>
            <geom type="mesh" class="collision" pos="-0.0134121 -0.0859 0.047" quat="5.15187e-17 2.86864e-16 0.707107 -0.707107" mesh="almi_6_5mm_l_mx64" material="almi_6_5mm_l_mx64_material"/>
            <!-- Part almi_6_5mm_l_mx64_2 -->
            <geom type="mesh" class="visual" pos="-0.0134121 -0.0859 0.0065" quat="2.22045e-16 5.0292e-16 0.707107 -0.707107" mesh="almi_6_5mm_l_mx64" material="almi_6_5mm_l_mx64_material"/>
            <geom type="mesh" class="collision" pos="-0.0134121 -0.0859 0.0065" quat="2.22045e-16 5.0292e-16 0.707107 -0.707107" mesh="almi_6_5mm_l_mx64" material="almi_6_5mm_l_mx64_material"/>
            <!-- Part mx_64t_1 -->
            <geom type="mesh" class="visual" pos="-6.38378e-16 -0.134 0.0235" quat="2.77556e-17 1 -3.46945e-17 1.66533e-16" mesh="mx_64t_1" material="mx_64t_1_material"/>
            <geom type="mesh" class="collision" pos="-6.38378e-16 -0.134 0.0235" quat="2.77556e-17 1 -3.46945e-17 1.66533e-16" mesh="mx_64t_1" material="mx_64t_1_material"/>
            <!-- Part hn05_i101 -->
            <geom type="mesh" class="visual" pos="-6.52256e-16 -0.134 0.04694" quat="0.5 0.5 -0.5 -0.5" mesh="hn05_i101" material="hn05_i101_material"/>
            <geom type="mesh" class="collision" pos="-6.52256e-16 -0.134 0.04694" quat="0.5 0.5 -0.5 -0.5" mesh="hn05_i101" material="hn05_i101_material"/>
            <!-- Part mf128zz -->
            <geom type="mesh" class="visual" pos="-6.52256e-16 -0.134 0.04322" quat="0.5 0.5 -0.5 -0.5" mesh="mf128zz" material="mf128zz_material"/>
            <geom type="mesh" class="collision" pos="-6.52256e-16 -0.134 0.04322" quat="0.5 0.5 -0.5 -0.5" mesh="mf128zz" material="mf128zz_material"/>
            <!-- Part rx64_cap -->
            <geom type="mesh" class="visual" pos="-6.66134e-16 -0.134 0.0467" quat="0.707107 -1.15511e-16 2.498e-16 -0.707107" mesh="rx64_cap" material="rx64_cap_material"/>
            <geom type="mesh" class="collision" pos="-6.66134e-16 -0.134 0.0467" quat="0.707107 -1.15511e-16 2.498e-16 -0.707107" mesh="rx64_cap" material="rx64_cap_material"/>
            <!-- Link foot_right_3 -->
            <body name="foot_right_3" pos="-6.38378e-16 -0.134 4.16334e-17" quat="1 3.61226e-15 3.88578e-15 1.11022e-16">
              <!-- Joint from foot_right_2 to foot_right_3 -->
              <joint axis="0 0 1" name="right_knee" type="hinge"/>
              <inertial pos="0.00350206 -0.0535427 0.0235017" mass="0.157154" fullinertia="0.000266743 0.000115972 0.000200186 -8.33375e-06 -5.26492e-09 -6.48605e-09"/>
              <!-- Part stainless_steel_2mm_leg_spacer -->
              <geom type="mesh" class="visual" pos="0.024 -0.0190814 0.045" quat="5.29416e-15 0.707107 -0.707107 -4.56308e-16" mesh="stainless_steel_2mm_leg_spacer" material="stainless_steel_2mm_leg_spacer_material"/>
              <geom type="mesh" class="collision" pos="0.024 -0.0190814 0.045" quat="5.29416e-15 0.707107 -0.707107 -4.56308e-16" mesh="stainless_steel_2mm_leg_spacer" material="stainless_steel_2mm_leg_spacer_material"/>
              <!-- Part stainless_steel_2mm_shinebone -->
              <geom type="mesh" class="visual" pos="0.0135 -0.0197269 0.05" quat="0.707107 -0.707107 9.99201e-16 4.75444e-15" mesh="stainless_steel_2mm_shinebone" material="stainless_steel_2mm_shinebone_material"/>
              <geom type="mesh" class="collision" pos="0.0135 -0.0197269 0.05" quat="0.707107 -0.707107 9.99201e-16 4.75444e-15" mesh="stainless_steel_2mm_shinebone" material="stainless_steel_2mm_shinebone_material"/>
              <!-- Part stainless_steel_2mm_shinebone_2 -->
              <geom type="mesh" class="visual" pos="0.0135 -0.0197269 0" quat="0.707107 -0.707107 -0 6.64577e-31" mesh="stainless_steel_2mm_shinebone" material="stainless_steel_2mm_shinebone_material"/>
              <geom type="mesh" class="collision" pos="0.0135 -0.0197269 0" quat="0.707107 -0.707107 -0 6.64577e-31" mesh="stainless_steel_2mm_shinebone" material="stainless_steel_2mm_shinebone_material"/>
              <!-- Link foot_right_4 -->
              <body name="foot_right_4" pos="-9.71445e-17 -0.111702 1.38778e-17" quat="3.62904e-15 1 2.38906e-14 4.27436e-15">
                <!-- Joint from foot_right_3 to foot_right_4 -->
                <joint axis="0 0 1" name="right_ankle_pitch" type="hinge"/>
                <inertial pos="-0.0215978 -0.0144558 -0.0236219" mass="0.292143" fullinertia="0.000112946 0.000262476 0.000302507 -1.25976e-05 7.69336e-07 -2.05088e-07"/>
                <!-- Part mx_64t_3 -->
                <geom type="mesh" class="visual" pos="-0.04908 5.55112e-17 -0.0235" quat="0.707107 5.12733e-16 0.707107 2.77556e-16" mesh="mx_64t_3" material="mx_64t_3_material"/>
                <geom type="mesh" class="collision" pos="-0.04908 5.55112e-17 -0.0235" quat="0.707107 5.12733e-16 0.707107 2.77556e-16" mesh="mx_64t_3" material="mx_64t_3_material"/>
                <!-- Part fr05_f101k_set_1 -->
                <geom type="mesh" class="visual" pos="0.024 -4.58208e-05 -0.0235" quat="0.5 -0.5 0.5 -0.5" mesh="fr05_f101k_set_1" material="fr05_f101k_set_1_material"/>
                <geom type="mesh" class="collision" pos="0.024 -4.58208e-05 -0.0235" quat="0.5 -0.5 0.5 -0.5" mesh="fr05_f101k_set_1" material="fr05_f101k_set_1_material"/>
                <!-- Part almi_2mm_connector_mx64_1 -->
                <geom type="mesh" class="visual" pos="-0.015 -0.015 -0.0425" quat="0.5 0.5 0.5 0.5" mesh="almi_2mm_connector_mx64_1" material="almi_2mm_connector_mx64_1_material"/>
                <geom type="mesh" class="collision" pos="-0.015 -0.015 -0.0425" quat="0.5 0.5 0.5 0.5" mesh="almi_2mm_connector_mx64_1" material="almi_2mm_connector_mx64_1_material"/>
                <!-- Part almi_2mm_connector_mx64_1_2 -->
                <geom type="mesh" class="visual" pos="-0.015 -0.043 -0.0045" quat="0.5 -0.5 0.5 -0.5" mesh="almi_2mm_connector_mx64_1" material="almi_2mm_connector_mx64_1_material"/>
                <geom type="mesh" class="collision" pos="-0.015 -0.043 -0.0045" quat="0.5 -0.5 0.5 -0.5" mesh="almi_2mm_connector_mx64_1" material="almi_2mm_connector_mx64_1_material"/>
                <!-- Part mx_64t_3_2 -->
                <geom type="mesh" class="visual" pos="0 0 -0.0235" quat="1 0 0 0" mesh="mx_64t_3" material="mx_64t_3_material"/>
                <geom type="mesh" class="collision" pos="0 0 -0.0235" quat="1 0 0 0" mesh="mx_64t_3" material="mx_64t_3_material"/>
                <!-- Part almi_2mm_fr05_f101k_set_1 -->
                <geom type="mesh" class="visual" pos="0.024 5.55112e-17 -0.0235" quat="0.707107 1.22174e-16 -4.71845e-16 0.707107" mesh="almi_2mm_fr05_f101k_set_1" material="almi_2mm_fr05_f101k_set_1_material"/>
                <geom type="mesh" class="collision" pos="0.024 5.55112e-17 -0.0235" quat="0.707107 1.22174e-16 -4.71845e-16 0.707107" mesh="almi_2mm_fr05_f101k_set_1" material="almi_2mm_fr05_f101k_set_1_material"/>
                <!-- Part hn05_i101_2 -->
                <geom type="mesh" class="visual" pos="1.38778e-17 5.55112e-17 -0.04694" quat="0.707107 -0.707107 1.11022e-16 1.21185e-16" mesh="hn05_i101_2" material="hn05_i101_2_material"/>
                <geom type="mesh" class="collision" pos="1.38778e-17 5.55112e-17 -0.04694" quat="0.707107 -0.707107 1.11022e-16 1.21185e-16" mesh="hn05_i101_2" material="hn05_i101_2_material"/>
                <!-- Part mf128zz_2 -->
                <geom type="mesh" class="visual" pos="2.77556e-17 5.55112e-17 -0.04322" quat="0.707107 -0.707107 1.11022e-16 1.36108e-16" mesh="mf128zz_2" material="mf128zz_2_material"/>
                <geom type="mesh" class="collision" pos="2.77556e-17 5.55112e-17 -0.04322" quat="0.707107 -0.707107 1.11022e-16 1.36108e-16" mesh="mf128zz_2" material="mf128zz_2_material"/>
                <!-- Part rx64_cap_2 -->
                <geom type="mesh" class="visual" pos="1.38778e-17 5.55112e-17 -0.0467" quat="1.45717e-16 -1 -2.77556e-17 1.11022e-16" mesh="rx64_cap_2" material="rx64_cap_2_material"/>
                <geom type="mesh" class="collision" pos="1.38778e-17 5.55112e-17 -0.0467" quat="1.45717e-16 -1 -2.77556e-17 1.11022e-16" mesh="rx64_cap_2" material="rx64_cap_2_material"/>
                <!-- Part mf128zz_2_2 -->
                <geom type="mesh" class="visual" pos="0.02622 -4.58208e-05 -0.0235" quat="0.707107 1.07592e-15 2.22045e-16 -0.707107" mesh="mf128zz_2" material="mf128zz_2_material"/>
                <geom type="mesh" class="collision" pos="0.02622 -4.58208e-05 -0.0235" quat="0.707107 1.07592e-15 2.22045e-16 -0.707107" mesh="mf128zz_2" material="mf128zz_2_material"/>
                <!-- Part hn05_i101_2_2 -->
                <geom type="mesh" class="visual" pos="0.02994 -4.58208e-05 -0.0235" quat="0.707107 9.30783e-16 2.22045e-16 -0.707107" mesh="hn05_i101_2" material="hn05_i101_2_material"/>
                <geom type="mesh" class="collision" pos="0.02994 -4.58208e-05 -0.0235" quat="0.707107 9.30783e-16 2.22045e-16 -0.707107" mesh="hn05_i101_2" material="hn05_i101_2_material"/>
                <!-- Part rx64_cap_2_2 -->
                <geom type="mesh" class="visual" pos="0.0297 -4.58208e-05 -0.0235" quat="0.5 -0.5 0.5 -0.5" mesh="rx64_cap_2" material="rx64_cap_2_material"/>
                <geom type="mesh" class="collision" pos="0.0297 -4.58208e-05 -0.0235" quat="0.5 -0.5 0.5 -0.5" mesh="rx64_cap_2" material="rx64_cap_2_material"/>
                <!-- Link foot_right_5 -->
                <body name="foot_right_5" pos="-0.02558 0 -0.0235" quat="0.707107 1.17757e-15 -0.707107 4.44089e-16">
                  <!-- Joint from foot_right_4 to foot_right_5 -->
                  <joint axis="0 0 1" name="right_ankle_roll" type="hinge"/>
                  <inertial pos="-0.00431494 0.027932 -0.0410276" mass="0.132192" fullinertia="0.000177533 0.000221544 6.06598e-05 1.91248e-06 -5.63401e-06 8.6074e-07"/>
                  <!-- Part pla_50__shoes -->
                  <geom type="mesh" class="visual" pos="-0.04925 0.032 -0.10376" quat="9.02803e-16 -0.707107 2.55351e-15 0.707107" mesh="pla_50__shoes" material="pla_50__shoes_material"/>
                  <geom type="mesh" class="collision" pos="-0.04925 0.032 -0.10376" quat="9.02803e-16 -0.707107 2.55351e-15 0.707107" mesh="pla_50__shoes" material="pla_50__shoes_material"/>
                  <!-- Part almi_2mm_lower_leg -->
                  <geom type="mesh" class="visual" pos="-0.00775 0.032 -0.02876" quat="0.707107 -2.61082e-15 -0.707107 -6.66134e-16" mesh="almi_2mm_lower_leg" material="almi_2mm_lower_leg_material"/>
                  <geom type="mesh" class="collision" pos="-0.00775 0.032 -0.02876" quat="0.707107 -2.61082e-15 -0.707107 -6.66134e-16" mesh="almi_2mm_lower_leg" material="almi_2mm_lower_leg_material"/>
                  <!-- Part stainless_steel_2mm_lower_leg_bracket -->
                  <geom type="mesh" class="visual" pos="-0.016 0.032 -0.00052" quat="0.5 0.5 0.5 -0.5" mesh="stainless_steel_2mm_lower_leg_bracket" material="stainless_steel_2mm_lower_leg_bracket_material"/>
                  <geom type="mesh" class="collision" pos="-0.016 0.032 -0.00052" quat="0.5 0.5 0.5 -0.5" mesh="stainless_steel_2mm_lower_leg_bracket" material="stainless_steel_2mm_lower_leg_bracket_material"/>
                </body>
              </body>
            </body>
          </body>
        </body>
      </body>
      <!-- Link stainless_steel_2mm_upper_leg_bracket_mir -->
      <body name="stainless_steel_2mm_upper_leg_bracket_mir" pos="0.0981628 0.0255728 0.109005" quat="9.92262e-15 1 4.996e-16 -1.77636e-15">
        <!-- Joint from torso_kidsize25 to stainless_steel_2mm_upper_leg_bracket_mir -->
        <joint axis="0 0 1" name="left_hip_yaw" type="hinge"/>
        <inertial pos="-0.00421162 1.80642e-07 -0.00839045" mass="0.0521561" fullinertia="1.13163e-05 2.97089e-05 2.98236e-05 2.66522e-10 -2.03733e-07 -3.66542e-11"/>
        <!-- Part stainless_steel_2mm_upper_leg_bracket_mir -->
        <geom type="mesh" class="visual" pos="-0.03298 -0.016 1.38778e-17" quat="1 0 3.33067e-16 -5.55112e-17" mesh="stainless_steel_2mm_upper_leg_bracket_mir" material="stainless_steel_2mm_upper_leg_bracket_mir_material"/>
        <geom type="mesh" class="collision" pos="-0.03298 -0.016 1.38778e-17" quat="1 0 3.33067e-16 -5.55112e-17" mesh="stainless_steel_2mm_upper_leg_bracket_mir" material="stainless_steel_2mm_upper_leg_bracket_mir_material"/>
        <!-- Link foot_left_1 -->
        <body name="foot_left_1" pos="-0.0335 -3.56e-14 -0.032" quat="0.5 -0.5 0.5 -0.5">
          <!-- Joint from stainless_steel_2mm_upper_leg_bracket_mir to foot_left_1 -->
          <joint axis="0 0 1" name="left_hip_roll" type="hinge"/>
          <inertial pos="-0.000121924 0.0144559 0.00398223" mass="0.292143" fullinertia="0.000302507 0.000262475 0.000112946 1.96526e-07 7.69256e-07 1.25975e-05"/>
          <!-- Part mx_64t_mir_1 -->
          <geom type="mesh" class="visual" pos="0 2.77556e-17 -0.0235" quat="0 1 0 0" mesh="mx_64t_mir_1" material="mx_64t_mir_1_material"/>
          <geom type="mesh" class="collision" pos="0 2.77556e-17 -0.0235" quat="0 1 0 0" mesh="mx_64t_mir_1" material="mx_64t_mir_1_material"/>
          <!-- Part almi_2mm_fr05_f101k_set_mir -->
          <geom type="mesh" class="visual" pos="3.1225e-17 -1.38778e-16 0.04958" quat="0.5 -0.5 0.5 -0.5" mesh="almi_2mm_fr05_f101k_set_mir" material="almi_2mm_fr05_f101k_set_mir_material"/>
          <geom type="mesh" class="collision" pos="3.1225e-17 -1.38778e-16 0.04958" quat="0.5 -0.5 0.5 -0.5" mesh="almi_2mm_fr05_f101k_set_mir" material="almi_2mm_fr05_f101k_set_mir_material"/>
          <!-- Part almi_2mm_connector_mx64_mir -->
          <geom type="mesh" class="visual" pos="-0.019 0.043 0.01058" quat="2.07056e-15 -0.707107 -0.707107 -3.6799e-15" mesh="almi_2mm_connector_mx64_mir" material="almi_2mm_connector_mx64_mir_material"/>
          <geom type="mesh" class="collision" pos="-0.019 0.043 0.01058" quat="2.07056e-15 -0.707107 -0.707107 -3.6799e-15" mesh="almi_2mm_connector_mx64_mir" material="almi_2mm_connector_mx64_mir_material"/>
          <!-- Part fr05_f101k_set_mir -->
          <geom type="mesh" class="visual" pos="-2.08167e-16 4.58208e-05 0.04958" quat="2.17365e-15 -0.707107 -0.707107 -4.10399e-15" mesh="fr05_f101k_set_mir" material="fr05_f101k_set_mir_material"/>
          <geom type="mesh" class="collision" pos="-2.08167e-16 4.58208e-05 0.04958" quat="2.17365e-15 -0.707107 -0.707107 -4.10399e-15" mesh="fr05_f101k_set_mir" material="fr05_f101k_set_mir_material"/>
          <!-- Part almi_2mm_connector_mx64_mir_2 -->
          <geom type="mesh" class="visual" pos="0.019 0.015 0.01058" quat="4.65876e-15 -0.707107 0.707107 2.67652e-15" mesh="almi_2mm_connector_mx64_mir" material="almi_2mm_connector_mx64_mir_material"/>
          <geom type="mesh" class="collision" pos="0.019 0.015 0.01058" quat="4.65876e-15 -0.707107 0.707107 2.67652e-15" mesh="almi_2mm_connector_mx64_mir" material="almi_2mm_connector_mx64_mir_material"/>
          <!-- Part mx_64t_mir_1_2 -->
          <geom type="mesh" class="visual" pos="-2.08167e-17 3.33067e-16 0.02558" quat="2.77465e-15 0.707107 1.0103e-14 -0.707107" mesh="mx_64t_mir_1" material="mx_64t_mir_1_material"/>
          <geom type="mesh" class="collision" pos="-2.08167e-17 3.33067e-16 0.02558" quat="2.77465e-15 0.707107 1.0103e-14 -0.707107" mesh="mx_64t_mir_1" material="mx_64t_mir_1_material"/>
          <!-- Part mf128zz_mir_1 -->
          <geom type="mesh" class="visual" pos="-2.11636e-16 4.58208e-05 0.0518" quat="0.5 0.5 -0.5 -0.5" mesh="mf128zz_mir_1" material="mf128zz_mir_1_material"/>
          <geom type="mesh" class="collision" pos="-2.11636e-16 4.58208e-05 0.0518" quat="0.5 0.5 -0.5 -0.5" mesh="mf128zz_mir_1" material="mf128zz_mir_1_material"/>
          <!-- Part hn05_i101_mir_1 -->
          <geom type="mesh" class="visual" pos="-2.11636e-16 4.58208e-05 0.05552" quat="0.5 0.5 -0.5 -0.5" mesh="hn05_i101_mir_1" material="hn05_i101_mir_1_material"/>
          <geom type="mesh" class="collision" pos="-2.11636e-16 4.58208e-05 0.05552" quat="0.5 0.5 -0.5 -0.5" mesh="hn05_i101_mir_1" material="hn05_i101_mir_1_material"/>
          <!-- Part rx64_cap_mir_1 -->
          <geom type="mesh" class="visual" pos="-2.11636e-16 4.58208e-05 0.05528" quat="3.07149e-15 -0.707107 0.707107 2.7771e-15" mesh="rx64_cap_mir_1" material="rx64_cap_mir_1_material"/>
          <geom type="mesh" class="collision" pos="-2.11636e-16 4.58208e-05 0.05528" quat="3.07149e-15 -0.707107 0.707107 2.7771e-15" mesh="rx64_cap_mir_1" material="rx64_cap_mir_1_material"/>
          <!-- Part rx64_cap_mir_1_2 -->
          <geom type="mesh" class="visual" pos="-0.0232 -5.82867e-16 0.02558" quat="0.5 0.5 0.5 0.5" mesh="rx64_cap_mir_1" material="rx64_cap_mir_1_material"/>
          <geom type="mesh" class="collision" pos="-0.0232 -5.82867e-16 0.02558" quat="0.5 0.5 0.5 0.5" mesh="rx64_cap_mir_1" material="rx64_cap_mir_1_material"/>
          <!-- Part hn05_i101_mir_1_2 -->
          <geom type="mesh" class="visual" pos="-0.02344 -6.10623e-16 0.02558" quat="0.707107 2.43892e-15 -4.21885e-15 0.707107" mesh="hn05_i101_mir_1" material="hn05_i101_mir_1_material"/>
          <geom type="mesh" class="collision" pos="-0.02344 -6.10623e-16 0.02558" quat="0.707107 2.43892e-15 -4.21885e-15 0.707107" mesh="hn05_i101_mir_1" material="hn05_i101_mir_1_material"/>
          <!-- Part mf128zz_mir_1_2 -->
          <geom type="mesh" class="visual" pos="-0.01972 -4.44089e-16 0.02558" quat="0.707107 2.30532e-15 -4.38538e-15 0.707107" mesh="mf128zz_mir_1" material="mf128zz_mir_1_material"/>
          <geom type="mesh" class="collision" pos="-0.01972 -4.44089e-16 0.02558" quat="0.707107 2.30532e-15 -4.38538e-15 0.707107" mesh="mf128zz_mir_1" material="mf128zz_mir_1_material"/>
          <!-- Link foot_left_2 -->
          <body name="foot_left_2" pos="0.0235 1.80411e-15 0.02558" quat="0.707107 6.33925e-15 -0.707107 1.02141e-14">
            <!-- Joint from foot_left_1 to foot_left_2 -->
            <joint axis="0 0 1" name="left_hip_pitch" type="hinge"/>
            <inertial pos="0.00189202 0.0890217 0.0236304" mass="0.273181" fullinertia="0.00054925 0.000131243 0.000472641 3.23354e-06 6.73963e-08 -8.86436e-07"/>
            <!-- Part mx_64t_mir -->
            <geom type="mesh" class="visual" pos="-1.04083e-15 0.134 0.0235" quat="1 -2.80331e-15 8.88178e-16 3.2474e-15" mesh="mx_64t_mir" material="mx_64t_mir_material"/>
            <geom type="mesh" class="collision" pos="-1.04083e-15 0.134 0.0235" quat="1 -2.80331e-15 8.88178e-16 3.2474e-15" mesh="mx_64t_mir" material="mx_64t_mir_material"/>
            <!-- Part stainless_steel_2mm__femur_mir -->
            <geom type="mesh" class="visual" pos="-0.014 0.07746 0.047" quat="0.707107 0.707107 2.77556e-15 1.69494e-15" mesh="stainless_steel_2mm__femur_mir" material="stainless_steel_2mm__femur_mir_material"/>
            <geom type="mesh" class="collision" pos="-0.014 0.07746 0.047" quat="0.707107 0.707107 2.77556e-15 1.69494e-15" mesh="stainless_steel_2mm__femur_mir" material="stainless_steel_2mm__femur_mir_material"/>
            <!-- Part stainless_steel_2mm__femur_mir_2 -->
            <geom type="mesh" class="visual" pos="-0.014 0.07746 -0.003" quat="0.707107 0.707107 0 1.80307e-31" mesh="stainless_steel_2mm__femur_mir" material="stainless_steel_2mm__femur_mir_material"/>
            <geom type="mesh" class="collision" pos="-0.014 0.07746 -0.003" quat="0.707107 0.707107 0 1.80307e-31" mesh="stainless_steel_2mm__femur_mir" material="stainless_steel_2mm__femur_mir_material"/>
            <!-- Part almi_6_5mm_l_mx64_mir -->
            <geom type="mesh" class="visual" pos="-0.0134121 0.0859 0.0065" quat="1.44329e-15 -2.60738e-15 0.707107 -0.707107" mesh="almi_6_5mm_l_mx64_mir" material="almi_6_5mm_l_mx64_mir_material"/>
            <geom type="mesh" class="collision" pos="-0.0134121 0.0859 0.0065" quat="1.44329e-15 -2.60738e-15 0.707107 -0.707107" mesh="almi_6_5mm_l_mx64_mir" material="almi_6_5mm_l_mx64_mir_material"/>
            <!-- Part almi_6_5mm_l_mx64_mir_2 -->
            <geom type="mesh" class="visual" pos="-0.0134121 0.0859 0.047" quat="1.55431e-15 -2.64589e-15 0.707107 -0.707107" mesh="almi_6_5mm_l_mx64_mir" material="almi_6_5mm_l_mx64_mir_material"/>
            <geom type="mesh" class="collision" pos="-0.0134121 0.0859 0.047" quat="1.55431e-15 -2.64589e-15 0.707107 -0.707107" mesh="almi_6_5mm_l_mx64_mir" material="almi_6_5mm_l_mx64_mir_material"/>
            <!-- Part hn05_i101_mir -->
            <geom type="mesh" class="visual" pos="-9.85323e-16 0.134 0.04694" quat="0.5 0.5 0.5 0.5" mesh="hn05_i101_mir" material="hn05_i101_mir_material"/>
            <geom type="mesh" class="collision" pos="-9.85323e-16 0.134 0.04694" quat="0.5 0.5 0.5 0.5" mesh="hn05_i101_mir" material="hn05_i101_mir_material"/>
            <!-- Part rx64_cap_mir -->
            <geom type="mesh" class="visual" pos="-9.85323e-16 0.134 0.0467" quat="1.22857e-15 0.707107 0.707107 -2.24634e-15" mesh="rx64_cap_mir" material="rx64_cap_mir_material"/>
            <geom type="mesh" class="collision" pos="-9.85323e-16 0.134 0.0467" quat="1.22857e-15 0.707107 0.707107 -2.24634e-15" mesh="rx64_cap_mir" material="rx64_cap_mir_material"/>
            <!-- Part mf128zz_mir -->
            <geom type="mesh" class="visual" pos="-9.99201e-16 0.134 0.04322" quat="0.5 0.5 0.5 0.5" mesh="mf128zz_mir" material="mf128zz_mir_material"/>
            <geom type="mesh" class="collision" pos="-9.99201e-16 0.134 0.04322" quat="0.5 0.5 0.5 0.5" mesh="mf128zz_mir" material="mf128zz_mir_material"/>
            <!-- Link foot_left_3 -->
            <body name="foot_left_3" pos="-1.11022e-15 0.134 -4.996e-16" quat="1 -2.04697e-15 7.77156e-16 3.21965e-15">
              <!-- Joint from foot_left_2 to foot_left_3 -->
              <joint axis="0 0 1" name="left_knee" type="hinge"/>
              <inertial pos="0.00350206 0.0535427 0.0235017" mass="0.157154" fullinertia="0.000266743 0.000115972 0.000200186 8.33375e-06 -5.26492e-09 6.48605e-09"/>
              <!-- Part stainless_steel_2mm_shinebone_mir -->
              <geom type="mesh" class="visual" pos="0.0135 0.0197269 0.05" quat="0.707107 -0.707107 1.55431e-15 -1.27079e-15" mesh="stainless_steel_2mm_shinebone_mir" material="stainless_steel_2mm_shinebone_mir_material"/>
              <geom type="mesh" class="collision" pos="0.0135 0.0197269 0.05" quat="0.707107 -0.707107 1.55431e-15 -1.27079e-15" mesh="stainless_steel_2mm_shinebone_mir" material="stainless_steel_2mm_shinebone_mir_material"/>
              <!-- Part stainless_steel_2mm_leg_spacer_mir -->
              <geom type="mesh" class="visual" pos="0.024 0.0190814 0.045" quat="0.707107 -1.17113e-16 5.27356e-16 0.707107" mesh="stainless_steel_2mm_leg_spacer_mir" material="stainless_steel_2mm_leg_spacer_mir_material"/>
              <geom type="mesh" class="collision" pos="0.024 0.0190814 0.045" quat="0.707107 -1.17113e-16 5.27356e-16 0.707107" mesh="stainless_steel_2mm_leg_spacer_mir" material="stainless_steel_2mm_leg_spacer_mir_material"/>
              <!-- Part stainless_steel_2mm_shinebone_mir_2 -->
              <geom type="mesh" class="visual" pos="0.0135 0.0197269 6.93889e-18" quat="0.707107 -0.707107 -0 1.55794e-31" mesh="stainless_steel_2mm_shinebone_mir" material="stainless_steel_2mm_shinebone_mir_material"/>
              <geom type="mesh" class="collision" pos="0.0135 0.0197269 6.93889e-18" quat="0.707107 -0.707107 -0 1.55794e-31" mesh="stainless_steel_2mm_shinebone_mir" material="stainless_steel_2mm_shinebone_mir_material"/>
              <!-- Link foot_left_4 -->
              <body name="foot_left_4" pos="-8.32667e-17 0.111702 6.93889e-18" quat="1.67227e-15 -1 -2.08167e-17 -4.16334e-16">
                <!-- Joint from foot_left_3 to foot_left_4 -->
                <joint axis="0 0 1" name="left_ankle_pitch" type="hinge"/>
                <inertial pos="-0.0215978 0.0144559 -0.0236219" mass="0.292143" fullinertia="0.000112946 0.000262475 0.000302507 1.25975e-05 7.69402e-07 2.05066e-07"/>
                <!-- Part mx_64t_mir_2 -->
                <geom type="mesh" class="visual" pos="-0.04908 -1.11022e-15 -0.0235" quat="3.1549e-15 0.707107 6.66134e-15 -0.707107" mesh="mx_64t_mir_2" material="mx_64t_mir_2_material"/>
                <geom type="mesh" class="collision" pos="-0.04908 -1.11022e-15 -0.0235" quat="3.1549e-15 0.707107 6.66134e-15 -0.707107" mesh="mx_64t_mir_2" material="mx_64t_mir_2_material"/>
                <!-- Part almi_2mm_connector_mx64_mir_1 -->
                <geom type="mesh" class="visual" pos="-0.015 0.015 -0.0425" quat="0.5 0.5 -0.5 -0.5" mesh="almi_2mm_connector_mx64_mir_1" material="almi_2mm_connector_mx64_mir_1_material"/>
                <geom type="mesh" class="collision" pos="-0.015 0.015 -0.0425" quat="0.5 0.5 -0.5 -0.5" mesh="almi_2mm_connector_mx64_mir_1" material="almi_2mm_connector_mx64_mir_1_material"/>
                <!-- Part fr05_f101k_set_mir_1 -->
                <geom type="mesh" class="visual" pos="0.024 4.58208e-05 -0.0235" quat="0.5 -0.5 -0.5 0.5" mesh="fr05_f101k_set_mir_1" material="fr05_f101k_set_mir_1_material"/>
                <geom type="mesh" class="collision" pos="0.024 4.58208e-05 -0.0235" quat="0.5 -0.5 -0.5 0.5" mesh="fr05_f101k_set_mir_1" material="fr05_f101k_set_mir_1_material"/>
                <!-- Part mx_64t_mir_2_2 -->
                <geom type="mesh" class="visual" pos="0 5.55112e-17 -0.0235" quat="0 1 0 0" mesh="mx_64t_mir_2" material="mx_64t_mir_2_material"/>
                <geom type="mesh" class="collision" pos="0 5.55112e-17 -0.0235" quat="0 1 0 0" mesh="mx_64t_mir_2" material="mx_64t_mir_2_material"/>
                <!-- Part almi_2mm_fr05_f101k_set_mir_1 -->
                <geom type="mesh" class="visual" pos="0.024 4.44089e-16 -0.0235" quat="1.77126e-15 -0.707107 0.707107 1.1236e-15" mesh="almi_2mm_fr05_f101k_set_mir_1" material="almi_2mm_fr05_f101k_set_mir_1_material"/>
                <geom type="mesh" class="collision" pos="0.024 4.44089e-16 -0.0235" quat="1.77126e-15 -0.707107 0.707107 1.1236e-15" mesh="almi_2mm_fr05_f101k_set_mir_1" material="almi_2mm_fr05_f101k_set_mir_1_material"/>
                <!-- Part almi_2mm_connector_mx64_mir_1_2 -->
                <geom type="mesh" class="visual" pos="-0.015 0.043 -0.0045" quat="0.5 -0.5 -0.5 0.5" mesh="almi_2mm_connector_mx64_mir_1" material="almi_2mm_connector_mx64_mir_1_material"/>
                <geom type="mesh" class="collision" pos="-0.015 0.043 -0.0045" quat="0.5 -0.5 -0.5 0.5" mesh="almi_2mm_connector_mx64_mir_1" material="almi_2mm_connector_mx64_mir_1_material"/>
                <!-- Part hn05_i101_mir_2 -->
                <geom type="mesh" class="visual" pos="0 5.55112e-17 -0.04694" quat="0.707107 -0.707107 5.21805e-15 -4.50911e-15" mesh="hn05_i101_mir_2" material="hn05_i101_mir_2_material"/>
                <geom type="mesh" class="collision" pos="0 5.55112e-17 -0.04694" quat="0.707107 -0.707107 5.21805e-15 -4.50911e-15" mesh="hn05_i101_mir_2" material="hn05_i101_mir_2_material"/>
                <!-- Part mf128zz_mir_2 -->
                <geom type="mesh" class="visual" pos="0 5.55112e-17 -0.04322" quat="0.707107 -0.707107 5.10703e-15 -4.38154e-15" mesh="mf128zz_mir_2" material="mf128zz_mir_2_material"/>
                <geom type="mesh" class="collision" pos="0 5.55112e-17 -0.04322" quat="0.707107 -0.707107 5.10703e-15 -4.38154e-15" mesh="mf128zz_mir_2" material="mf128zz_mir_2_material"/>
                <!-- Part rx64_cap_mir_2 -->
                <geom type="mesh" class="visual" pos="1.38778e-17 5.55112e-17 -0.0467" quat="1 -2.00428e-15 3.33067e-16 -5.88245e-15" mesh="rx64_cap_mir_2" material="rx64_cap_mir_2_material"/>
                <geom type="mesh" class="collision" pos="1.38778e-17 5.55112e-17 -0.0467" quat="1 -2.00428e-15 3.33067e-16 -5.88245e-15" mesh="rx64_cap_mir_2" material="rx64_cap_mir_2_material"/>
                <!-- Part mf128zz_mir_2_2 -->
                <geom type="mesh" class="visual" pos="0.02622 4.58208e-05 -0.0235" quat="1.28395e-15 -0.707107 -0.707107 -1.85658e-15" mesh="mf128zz_mir_2" material="mf128zz_mir_2_material"/>
                <geom type="mesh" class="collision" pos="0.02622 4.58208e-05 -0.0235" quat="1.28395e-15 -0.707107 -0.707107 -1.85658e-15" mesh="mf128zz_mir_2" material="mf128zz_mir_2_material"/>
                <!-- Part hn05_i101_mir_2_2 -->
                <geom type="mesh" class="visual" pos="0.02994 4.58208e-05 -0.0235" quat="1.57631e-15 -0.707107 -0.707107 -2.07675e-15" mesh="hn05_i101_mir_2" material="hn05_i101_mir_2_material"/>
                <geom type="mesh" class="collision" pos="0.02994 4.58208e-05 -0.0235" quat="1.57631e-15 -0.707107 -0.707107 -2.07675e-15" mesh="hn05_i101_mir_2" material="hn05_i101_mir_2_material"/>
                <!-- Part rx64_cap_mir_2_2 -->
                <geom type="mesh" class="visual" pos="0.0297 4.58208e-05 -0.0235" quat="0.5 -0.5 -0.5 0.5" mesh="rx64_cap_mir_2" material="rx64_cap_mir_2_material"/>
                <geom type="mesh" class="collision" pos="0.0297 4.58208e-05 -0.0235" quat="0.5 -0.5 -0.5 0.5" mesh="rx64_cap_mir_2" material="rx64_cap_mir_2_material"/>
                <!-- Link foot_left_5 -->
                <body name="foot_left_5" pos="-0.02558 -4.996e-16 -0.0235" quat="0.707107 9.52114e-15 -0.707107 7.43849e-15">
                  <!-- Joint from foot_left_4 to foot_left_5 -->
                  <joint axis="0 0 1" name="left_ankle_roll" type="hinge"/>
                  <inertial pos="-0.00577513 -0.0300863 -0.0389132" mass="0.229936" fullinertia="0.000336096 0.000437543 0.000121048 -2.89074e-06 -4.67383e-06 5.55837e-07"/>
                  <!-- Part almi_2mm_lower_leg_mir -->
                  <geom type="mesh" class="visual" pos="-0.00775 -0.032 -0.02876" quat="1.18002e-15 -0.707107 5.32907e-15 -0.707107" mesh="almi_2mm_lower_leg_mir" material="almi_2mm_lower_leg_mir_material"/>
                  <geom type="mesh" class="collision" pos="-0.00775 -0.032 -0.02876" quat="1.18002e-15 -0.707107 5.32907e-15 -0.707107" mesh="almi_2mm_lower_leg_mir" material="almi_2mm_lower_leg_mir_material"/>
                  <!-- Part stainless_steel_2mm_lower_leg_bracket_mir -->
                  <geom type="mesh" class="visual" pos="-0.016 -0.032 -0.00052" quat="0.5 0.5 0.5 -0.5" mesh="stainless_steel_2mm_lower_leg_bracket_mir" material="stainless_steel_2mm_lower_leg_bracket_mir_material"/>
                  <geom type="mesh" class="collision" pos="-0.016 -0.032 -0.00052" quat="0.5 0.5 0.5 -0.5" mesh="stainless_steel_2mm_lower_leg_bracket_mir" material="stainless_steel_2mm_lower_leg_bracket_mir_material"/>
                  <!-- Part pla_50__shoes_mir -->
                  <geom type="mesh" class="visual" pos="-0.04925 -0.032 -0.10376" quat="0.707107 6.10923e-15 0.707107 1.88738e-15" mesh="pla_50__shoes_mir" material="pla_50__shoes_mir_material"/>
                  <geom type="mesh" class="collision" pos="-0.04925 -0.032 -0.10376" quat="0.707107 6.10923e-15 0.707107 1.88738e-15" mesh="pla_50__shoes_mir" material="pla_50__shoes_mir_material"/>
                </body>
              </body>
            </body>
          </body>
        </body>
      </body>
    </body>
  </worldbody>
  <asset>
    <mesh file="mf128zz_mir_1.stl"/>
    <mesh file="xt_bracket.stl"/>
    <mesh file="almi_5mm_bracket_servo_1_2.stl"/>
    <mesh file="stainless_steel_2mm_upper_leg_bracket_mir.stl"/>
    <mesh file="rx64_cap.stl"/>
    <mesh file="2nd_floor.stl"/>
    <mesh file="hn05_i101_1.stl"/>
    <mesh file="bracket_back_bumper_mir.stl"/>
    <mesh file="almi_6_5mm_l_mx64_mir.stl"/>
    <mesh file="stainless_steel_2mm_shinebone_mir.stl"/>
    <mesh file="almi_2mm_fr05_f101k_set.stl"/>
    <mesh file="back_bumper.stl"/>
    <mesh file="rx64_cap_mir_2.stl"/>
    <mesh file="hn05_i101.stl"/>
    <mesh file="front_upper_bumper.stl"/>
    <mesh file="handle_bracket_kidsize.stl"/>
    <mesh file="almi_2mm_connector_mx64_mir_1.stl"/>
    <mesh file="spacer_bracket_id_1_19_2.stl"/>
    <mesh file="fr05_f101k_set_mir_1.stl"/>
    <mesh file="camera_frame.stl"/>
    <mesh file="rx64_cap_1.stl"/>
    <mesh file="almi_2mm_fr05_f101k_set_mir.stl"/>
    <mesh file="mf128zz.stl"/>
    <mesh file="almi_4_5mm_connector_lower_arm_kidsize.stl"/>
    <mesh file="bracket_1_2_lower.stl"/>
    <mesh file="spacer_106_64_mir2_mir.stl"/>
    <mesh file="upper_floor.stl"/>
    <mesh file="pcnel_exch.stl"/>
    <mesh file="almi2_view_13__14__arm.stl"/>
    <mesh file="hn05_i101_mir.stl"/>
    <mesh file="almi_2mm_lower_leg.stl"/>
    <mesh file="fr05_f101k_set.stl"/>
    <mesh file="bracket_1_2_lower_left.stl"/>
    <mesh file="almi_2mm_connector_mx64.stl"/>
    <mesh file="spacer_106_64_mir2.stl"/>
    <mesh file="hn05_i101_2.stl"/>
    <mesh file="hn05_i101_mir_1.stl"/>
    <mesh file="holder_lower_bracket.stl"/>
    <mesh file="mx_64t.stl"/>
    <mesh file="fr05_f101k_set_mir.stl"/>
    <mesh file="stainless_steel_2mm_upper_leg_bracket.stl"/>
    <mesh file="mf128zz_2.stl"/>
    <mesh file="almi_2mm_floor_2nd__1.stl"/>
    <mesh file="mx_64t_mir.stl"/>
    <mesh file="stainless_steel_2mm__femur.stl"/>
    <mesh file="stainless_steel_2mm_leg_spacer.stl"/>
    <mesh file="mx_64t_1.stl"/>
    <mesh file="mx_64t_mir_1.stl"/>
    <mesh file="tpu_arm_kidsize_telapak.stl"/>
    <mesh file="carbon_2mm_arm_kidsize_1.stl"/>
    <mesh file="pla_50__shoes.stl"/>
    <mesh file="pla_50__shoes_mir.stl"/>
    <mesh file="mf128zz_mir_2.stl"/>
    <mesh file="mx_64t_mir_2.stl"/>
    <mesh file="front_upper_bumper_mir.stl"/>
    <mesh file="holder_lower_bracket_mir.stl"/>
    <mesh file="fr05_f101k_set_1.stl"/>
    <mesh file="handler_holder_siber.stl"/>
    <mesh file="bumper_front_lower.stl"/>
    <mesh file="camera_logitech_c920_offset_2mm.stl"/>
    <mesh file="almi_6_5mm_l_mx64.stl"/>
    <mesh file="stainless_steel_2mm_shinebone.stl"/>
    <mesh file="almi_2mm_fr05_f101k_set_mir_1.stl"/>
    <mesh file="rx64_cap_mir.stl"/>
    <mesh file="carbon_2mm_neck_side_plate.stl"/>
    <mesh file="almi_2mm_connector_mx64_mir.stl"/>
    <mesh file="almi_5mm_bracket_servo_1_2_left.stl"/>
    <mesh file="bracket_back_bumper.stl"/>
    <mesh file="handle.stl"/>
    <mesh file="bumper_front_lower_mir.stl"/>
    <mesh file="mf128zz_1.stl"/>
    <mesh file="rx64_cap_2.stl"/>
    <mesh file="rx64_cap_mir_1.stl"/>
    <mesh file="almi2_view_6_7__arm_bracket.stl"/>
    <mesh file="petg_2mm_rotatingheadbracket.stl"/>
    <mesh file="carbon_2mm_arm_kidsize_2.stl"/>
    <mesh file="petg_2mm_headbracket_old.stl"/>
    <mesh file="mx_64t_2.stl"/>
    <mesh file="spacer_bracket_id_1_19_2_mir.stl"/>
    <mesh file="stainless_steel_2mm__femur_mir.stl"/>
    <mesh file="front_pillar.stl"/>
    <mesh file="petg_5_19_mx28_seating.stl"/>
    <mesh file="almi_4mm_neck_bracket.stl"/>
    <mesh file="mx_64t_3.stl"/>
    <mesh file="stainless_steel_2mm_leg_spacer_mir.stl"/>
    <mesh file="almi_2mm_connector_mx64_1.stl"/>
    <mesh file="almi_2mm_lower_leg_mir.stl"/>
    <mesh file="battery_holder.stl"/>
    <mesh file="almi_2mm_fr05_f101k_set_1.stl"/>
    <mesh file="stainless_steel_2mm_lower_leg_bracket_mir.stl"/>
    <mesh file="mx_28.stl"/>
    <mesh file="stainless_steel_2mm_lower_leg_bracket.stl"/>
    <mesh file="hn05_i101_mir_2.stl"/>
    <mesh file="holder_bumper_upper.stl"/>
    <mesh file="mx_64t_mir1.stl"/>
    <mesh file="mf128zz_mir.stl"/>
    <material name="mx_64t_mir1_material" rgba="0.74902 0.74902 0.74902 1"/>
    <material name="mx_64t_material" rgba="0.211765 0.211765 0.211765 1"/>
    <material name="mx_28_material" rgba="0.266667 0.266667 0.266667 1"/>
    <material name="upper_floor_material" rgba="0.14902 0.152941 0.133333 1"/>
    <material name="2nd_floor_material" rgba="0.14902 0.152941 0.133333 1"/>
    <material name="front_pillar_material" rgba="0.996078 0.996078 1 1"/>
    <material name="pcnel_exch_material" rgba="0.74902 0.74902 0.74902 1"/>
    <material name="spacer_bracket_id_1_19_2_mir_material" rgba="0.74902 0.74902 0.74902 1"/>
    <material name="handle_bracket_kidsize_material" rgba="0.14902 0.152941 0.133333 1"/>
    <material name="almi_5mm_bracket_servo_1_2_left_material" rgba="0.74902 0.74902 0.74902 1"/>
    <material name="handle_material" rgba="0.996078 0.996078 1 1"/>
    <material name="holder_bumper_upper_material" rgba="0.74902 0.74902 0.74902 1"/>
    <material name="handler_holder_siber_material" rgba="0.0392157 0.0392157 0.0392157 1"/>
    <material name="bracket_1_2_lower_left_material" rgba="0.74902 0.74902 0.74902 1"/>
    <material name="front_upper_bumper_material" rgba="0.74902 0.74902 0.74902 1"/>
    <material name="petg_5_19_mx28_seating_material" rgba="0.74902 0.74902 0.74902 1"/>
    <material name="almi_5mm_bracket_servo_1_2_material" rgba="0.74902 0.74902 0.74902 1"/>
    <material name="spacer_bracket_id_1_19_2_material" rgba="0.74902 0.74902 0.74902 1"/>
    <material name="front_upper_bumper_mir_material" rgba="0.74902 0.74902 0.74902 1"/>
    <material name="bracket_1_2_lower_material" rgba="0.74902 0.74902 0.74902 1"/>
    <material name="bumper_front_lower_mir_material" rgba="0.74902 0.74902 0.74902 1"/>
    <material name="spacer_106_64_mir2_material" rgba="0.74902 0.74902 0.74902 1"/>
    <material name="holder_lower_bracket_mir_material" rgba="0.74902 0.74902 0.74902 1"/>
    <material name="almi_2mm_floor_2nd__1_material" rgba="0.74902 0.74902 0.74902 1"/>
    <material name="spacer_106_64_mir2_mir_material" rgba="0.74902 0.74902 0.74902 1"/>
    <material name="back_bumper_material" rgba="0.0196078 0.0196078 0.0196078 1"/>
    <material name="xt_bracket_material" rgba="0.996078 0.996078 1 1"/>
    <material name="battery_holder_material" rgba="0.996078 0.996078 1 1"/>
    <material name="bracket_back_bumper_material" rgba="0.74902 0.74902 0.74902 1"/>
    <material name="holder_lower_bracket_material" rgba="0.74902 0.74902 0.74902 1"/>
    <material name="bumper_front_lower_material" rgba="0.74902 0.74902 0.74902 1"/>
    <material name="bracket_back_bumper_mir_material" rgba="0.74902 0.74902 0.74902 1"/>
    <material name="almi_4mm_neck_bracket_material" rgba="0.0392157 0.0392157 0.0392157 1"/>
    <material name="carbon_2mm_neck_side_plate_material" rgba="0.14902 0.152941 0.133333 1"/>
    <material name="petg_2mm_headbracket_old_material" rgba="0.0392157 0.0392157 0.0392157 1"/>
    <material name="camera_logitech_c920_offset_2mm_material" rgba="0.792157 0.819608 0.933333 1"/>
    <material name="camera_frame_material" rgba="0.0392157 0.0392157 0.0392157 1"/>
    <material name="petg_2mm_rotatingheadbracket_material" rgba="0.0392157 0.0392157 0.0392157 1"/>
    <material name="almi2_view_6_7__arm_bracket_material" rgba="0.74902 0.74902 0.74902 1"/>
    <material name="almi2_view_13__14__arm_material" rgba="0.298039 0.298039 0.298039 1"/>
    <material name="almi_4_5mm_connector_lower_arm_kidsize_material" rgba="0.74902 0.74902 0.74902 1"/>
    <material name="carbon_2mm_arm_kidsize_1_material" rgba="0.74902 0.74902 0.74902 1"/>
    <material name="tpu_arm_kidsize_telapak_material" rgba="0.74902 0.74902 0.74902 1"/>
    <material name="carbon_2mm_arm_kidsize_2_material" rgba="0.74902 0.74902 0.74902 1"/>
    <material name="stainless_steel_2mm_upper_leg_bracket_material" rgba="0.745098 0.737255 0.729412 1"/>
    <material name="mx_64t_2_material" rgba="0.211765 0.211765 0.211765 1"/>
    <material name="almi_2mm_fr05_f101k_set_material" rgba="0 0 0 1"/>
    <material name="almi_2mm_connector_mx64_material" rgba="0.74902 0.74902 0.74902 1"/>
    <material name="fr05_f101k_set_material" rgba="0.376471 0.376471 0.376471 1"/>
    <material name="mf128zz_1_material" rgba="0.74902 0.74902 0.74902 1"/>
    <material name="rx64_cap_1_material" rgba="0.74902 0.74902 0.74902 1"/>
    <material name="hn05_i101_1_material" rgba="0.74902 0.74902 0.74902 1"/>
    <material name="stainless_steel_2mm__femur_material" rgba="0.74902 0.74902 0.74902 1"/>
    <material name="almi_6_5mm_l_mx64_material" rgba="0.74902 0.74902 0.74902 1"/>
    <material name="mx_64t_1_material" rgba="0.211765 0.211765 0.211765 1"/>
    <material name="hn05_i101_material" rgba="0.74902 0.74902 0.74902 1"/>
    <material name="mf128zz_material" rgba="0.74902 0.74902 0.74902 1"/>
    <material name="rx64_cap_material" rgba="0.74902 0.74902 0.74902 1"/>
    <material name="stainless_steel_2mm_leg_spacer_material" rgba="0.74902 0.74902 0.74902 1"/>
    <material name="stainless_steel_2mm_shinebone_material" rgba="0.74902 0.74902 0.74902 1"/>
    <material name="mx_64t_3_material" rgba="0.211765 0.211765 0.211765 1"/>
    <material name="fr05_f101k_set_1_material" rgba="0.376471 0.376471 0.376471 1"/>
    <material name="almi_2mm_connector_mx64_1_material" rgba="0.74902 0.74902 0.74902 1"/>
    <material name="almi_2mm_fr05_f101k_set_1_material" rgba="0 0 0 1"/>
    <material name="hn05_i101_2_material" rgba="0.74902 0.74902 0.74902 1"/>
    <material name="mf128zz_2_material" rgba="0.74902 0.74902 0.74902 1"/>
    <material name="rx64_cap_2_material" rgba="0.74902 0.74902 0.74902 1"/>
    <material name="pla_50__shoes_material" rgba="0.74902 0.74902 0.74902 1"/>
    <material name="almi_2mm_lower_leg_material" rgba="0.74902 0.74902 0.74902 1"/>
    <material name="stainless_steel_2mm_lower_leg_bracket_material" rgba="0.745098 0.737255 0.729412 1"/>
    <material name="stainless_steel_2mm_upper_leg_bracket_mir_material" rgba="0.74902 0.74902 0.74902 1"/>
    <material name="mx_64t_mir_1_material" rgba="0.74902 0.74902 0.74902 1"/>
    <material name="almi_2mm_fr05_f101k_set_mir_material" rgba="0.74902 0.74902 0.74902 1"/>
    <material name="almi_2mm_connector_mx64_mir_material" rgba="0.74902 0.74902 0.74902 1"/>
    <material name="fr05_f101k_set_mir_material" rgba="0.74902 0.74902 0.74902 1"/>
    <material name="mf128zz_mir_1_material" rgba="0.74902 0.74902 0.74902 1"/>
    <material name="hn05_i101_mir_1_material" rgba="0.74902 0.74902 0.74902 1"/>
    <material name="rx64_cap_mir_1_material" rgba="0.74902 0.74902 0.74902 1"/>
    <material name="mx_64t_mir_material" rgba="0.74902 0.74902 0.74902 1"/>
    <material name="stainless_steel_2mm__femur_mir_material" rgba="0.74902 0.74902 0.74902 1"/>
    <material name="almi_6_5mm_l_mx64_mir_material" rgba="0.74902 0.74902 0.74902 1"/>
    <material name="hn05_i101_mir_material" rgba="0.74902 0.74902 0.74902 1"/>
    <material name="rx64_cap_mir_material" rgba="0.74902 0.74902 0.74902 1"/>
    <material name="mf128zz_mir_material" rgba="0.74902 0.74902 0.74902 1"/>
    <material name="stainless_steel_2mm_shinebone_mir_material" rgba="0.74902 0.74902 0.74902 1"/>
    <material name="stainless_steel_2mm_leg_spacer_mir_material" rgba="0.74902 0.74902 0.74902 1"/>
    <material name="mx_64t_mir_2_material" rgba="0.74902 0.74902 0.74902 1"/>
    <material name="almi_2mm_connector_mx64_mir_1_material" rgba="0.74902 0.74902 0.74902 1"/>
    <material name="fr05_f101k_set_mir_1_material" rgba="0.74902 0.74902 0.74902 1"/>
    <material name="almi_2mm_fr05_f101k_set_mir_1_material" rgba="0.74902 0.74902 0.74902 1"/>
    <material name="hn05_i101_mir_2_material" rgba="0.74902 0.74902 0.74902 1"/>
    <material name="mf128zz_mir_2_material" rgba="0.74902 0.74902 0.74902 1"/>
    <material name="rx64_cap_mir_2_material" rgba="0.74902 0.74902 0.74902 1"/>
    <material name="almi_2mm_lower_leg_mir_material" rgba="0.74902 0.74902 0.74902 1"/>
    <material name="stainless_steel_2mm_lower_leg_bracket_mir_material" rgba="0.74902 0.74902 0.74902 1"/>
    <material name="pla_50__shoes_mir_material" rgba="0.74902 0.74902 0.74902 1"/>
  </asset>
  <actuator>
    <position class="project1" name="head_yaw" joint="head_yaw"/>
    <position class="project1" name="head_pitch" joint="head_pitch"/>
    <position class="project1" name="right_shoulder_pitch" joint="right_shoulder_pitch"/>
    <position class="project1" name="right_shoulder_roll" joint="right_shoulder_roll"/>
    <position class="project1" name="right_elbow" joint="right_elbow"/>
    <position class="project1" name="left_shoulder_pitch" joint="left_shoulder_pitch"/>
    <position class="project1" name="left_shoulder_roll" joint="left_shoulder_roll"/>
    <position class="project1" name="left_elbow" joint="left_elbow"/>
    <position class="project1" name="right_hip_yaw" joint="right_hip_yaw"/>
    <position class="project1" name="right_hip_roll" joint="right_hip_roll"/>
    <position class="project1" name="right_hip_pitch" joint="right_hip_pitch"/>
    <position class="project1" name="right_knee" joint="right_knee"/>
    <position class="project1" name="right_ankle_pitch" joint="right_ankle_pitch"/>
    <position class="project1" name="right_ankle_roll" joint="right_ankle_roll"/>
    <position class="project1" name="left_hip_yaw" joint="left_hip_yaw"/>
    <position class="project1" name="left_hip_roll" joint="left_hip_roll"/>
    <position class="project1" name="left_hip_pitch" joint="left_hip_pitch"/>
    <position class="project1" name="left_knee" joint="left_knee"/>
    <position class="project1" name="left_ankle_pitch" joint="left_ankle_pitch"/>
    <position class="project1" name="left_ankle_roll" joint="left_ankle_roll"/>
  </actuator>
  <equality/>
</mujoco>
