<?xml version="1.0" ?>
<!-- Generated using onshape-to-robot -->
<!-- Onshape document_id: 821537de265f690cd6a7463f -->
<robot name="project1">
  <!-- Link torso_kidsize25 -->
  <link name="torso_kidsize25">
    <inertial>
      <origin xyz="0.103344 0.0750782 0.0323184" rpy="0 0 0"/>
      <mass value="2.16719"/>
      <inertia ixx="0.00982507" ixy="-9.38024e-07" ixz="0.000706149" iyy="0.00929033" iyz="8.09787e-07" izz="0.00934245"/>
    </inertial>
    <!-- Part mx_64t_mir1 -->
    <visual>
      <origin xyz="0.0981628 0.0255728 0.0855046" rpy="3.14159 -1.44051e-14 -1.5708"/>
      <geometry>
        <mesh filename="package://assets/mx_64t_mir1.stl"/>
      </geometry>
      <material name="mx_64t_mir1_material">
        <color rgba="0.74902 0.74902 0.74902 1"/>
      </material>
    </visual>
    <collision>
      <origin xyz="0.0981628 0.0255728 0.0855046" rpy="3.14159 -1.44051e-14 -1.5708"/>
      <geometry>
        <mesh filename="package://assets/mx_64t_mir1.stl"/>
      </geometry>
    </collision>
    <!-- Part mx_64t -->
    <visual>
      <origin xyz="0.0981644 0.124573 0.0855046" rpy="5.21805e-15 1.43496e-14 1.5708"/>
      <geometry>
        <mesh filename="package://assets/mx_64t.stl"/>
      </geometry>
      <material name="mx_64t_material">
        <color rgba="0.211765 0.211765 0.211765 1"/>
      </material>
    </visual>
    <collision>
      <origin xyz="0.0981644 0.124573 0.0855046" rpy="5.21805e-15 1.43496e-14 1.5708"/>
      <geometry>
        <mesh filename="package://assets/mx_64t.stl"/>
      </geometry>
    </collision>
    <!-- Part mx_28 -->
    <visual>
      <origin xyz="0.167821 0.118573 -0.0392008" rpy="3.14159 1.5708 0"/>
      <geometry>
        <mesh filename="package://assets/mx_28.stl"/>
      </geometry>
      <material name="mx_28_material">
        <color rgba="0.266667 0.266667 0.266667 1"/>
      </material>
    </visual>
    <collision>
      <origin xyz="0.167821 0.118573 -0.0392008" rpy="3.14159 1.5708 0"/>
      <geometry>
        <mesh filename="package://assets/mx_28.stl"/>
      </geometry>
    </collision>
    <!-- Part mx_28_2 -->
    <visual>
      <origin xyz="0.0625405 0.0828915 -0.0259091" rpy="1.5708 1.09635e-14 1.5708"/>
      <geometry>
        <mesh filename="package://assets/mx_28.stl"/>
      </geometry>
      <material name="mx_28_2_material">
        <color rgba="0.266667 0.266667 0.266667 1"/>
      </material>
    </visual>
    <collision>
      <origin xyz="0.0625405 0.0828915 -0.0259091" rpy="1.5708 1.09635e-14 1.5708"/>
      <geometry>
        <mesh filename="package://assets/mx_28.stl"/>
      </geometry>
    </collision>
    <!-- Part mx_28_3 -->
    <visual>
      <origin xyz="0.167821 0.0315724 -0.02339" rpy="3.44169e-15 -1.5708 0"/>
      <geometry>
        <mesh filename="package://assets/mx_28.stl"/>
      </geometry>
      <material name="mx_28_3_material">
        <color rgba="0.266667 0.266667 0.266667 1"/>
      </material>
    </visual>
    <collision>
      <origin xyz="0.167821 0.0315724 -0.02339" rpy="3.44169e-15 -1.5708 0"/>
      <geometry>
        <mesh filename="package://assets/mx_28.stl"/>
      </geometry>
    </collision>
    <!-- Part upper_floor -->
    <visual>
      <origin xyz="0.145966 0.139451 -0.0104954" rpy="1.5708 5.17641e-15 1.05471e-15"/>
      <geometry>
        <mesh filename="package://assets/upper_floor.stl"/>
      </geometry>
      <material name="upper_floor_material">
        <color rgba="0.14902 0.152941 0.133333 1"/>
      </material>
    </visual>
    <collision>
      <origin xyz="0.145966 0.139451 -0.0104954" rpy="1.5708 5.17641e-15 1.05471e-15"/>
      <geometry>
        <mesh filename="package://assets/upper_floor.stl"/>
      </geometry>
    </collision>
    <!-- Part 2nd_floor -->
    <visual>
      <origin xyz="0.145966 0.0106948 0.0585046" rpy="-1.5708 -5.30131e-15 -3.14159"/>
      <geometry>
        <mesh filename="package://assets/2nd_floor.stl"/>
      </geometry>
      <material name="2nd_floor_material">
        <color rgba="0.14902 0.152941 0.133333 1"/>
      </material>
    </visual>
    <collision>
      <origin xyz="0.145966 0.0106948 0.0585046" rpy="-1.5708 -5.30131e-15 -3.14159"/>
      <geometry>
        <mesh filename="package://assets/2nd_floor.stl"/>
      </geometry>
    </collision>
    <!-- Part front_pillar -->
    <visual>
      <origin xyz="0.0369649 0.147073 0.0505046" rpy="-1.5708 -1.63203e-14 -1.5708"/>
      <geometry>
        <mesh filename="package://assets/front_pillar.stl"/>
      </geometry>
      <material name="front_pillar_material">
        <color rgba="0.996078 0.996078 1 1"/>
      </material>
    </visual>
    <collision>
      <origin xyz="0.0369649 0.147073 0.0505046" rpy="-1.5708 -1.63203e-14 -1.5708"/>
      <geometry>
        <mesh filename="package://assets/front_pillar.stl"/>
      </geometry>
    </collision>
    <!-- Part front_pillar_2 -->
    <visual>
      <origin xyz="0.0439649 0.00307279 0.0505046" rpy="-1.5708 1.6348e-14 1.5708"/>
      <geometry>
        <mesh filename="package://assets/front_pillar.stl"/>
      </geometry>
      <material name="front_pillar_2_material">
        <color rgba="0.996078 0.996078 1 1"/>
      </material>
    </visual>
    <collision>
      <origin xyz="0.0439649 0.00307279 0.0505046" rpy="-1.5708 1.6348e-14 1.5708"/>
      <geometry>
        <mesh filename="package://assets/front_pillar.stl"/>
      </geometry>
    </collision>
    <!-- Part front_pillar_3 -->
    <visual>
      <origin xyz="0.153965 0.00307279 0.0505046" rpy="-1.5708 1.62925e-14 1.5708"/>
      <geometry>
        <mesh filename="package://assets/front_pillar.stl"/>
      </geometry>
      <material name="front_pillar_3_material">
        <color rgba="0.996078 0.996078 1 1"/>
      </material>
    </visual>
    <collision>
      <origin xyz="0.153965 0.00307279 0.0505046" rpy="-1.5708 1.62925e-14 1.5708"/>
      <geometry>
        <mesh filename="package://assets/front_pillar.stl"/>
      </geometry>
    </collision>
    <!-- Part front_pillar_4 -->
    <visual>
      <origin xyz="0.146965 0.147073 -0.00249543" rpy="1.5708 5.34295e-15 1.33227e-15"/>
      <geometry>
        <mesh filename="package://assets/front_pillar.stl"/>
      </geometry>
      <material name="front_pillar_4_material">
        <color rgba="0.996078 0.996078 1 1"/>
      </material>
    </visual>
    <collision>
      <origin xyz="0.146965 0.147073 -0.00249543" rpy="1.5708 5.34295e-15 1.33227e-15"/>
      <geometry>
        <mesh filename="package://assets/front_pillar.stl"/>
      </geometry>
    </collision>
    <!-- Part pcnel_exch -->
    <visual>
      <origin xyz="0.0974649 0.0750728 -0.00749543" rpy="1.5708 5.3707e-15 1.11022e-15"/>
      <geometry>
        <mesh filename="package://assets/pcnel_exch.stl"/>
      </geometry>
      <material name="pcnel_exch_material">
        <color rgba="0.74902 0.74902 0.74902 1"/>
      </material>
    </visual>
    <collision>
      <origin xyz="0.0974649 0.0750728 -0.00749543" rpy="1.5708 5.3707e-15 1.11022e-15"/>
      <geometry>
        <mesh filename="package://assets/pcnel_exch.stl"/>
      </geometry>
    </collision>
    <!-- Part spacer_bracket_id_1_19_2_mir -->
    <visual>
      <origin xyz="0.124012 0.0383861 -0.0282569" rpy="-1.5708 1.09635e-14 1.5708"/>
      <geometry>
        <mesh filename="package://assets/spacer_bracket_id_1_19_2_mir.stl"/>
      </geometry>
      <material name="spacer_bracket_id_1_19_2_mir_material">
        <color rgba="0.74902 0.74902 0.74902 1"/>
      </material>
    </visual>
    <collision>
      <origin xyz="0.124012 0.0383861 -0.0282569" rpy="-1.5708 1.09635e-14 1.5708"/>
      <geometry>
        <mesh filename="package://assets/spacer_bracket_id_1_19_2_mir.stl"/>
      </geometry>
    </collision>
    <!-- Part handle_bracket_kidsize -->
    <visual>
      <origin xyz="0.074666 0.00707279 -0.0144954" rpy="1.5708 5.30131e-15 1.05471e-15"/>
      <geometry>
        <mesh filename="package://assets/handle_bracket_kidsize.stl"/>
      </geometry>
      <material name="handle_bracket_kidsize_material">
        <color rgba="0.14902 0.152941 0.133333 1"/>
      </material>
    </visual>
    <collision>
      <origin xyz="0.074666 0.00707279 -0.0144954" rpy="1.5708 5.30131e-15 1.05471e-15"/>
      <geometry>
        <mesh filename="package://assets/handle_bracket_kidsize.stl"/>
      </geometry>
    </collision>
    <!-- Part almi_5mm_bracket_servo_1_2_left -->
    <visual>
      <origin xyz="0.128758 0.0339361 -0.0333577" rpy="-1.5708 1.10745e-14 1.5708"/>
      <geometry>
        <mesh filename="package://assets/almi_5mm_bracket_servo_1_2_left.stl"/>
      </geometry>
      <material name="almi_5mm_bracket_servo_1_2_left_material">
        <color rgba="0.74902 0.74902 0.74902 1"/>
      </material>
    </visual>
    <collision>
      <origin xyz="0.128758 0.0339361 -0.0333577" rpy="-1.5708 1.10745e-14 1.5708"/>
      <geometry>
        <mesh filename="package://assets/almi_5mm_bracket_servo_1_2_left.stl"/>
      </geometry>
    </collision>
    <!-- Part handle -->
    <visual>
      <origin xyz="0.025166 0.0750728 -0.0674949" rpy="-1.5708 -1.5708 0"/>
      <geometry>
        <mesh filename="package://assets/handle.stl"/>
      </geometry>
      <material name="handle_material">
        <color rgba="0.996078 0.996078 1 1"/>
      </material>
    </visual>
    <collision>
      <origin xyz="0.025166 0.0750728 -0.0674949" rpy="-1.5708 -1.5708 0"/>
      <geometry>
        <mesh filename="package://assets/handle.stl"/>
      </geometry>
    </collision>
    <!-- Part holder_bumper_upper -->
    <visual>
      <origin xyz="0.0210947 0.141786 -0.0837461" rpy="-1.5708 1.15741e-14 1.5708"/>
      <geometry>
        <mesh filename="package://assets/holder_bumper_upper.stl"/>
      </geometry>
      <material name="holder_bumper_upper_material">
        <color rgba="0.74902 0.74902 0.74902 1"/>
      </material>
    </visual>
    <collision>
      <origin xyz="0.0210947 0.141786 -0.0837461" rpy="-1.5708 1.15741e-14 1.5708"/>
      <geometry>
        <mesh filename="package://assets/holder_bumper_upper.stl"/>
      </geometry>
    </collision>
    <!-- Part handler_holder_siber -->
    <visual>
      <origin xyz="0.142666 0.133573 0.027505" rpy="-1.5708 -5.28744e-15 -3.14159"/>
      <geometry>
        <mesh filename="package://assets/handler_holder_siber.stl"/>
      </geometry>
      <material name="handler_holder_siber_material">
        <color rgba="0.0392157 0.0392157 0.0392157 1"/>
      </material>
    </visual>
    <collision>
      <origin xyz="0.142666 0.133573 0.027505" rpy="-1.5708 -5.28744e-15 -3.14159"/>
      <geometry>
        <mesh filename="package://assets/handler_holder_siber.stl"/>
      </geometry>
    </collision>
    <!-- Part bracket_1_2_lower_left -->
    <visual>
      <origin xyz="0.129015 0.00858607 -0.0350437" rpy="-1.5708 -1.23235e-14 -1.5708"/>
      <geometry>
        <mesh filename="package://assets/bracket_1_2_lower_left.stl"/>
      </geometry>
      <material name="bracket_1_2_lower_left_material">
        <color rgba="0.74902 0.74902 0.74902 1"/>
      </material>
    </visual>
    <collision>
      <origin xyz="0.129015 0.00858607 -0.0350437" rpy="-1.5708 -1.23235e-14 -1.5708"/>
      <geometry>
        <mesh filename="package://assets/bracket_1_2_lower_left.stl"/>
      </geometry>
    </collision>
    <!-- Part front_upper_bumper -->
    <visual>
      <origin xyz="0.174531 0.146286 -0.0308954" rpy="-1.5708 -1.15741e-14 -1.5708"/>
      <geometry>
        <mesh filename="package://assets/front_upper_bumper.stl"/>
      </geometry>
      <material name="front_upper_bumper_material">
        <color rgba="0.74902 0.74902 0.74902 1"/>
      </material>
    </visual>
    <collision>
      <origin xyz="0.174531 0.146286 -0.0308954" rpy="-1.5708 -1.15741e-14 -1.5708"/>
      <geometry>
        <mesh filename="package://assets/front_upper_bumper.stl"/>
      </geometry>
    </collision>
    <!-- Part petg_5_19_mx28_seating -->
    <visual>
      <origin xyz="0.140931 0.0625825 -0.0177454" rpy="1.5708 -1.79579e-14 -1.5708"/>
      <geometry>
        <mesh filename="package://assets/petg_5_19_mx28_seating.stl"/>
      </geometry>
      <material name="petg_5_19_mx28_seating_material">
        <color rgba="0.74902 0.74902 0.74902 1"/>
      </material>
    </visual>
    <collision>
      <origin xyz="0.140931 0.0625825 -0.0177454" rpy="1.5708 -1.79579e-14 -1.5708"/>
      <geometry>
        <mesh filename="package://assets/petg_5_19_mx28_seating.stl"/>
      </geometry>
    </collision>
    <!-- Part almi_5mm_bracket_servo_1_2 -->
    <visual>
      <origin xyz="0.128758 0.11621 -0.0333577" rpy="-1.5708 -1.79301e-14 -1.5708"/>
      <geometry>
        <mesh filename="package://assets/almi_5mm_bracket_servo_1_2.stl"/>
      </geometry>
      <material name="almi_5mm_bracket_servo_1_2_material">
        <color rgba="0.74902 0.74902 0.74902 1"/>
      </material>
    </visual>
    <collision>
      <origin xyz="0.128758 0.11621 -0.0333577" rpy="-1.5708 -1.79301e-14 -1.5708"/>
      <geometry>
        <mesh filename="package://assets/almi_5mm_bracket_servo_1_2.stl"/>
      </geometry>
    </collision>
    <!-- Part spacer_bracket_id_1_19_2 -->
    <visual>
      <origin xyz="0.124012 0.11176 -0.0282569" rpy="-1.5708 -1.79579e-14 -1.5708"/>
      <geometry>
        <mesh filename="package://assets/spacer_bracket_id_1_19_2.stl"/>
      </geometry>
      <material name="spacer_bracket_id_1_19_2_material">
        <color rgba="0.74902 0.74902 0.74902 1"/>
      </material>
    </visual>
    <collision>
      <origin xyz="0.124012 0.11176 -0.0282569" rpy="-1.5708 -1.79579e-14 -1.5708"/>
      <geometry>
        <mesh filename="package://assets/spacer_bracket_id_1_19_2.stl"/>
      </geometry>
    </collision>
    <!-- Part handler_holder_siber_2 -->
    <visual>
      <origin xyz="0.142666 0.00657279 0.027505" rpy="-1.5708 -5.32907e-15 -3.14159"/>
      <geometry>
        <mesh filename="package://assets/handler_holder_siber.stl"/>
      </geometry>
      <material name="handler_holder_siber_2_material">
        <color rgba="0.0392157 0.0392157 0.0392157 1"/>
      </material>
    </visual>
    <collision>
      <origin xyz="0.142666 0.00657279 0.027505" rpy="-1.5708 -5.32907e-15 -3.14159"/>
      <geometry>
        <mesh filename="package://assets/handler_holder_siber.stl"/>
      </geometry>
    </collision>
    <!-- Part front_upper_bumper_mir -->
    <visual>
      <origin xyz="0.174531 0.00408607 -0.0308954" rpy="-1.5708 1.15741e-14 1.5708"/>
      <geometry>
        <mesh filename="package://assets/front_upper_bumper_mir.stl"/>
      </geometry>
      <material name="front_upper_bumper_mir_material">
        <color rgba="0.74902 0.74902 0.74902 1"/>
      </material>
    </visual>
    <collision>
      <origin xyz="0.174531 0.00408607 -0.0308954" rpy="-1.5708 1.15741e-14 1.5708"/>
      <geometry>
        <mesh filename="package://assets/front_upper_bumper_mir.stl"/>
      </geometry>
    </collision>
    <!-- Part handle_bracket_kidsize_2 -->
    <visual>
      <origin xyz="0.074666 0.143073 -0.0144954" rpy="1.5708 5.25968e-15 2.16493e-15"/>
      <geometry>
        <mesh filename="package://assets/handle_bracket_kidsize.stl"/>
      </geometry>
      <material name="handle_bracket_kidsize_2_material">
        <color rgba="0.14902 0.152941 0.133333 1"/>
      </material>
    </visual>
    <collision>
      <origin xyz="0.074666 0.143073 -0.0144954" rpy="1.5708 5.25968e-15 2.16493e-15"/>
      <geometry>
        <mesh filename="package://assets/handle_bracket_kidsize.stl"/>
      </geometry>
    </collision>
    <!-- Part bracket_1_2_lower -->
    <visual>
      <origin xyz="0.129015 0.14156 -0.0350437" rpy="-1.5708 1.89571e-14 1.5708"/>
      <geometry>
        <mesh filename="package://assets/bracket_1_2_lower.stl"/>
      </geometry>
      <material name="bracket_1_2_lower_material">
        <color rgba="0.74902 0.74902 0.74902 1"/>
      </material>
    </visual>
    <collision>
      <origin xyz="0.129015 0.14156 -0.0350437" rpy="-1.5708 1.89571e-14 1.5708"/>
      <geometry>
        <mesh filename="package://assets/bracket_1_2_lower.stl"/>
      </geometry>
    </collision>
    <!-- Part bumper_front_lower_mir -->
    <visual>
      <origin xyz="0.177163 0.00657279 0.0805404" rpy="-1.5708 1.44884e-14 1.5708"/>
      <geometry>
        <mesh filename="package://assets/bumper_front_lower_mir.stl"/>
      </geometry>
      <material name="bumper_front_lower_mir_material">
        <color rgba="0.74902 0.74902 0.74902 1"/>
      </material>
    </visual>
    <collision>
      <origin xyz="0.177163 0.00657279 0.0805404" rpy="-1.5708 1.44884e-14 1.5708"/>
      <geometry>
        <mesh filename="package://assets/bumper_front_lower_mir.stl"/>
      </geometry>
    </collision>
    <!-- Part spacer_106_64_mir2 -->
    <visual>
      <origin xyz="0.123822 0.122909 0.0685046" rpy="-1.33227e-15 1.5708 0"/>
      <geometry>
        <mesh filename="package://assets/spacer_106_64_mir2.stl"/>
      </geometry>
      <material name="spacer_106_64_mir2_material">
        <color rgba="0.74902 0.74902 0.74902 1"/>
      </material>
    </visual>
    <collision>
      <origin xyz="0.123822 0.122909 0.0685046" rpy="-1.33227e-15 1.5708 0"/>
      <geometry>
        <mesh filename="package://assets/spacer_106_64_mir2.stl"/>
      </geometry>
    </collision>
    <!-- Part holder_lower_bracket_mir -->
    <visual>
      <origin xyz="0.148663 0.0342753 0.0388323" rpy="1.5708 1.44329e-14 1.5708"/>
      <geometry>
        <mesh filename="package://assets/holder_lower_bracket_mir.stl"/>
      </geometry>
      <material name="holder_lower_bracket_mir_material">
        <color rgba="0.74902 0.74902 0.74902 1"/>
      </material>
    </visual>
    <collision>
      <origin xyz="0.148663 0.0342753 0.0388323" rpy="1.5708 1.44329e-14 1.5708"/>
      <geometry>
        <mesh filename="package://assets/holder_lower_bracket_mir.stl"/>
      </geometry>
    </collision>
    <!-- Part almi_2mm_floor_2nd__1 -->
    <visual>
      <origin xyz="0.0992116 0.0787323 0.102505" rpy="1.5708 -1.5708 0"/>
      <geometry>
        <mesh filename="package://assets/almi_2mm_floor_2nd__1.stl"/>
      </geometry>
      <material name="almi_2mm_floor_2nd__1_material">
        <color rgba="0.74902 0.74902 0.74902 1"/>
      </material>
    </visual>
    <collision>
      <origin xyz="0.0992116 0.0787323 0.102505" rpy="1.5708 -1.5708 0"/>
      <geometry>
        <mesh filename="package://assets/almi_2mm_floor_2nd__1.stl"/>
      </geometry>
    </collision>
    <!-- Part spacer_106_64_mir2_mir -->
    <visual>
      <origin xyz="0.12382 0.0272362 0.0685046" rpy="3.14159 1.5708 0"/>
      <geometry>
        <mesh filename="package://assets/spacer_106_64_mir2_mir.stl"/>
      </geometry>
      <material name="spacer_106_64_mir2_mir_material">
        <color rgba="0.74902 0.74902 0.74902 1"/>
      </material>
    </visual>
    <collision>
      <origin xyz="0.12382 0.0272362 0.0685046" rpy="3.14159 1.5708 0"/>
      <geometry>
        <mesh filename="package://assets/spacer_106_64_mir2_mir.stl"/>
      </geometry>
    </collision>
    <!-- Part back_bumper -->
    <visual>
      <origin xyz="0.0544633 0.0103728 0.0815046" rpy="-1.5708 -5.20417e-15 -3.14159"/>
      <geometry>
        <mesh filename="package://assets/back_bumper.stl"/>
      </geometry>
      <material name="back_bumper_material">
        <color rgba="0.0196078 0.0196078 0.0196078 1"/>
      </material>
    </visual>
    <collision>
      <origin xyz="0.0544633 0.0103728 0.0815046" rpy="-1.5708 -5.20417e-15 -3.14159"/>
      <geometry>
        <mesh filename="package://assets/back_bumper.stl"/>
      </geometry>
    </collision>
    <!-- Part xt_bracket -->
    <visual>
      <origin xyz="0.0414633 0.0442728 0.102505" rpy="-3.14159 1.44329e-14 1.5708"/>
      <geometry>
        <mesh filename="package://assets/xt_bracket.stl"/>
      </geometry>
      <material name="xt_bracket_material">
        <color rgba="0.996078 0.996078 1 1"/>
      </material>
    </visual>
    <collision>
      <origin xyz="0.0414633 0.0442728 0.102505" rpy="-3.14159 1.44329e-14 1.5708"/>
      <geometry>
        <mesh filename="package://assets/xt_bracket.stl"/>
      </geometry>
    </collision>
    <!-- Part battery_holder -->
    <visual>
      <origin xyz="0.153463 0.0750728 0.107505" rpy="-1.5708 -5.30131e-15 -3.14159"/>
      <geometry>
        <mesh filename="package://assets/battery_holder.stl"/>
      </geometry>
      <material name="battery_holder_material">
        <color rgba="0.996078 0.996078 1 1"/>
      </material>
    </visual>
    <collision>
      <origin xyz="0.153463 0.0750728 0.107505" rpy="-1.5708 -5.30131e-15 -3.14159"/>
      <geometry>
        <mesh filename="package://assets/battery_holder.stl"/>
      </geometry>
    </collision>
    <!-- Part back_bumper_2 -->
    <visual>
      <origin xyz="0.0544633 0.139773 0.0815046" rpy="1.5708 -5.28744e-15 -3.14159"/>
      <geometry>
        <mesh filename="package://assets/back_bumper.stl"/>
      </geometry>
      <material name="back_bumper_2_material">
        <color rgba="0.0196078 0.0196078 0.0196078 1"/>
      </material>
    </visual>
    <collision>
      <origin xyz="0.0544633 0.139773 0.0815046" rpy="1.5708 -5.28744e-15 -3.14159"/>
      <geometry>
        <mesh filename="package://assets/back_bumper.stl"/>
      </geometry>
    </collision>
    <!-- Part bracket_back_bumper -->
    <visual>
      <origin xyz="0.0524633 0.0298728 0.0805046" rpy="-1.5708 1.43219e-14 1.5708"/>
      <geometry>
        <mesh filename="package://assets/bracket_back_bumper.stl"/>
      </geometry>
      <material name="bracket_back_bumper_material">
        <color rgba="0.74902 0.74902 0.74902 1"/>
      </material>
    </visual>
    <collision>
      <origin xyz="0.0524633 0.0298728 0.0805046" rpy="-1.5708 1.43219e-14 1.5708"/>
      <geometry>
        <mesh filename="package://assets/bracket_back_bumper.stl"/>
      </geometry>
    </collision>
    <!-- Part holder_lower_bracket -->
    <visual>
      <origin xyz="0.148664 0.11587 0.0388323" rpy="1.5708 -4.54081e-14 -1.5708"/>
      <geometry>
        <mesh filename="package://assets/holder_lower_bracket.stl"/>
      </geometry>
      <material name="holder_lower_bracket_material">
        <color rgba="0.74902 0.74902 0.74902 1"/>
      </material>
    </visual>
    <collision>
      <origin xyz="0.148664 0.11587 0.0388323" rpy="1.5708 -4.54081e-14 -1.5708"/>
      <geometry>
        <mesh filename="package://assets/holder_lower_bracket.stl"/>
      </geometry>
    </collision>
    <!-- Part xt_bracket_2 -->
    <visual>
      <origin xyz="0.0454633 0.105873 0.102505" rpy="3.14159 -1.43496e-14 -1.5708"/>
      <geometry>
        <mesh filename="package://assets/xt_bracket.stl"/>
      </geometry>
      <material name="xt_bracket_2_material">
        <color rgba="0.996078 0.996078 1 1"/>
      </material>
    </visual>
    <collision>
      <origin xyz="0.0454633 0.105873 0.102505" rpy="3.14159 -1.43496e-14 -1.5708"/>
      <geometry>
        <mesh filename="package://assets/xt_bracket.stl"/>
      </geometry>
    </collision>
    <!-- Part bumper_front_lower -->
    <visual>
      <origin xyz="0.177164 0.143573 0.0805404" rpy="-1.5708 -4.54081e-14 -1.5708"/>
      <geometry>
        <mesh filename="package://assets/bumper_front_lower.stl"/>
      </geometry>
      <material name="bumper_front_lower_material">
        <color rgba="0.74902 0.74902 0.74902 1"/>
      </material>
    </visual>
    <collision>
      <origin xyz="0.177164 0.143573 0.0805404" rpy="-1.5708 -4.54081e-14 -1.5708"/>
      <geometry>
        <mesh filename="package://assets/bumper_front_lower.stl"/>
      </geometry>
    </collision>
    <!-- Part bracket_back_bumper_mir -->
    <visual>
      <origin xyz="0.0524633 0.120273 0.0805046" rpy="-1.5708 -1.43219e-14 -1.5708"/>
      <geometry>
        <mesh filename="package://assets/bracket_back_bumper_mir.stl"/>
      </geometry>
      <material name="bracket_back_bumper_mir_material">
        <color rgba="0.74902 0.74902 0.74902 1"/>
      </material>
    </visual>
    <collision>
      <origin xyz="0.0524633 0.120273 0.0805046" rpy="-1.5708 -1.43219e-14 -1.5708"/>
      <geometry>
        <mesh filename="package://assets/bracket_back_bumper_mir.stl"/>
      </geometry>
    </collision>
  </link>
  <!-- Link neck -->
  <link name="neck">
    <inertial>
      <origin xyz="2.39298e-07 -1.6286e-17 -0.00879985" rpy="0 0 0"/>
      <mass value="0.0128985"/>
      <inertia ixx="5.01235e-06" ixy="-2.63324e-11" ixz="9.38605e-13" iyy="2.39998e-06" iyz="-4.12929e-21" izz="4.13467e-06"/>
    </inertial>
    <!-- Part almi_4mm_neck_bracket -->
    <visual>
      <origin xyz="0.0128945 0.0185 0" rpy="-1.5708 -5.60519e-45 -9.86076e-32"/>
      <geometry>
        <mesh filename="package://assets/almi_4mm_neck_bracket.stl"/>
      </geometry>
      <material name="almi_4mm_neck_bracket_material">
        <color rgba="0.0392157 0.0392157 0.0392157 1"/>
      </material>
    </visual>
    <collision>
      <origin xyz="0.0128945 0.0185 0" rpy="-1.5708 -5.60519e-45 -9.86076e-32"/>
      <geometry>
        <mesh filename="package://assets/almi_4mm_neck_bracket.stl"/>
      </geometry>
    </collision>
    <!-- Part carbon_2mm_neck_side_plate -->
    <visual>
      <origin xyz="5e-07 0.0205 -0.02" rpy="-1.5708 7.88861e-31 -6.82787e-15"/>
      <geometry>
        <mesh filename="package://assets/carbon_2mm_neck_side_plate.stl"/>
      </geometry>
      <material name="carbon_2mm_neck_side_plate_material">
        <color rgba="0.14902 0.152941 0.133333 1"/>
      </material>
    </visual>
    <collision>
      <origin xyz="5e-07 0.0205 -0.02" rpy="-1.5708 7.88861e-31 -6.82787e-15"/>
      <geometry>
        <mesh filename="package://assets/carbon_2mm_neck_side_plate.stl"/>
      </geometry>
    </collision>
    <!-- Part carbon_2mm_neck_side_plate_2 -->
    <visual>
      <origin xyz="-2.77556e-17 -0.0225 -0.02" rpy="-1.5708 2.36658e-30 -4.60743e-15"/>
      <geometry>
        <mesh filename="package://assets/carbon_2mm_neck_side_plate.stl"/>
      </geometry>
      <material name="carbon_2mm_neck_side_plate_2_material">
        <color rgba="0.14902 0.152941 0.133333 1"/>
      </material>
    </visual>
    <collision>
      <origin xyz="-2.77556e-17 -0.0225 -0.02" rpy="-1.5708 2.36658e-30 -4.60743e-15"/>
      <geometry>
        <mesh filename="package://assets/carbon_2mm_neck_side_plate.stl"/>
      </geometry>
    </collision>
  </link>
  <!-- Link head -->
  <link name="head">
    <inertial>
      <origin xyz="0.0315459 0.00214801 -0.0205645" rpy="0 0 0"/>
      <mass value="0.371554"/>
      <inertia ixx="0.000238323" ixy="-4.47308e-05" ixz="2.28198e-07" iyy="0.000308835" iyz="-2.79152e-07" izz="0.000217343"/>
    </inertial>
    <!-- Part petg_2mm_headbracket_old -->
    <visual>
      <origin xyz="-0.0064 -0.0265 -0.0386" rpy="-1.5708 -1.5708 0"/>
      <geometry>
        <mesh filename="package://assets/petg_2mm_headbracket_old.stl"/>
      </geometry>
      <material name="petg_2mm_headbracket_old_material">
        <color rgba="0.0392157 0.0392157 0.0392157 1"/>
      </material>
    </visual>
    <collision>
      <origin xyz="-0.0064 -0.0265 -0.0386" rpy="-1.5708 -1.5708 0"/>
      <geometry>
        <mesh filename="package://assets/petg_2mm_headbracket_old.stl"/>
      </geometry>
    </collision>
    <!-- Part camera_logitech_c920_offset_2mm -->
    <visual>
      <origin xyz="0.0256 -0.00182638 -0.06759" rpy="-1.5708 -1.5708 0"/>
      <geometry>
        <mesh filename="package://assets/camera_logitech_c920_offset_2mm.stl"/>
      </geometry>
      <material name="camera_logitech_c920_offset_2mm_material">
        <color rgba="0.792157 0.819608 0.933333 1"/>
      </material>
    </visual>
    <collision>
      <origin xyz="0.0256 -0.00182638 -0.06759" rpy="-1.5708 -1.5708 0"/>
      <geometry>
        <mesh filename="package://assets/camera_logitech_c920_offset_2mm.stl"/>
      </geometry>
    </collision>
    <!-- Part camera_frame -->
    <visual>
      <origin xyz="0.0251 0.0215 -0.0535485" rpy="-5.82867e-15 -8.21565e-15 -1.5708"/>
      <geometry>
        <mesh filename="package://assets/camera_frame.stl"/>
      </geometry>
      <material name="camera_frame_material">
        <color rgba="0.0392157 0.0392157 0.0392157 1"/>
      </material>
    </visual>
    <collision>
      <origin xyz="0.0251 0.0215 -0.0535485" rpy="-5.82867e-15 -8.21565e-15 -1.5708"/>
      <geometry>
        <mesh filename="package://assets/camera_frame.stl"/>
      </geometry>
    </collision>
    <!-- Part mx_28_4 -->
    <visual>
      <origin xyz="0.0079054 -0.0653899 -0.0287863" rpy="-1.5708 -4.00593e-30 -3.69779e-32"/>
      <geometry>
        <mesh filename="package://assets/mx_28.stl"/>
      </geometry>
      <material name="mx_28_4_material">
        <color rgba="0.266667 0.266667 0.266667 1"/>
      </material>
    </visual>
    <collision>
      <origin xyz="0.0079054 -0.0653899 -0.0287863" rpy="-1.5708 -4.00593e-30 -3.69779e-32"/>
      <geometry>
        <mesh filename="package://assets/mx_28.stl"/>
      </geometry>
    </collision>
    <!-- Part petg_2mm_rotatingheadbracket -->
    <visual>
      <origin xyz="-0.0064 -0.0265 -0.0386" rpy="-1.5708 -1.5708 0"/>
      <geometry>
        <mesh filename="package://assets/petg_2mm_rotatingheadbracket.stl"/>
      </geometry>
      <material name="petg_2mm_rotatingheadbracket_material">
        <color rgba="0.0392157 0.0392157 0.0392157 1"/>
      </material>
    </visual>
    <collision>
      <origin xyz="-0.0064 -0.0265 -0.0386" rpy="-1.5708 -1.5708 0"/>
      <geometry>
        <mesh filename="package://assets/petg_2mm_rotatingheadbracket.stl"/>
      </geometry>
    </collision>
  </link>
  <!-- Joint from neck to head -->
  <joint name="head_pitch" type="revolute">
    <origin xyz="5e-07 0.0205 -0.037" rpy="-1.5708 1.5708 0"/>
    <parent link="neck"/>
    <child link="head"/>
    <axis xyz="0 0 1"/>
    <limit effort="10" velocity="10" lower="-3.141592653589793" upper="3.141592653589793"/>
  </joint>
  <!-- Joint from torso_kidsize25 to neck -->
  <joint name="head_yaw" type="revolute">
    <origin xyz="0.12793 0.0749861 -0.0546954" rpy="8.71525e-15 -5.77316e-15 -3.14159"/>
    <parent link="torso_kidsize25"/>
    <child link="neck"/>
    <axis xyz="0 0 1"/>
    <limit effort="10" velocity="10" lower="-3.141592653589793" upper="3.141592653589793"/>
  </joint>
  <!-- Link almi2_view_6_7__arm_bracket -->
  <link name="almi2_view_6_7__arm_bracket">
    <inertial>
      <origin xyz="-9.36751e-17 0.00223841 -0.00829596" rpy="0 0 0"/>
      <mass value="0.0151289"/>
      <inertia ixx="2.57897e-06" ixy="5.42452e-37" ixz="9.2965e-37" iyy="5.57377e-06" iyz="4.04961e-07" izz="5.85595e-06"/>
    </inertial>
    <!-- Part almi2_view_6_7__arm_bracket -->
    <visual>
      <origin xyz="0.0185 -0.012 -0.002" rpy="1.5708 -4.36031e-31 1.01073e-30"/>
      <geometry>
        <mesh filename="package://assets/almi2_view_6_7__arm_bracket.stl"/>
      </geometry>
      <material name="almi2_view_6_7__arm_bracket_material">
        <color rgba="0.74902 0.74902 0.74902 1"/>
      </material>
    </visual>
    <collision>
      <origin xyz="0.0185 -0.012 -0.002" rpy="1.5708 -4.36031e-31 1.01073e-30"/>
      <geometry>
        <mesh filename="package://assets/almi2_view_6_7__arm_bracket.stl"/>
      </geometry>
    </collision>
  </link>
  <!-- Link right_upperhand -->
  <link name="right_upperhand">
    <inertial>
      <origin xyz="-4.16556e-05 -0.0497057 -0.0229115" rpy="0 0 0"/>
      <mass value="0.178"/>
      <inertia ixx="0.000293103" ixy="-7.35413e-07" ixz="-2.0111e-08" iyy="3.4849e-05" iyz="-1.67161e-05" izz="0.00029267"/>
    </inertial>
    <!-- Part mx_28_5 -->
    <visual>
      <origin xyz="0.00818918 -0.0341201 -0.0335054" rpy="1.5708 1.5708 0"/>
      <geometry>
        <mesh filename="package://assets/mx_28.stl"/>
      </geometry>
      <material name="mx_28_5_material">
        <color rgba="0.266667 0.266667 0.266667 1"/>
      </material>
    </visual>
    <collision>
      <origin xyz="0.00818918 -0.0341201 -0.0335054" rpy="1.5708 1.5708 0"/>
      <geometry>
        <mesh filename="package://assets/mx_28.stl"/>
      </geometry>
    </collision>
    <!-- Part mx_28_6 -->
    <visual>
      <origin xyz="0.0079054 -0.0653899 -0.0287863" rpy="-1.5708 -3.45127e-31 1.13399e-30"/>
      <geometry>
        <mesh filename="package://assets/mx_28.stl"/>
      </geometry>
      <material name="mx_28_6_material">
        <color rgba="0.266667 0.266667 0.266667 1"/>
      </material>
    </visual>
    <collision>
      <origin xyz="0.0079054 -0.0653899 -0.0287863" rpy="-1.5708 -3.45127e-31 1.13399e-30"/>
      <geometry>
        <mesh filename="package://assets/mx_28.stl"/>
      </geometry>
    </collision>
    <!-- Part almi2_view_13__14__arm -->
    <visual>
      <origin xyz="-0.0819971 -0.058605 -0.0256" rpy="3.88578e-16 -7.77156e-16 1.11022e-16"/>
      <geometry>
        <mesh filename="package://assets/almi2_view_13__14__arm.stl"/>
      </geometry>
      <material name="almi2_view_13__14__arm_material">
        <color rgba="0.298039 0.298039 0.298039 1"/>
      </material>
    </visual>
    <collision>
      <origin xyz="-0.0819971 -0.058605 -0.0256" rpy="3.88578e-16 -7.77156e-16 1.11022e-16"/>
      <geometry>
        <mesh filename="package://assets/almi2_view_13__14__arm.stl"/>
      </geometry>
    </collision>
  </link>
  <!-- Link right_lowerhand -->
  <link name="right_lowerhand">
    <inertial>
      <origin xyz="-0.00130389 -0.103918 0.0103596" rpy="0 0 0"/>
      <mass value="0.149258"/>
      <inertia ixx="0.000225269" ixy="-7.02224e-06" ixz="-1.20544e-07" iyy="5.61474e-05" iyz="-3.26703e-05" izz="0.000240431"/>
    </inertial>
    <!-- Part almi_4_5mm_connector_lower_arm_kidsize -->
    <visual>
      <origin xyz="0.00225 -0.0405 1.04083e-16" rpy="1.5708 9.71445e-17 -3.14159"/>
      <geometry>
        <mesh filename="package://assets/almi_4_5mm_connector_lower_arm_kidsize.stl"/>
      </geometry>
      <material name="almi_4_5mm_connector_lower_arm_kidsize_material">
        <color rgba="0.74902 0.74902 0.74902 1"/>
      </material>
    </visual>
    <collision>
      <origin xyz="0.00225 -0.0405 1.04083e-16" rpy="1.5708 9.71445e-17 -3.14159"/>
      <geometry>
        <mesh filename="package://assets/almi_4_5mm_connector_lower_arm_kidsize.stl"/>
      </geometry>
    </collision>
    <!-- Part carbon_2mm_arm_kidsize_1 -->
    <visual>
      <origin xyz="0 0 0" rpy="1.5708 1.5708 0"/>
      <geometry>
        <mesh filename="package://assets/carbon_2mm_arm_kidsize_1.stl"/>
      </geometry>
      <material name="carbon_2mm_arm_kidsize_1_material">
        <color rgba="0.74902 0.74902 0.74902 1"/>
      </material>
    </visual>
    <collision>
      <origin xyz="0 0 0" rpy="1.5708 1.5708 0"/>
      <geometry>
        <mesh filename="package://assets/carbon_2mm_arm_kidsize_1.stl"/>
      </geometry>
    </collision>
    <!-- Part tpu_arm_kidsize_telapak -->
    <visual>
      <origin xyz="-2.77556e-17 -0.14 0.0728" rpy="1.5708 -1.11022e-16 1.56347e-30"/>
      <geometry>
        <mesh filename="package://assets/tpu_arm_kidsize_telapak.stl"/>
      </geometry>
      <material name="tpu_arm_kidsize_telapak_material">
        <color rgba="0.74902 0.74902 0.74902 1"/>
      </material>
    </visual>
    <collision>
      <origin xyz="-2.77556e-17 -0.14 0.0728" rpy="1.5708 -1.11022e-16 1.56347e-30"/>
      <geometry>
        <mesh filename="package://assets/tpu_arm_kidsize_telapak.stl"/>
      </geometry>
    </collision>
    <!-- Part carbon_2mm_arm_kidsize_2 -->
    <visual>
      <origin xyz="0 0 0.043" rpy="-5.66955e-30 1.5708 0"/>
      <geometry>
        <mesh filename="package://assets/carbon_2mm_arm_kidsize_2.stl"/>
      </geometry>
      <material name="carbon_2mm_arm_kidsize_2_material">
        <color rgba="0.74902 0.74902 0.74902 1"/>
      </material>
    </visual>
    <collision>
      <origin xyz="0 0 0.043" rpy="-5.66955e-30 1.5708 0"/>
      <geometry>
        <mesh filename="package://assets/carbon_2mm_arm_kidsize_2.stl"/>
      </geometry>
    </collision>
  </link>
  <!-- Joint from right_upperhand to right_lowerhand -->
  <joint name="right_elbow" type="revolute">
    <origin xyz="-0.0205971 -0.09951 -0.0256" rpy="2.498e-16 1.5708 0"/>
    <parent link="right_upperhand"/>
    <child link="right_lowerhand"/>
    <axis xyz="0 0 1"/>
    <limit effort="10" velocity="10" lower="-3.141592653589793" upper="3.141592653589793"/>
  </joint>
  <!-- Joint from almi2_view_6_7__arm_bracket to right_upperhand -->
  <joint name="right_shoulder_roll" type="revolute">
    <origin xyz="0.0205 0.0147498 -0.0268034" rpy="1.5708 -3.60822e-15 1.5708"/>
    <parent link="almi2_view_6_7__arm_bracket"/>
    <child link="right_upperhand"/>
    <axis xyz="0 0 1"/>
    <limit effort="10" velocity="10" lower="-3.141592653589793" upper="3.141592653589793"/>
  </joint>
  <!-- Joint from torso_kidsize25 to almi2_view_6_7__arm_bracket -->
  <joint name="right_shoulder_pitch" type="revolute">
    <origin xyz="0.102431 0.14736 -0.0312954" rpy="1.5708 5.41234e-15 4.10783e-15"/>
    <parent link="torso_kidsize25"/>
    <child link="almi2_view_6_7__arm_bracket"/>
    <axis xyz="0 0 1"/>
    <limit effort="10" velocity="10" lower="-3.141592653589793" upper="3.141592653589793"/>
  </joint>
  <!-- Link almi2_view_6_7__arm_bracket_2 -->
  <link name="almi2_view_6_7__arm_bracket_2">
    <inertial>
      <origin xyz="-1.07553e-16 0.00223841 -0.00829596" rpy="0 0 0"/>
      <mass value="0.0151289"/>
      <inertia ixx="2.57897e-06" ixy="-3.05654e-36" ixz="1.88736e-35" iyy="5.57377e-06" iyz="4.04961e-07" izz="5.85595e-06"/>
    </inertial>
    <!-- Part almi2_view_6_7__arm_bracket_2 -->
    <visual>
      <origin xyz="0.0185 -0.012 -0.002" rpy="1.5708 -7.34049e-30 -7.70372e-32"/>
      <geometry>
        <mesh filename="package://assets/almi2_view_6_7__arm_bracket.stl"/>
      </geometry>
      <material name="almi2_view_6_7__arm_bracket_2_material">
        <color rgba="0.74902 0.74902 0.74902 1"/>
      </material>
    </visual>
    <collision>
      <origin xyz="0.0185 -0.012 -0.002" rpy="1.5708 -7.34049e-30 -7.70372e-32"/>
      <geometry>
        <mesh filename="package://assets/almi2_view_6_7__arm_bracket.stl"/>
      </geometry>
    </collision>
  </link>
  <!-- Link left_upperhand -->
  <link name="left_upperhand">
    <inertial>
      <origin xyz="-0.0497057 -4.16564e-05 -0.0182021" rpy="0 0 0"/>
      <mass value="0.178"/>
      <inertia ixx="3.47766e-05" ixy="-7.35406e-07" ixz="1.52286e-05" iyy="0.00029303" iyz="1.94701e-08" izz="0.00029267"/>
    </inertial>
    <!-- Part mx_28_7 -->
    <visual>
      <origin xyz="-0.0341201 0.00818918 -0.0076946" rpy="-7.18869e-15 -1.5708 0"/>
      <geometry>
        <mesh filename="package://assets/mx_28.stl"/>
      </geometry>
      <material name="mx_28_7_material">
        <color rgba="0.266667 0.266667 0.266667 1"/>
      </material>
    </visual>
    <collision>
      <origin xyz="-0.0341201 0.00818918 -0.0076946" rpy="-7.18869e-15 -1.5708 0"/>
      <geometry>
        <mesh filename="package://assets/mx_28.stl"/>
      </geometry>
    </collision>
    <!-- Part almi2_view_13__14__arm_2 -->
    <visual>
      <origin xyz="-0.058605 -0.0819971 -0.0156" rpy="-3.14159 -2.10942e-15 1.5708"/>
      <geometry>
        <mesh filename="package://assets/almi2_view_13__14__arm.stl"/>
      </geometry>
      <material name="almi2_view_13__14__arm_2_material">
        <color rgba="0.298039 0.298039 0.298039 1"/>
      </material>
    </visual>
    <collision>
      <origin xyz="-0.058605 -0.0819971 -0.0156" rpy="-3.14159 -2.10942e-15 1.5708"/>
      <geometry>
        <mesh filename="package://assets/almi2_view_13__14__arm.stl"/>
      </geometry>
    </collision>
    <!-- Part mx_28_8 -->
    <visual>
      <origin xyz="-0.0653899 -0.0079054 -0.0287863" rpy="-1.5708 -7.97973e-15 -1.5708"/>
      <geometry>
        <mesh filename="package://assets/mx_28.stl"/>
      </geometry>
      <material name="mx_28_8_material">
        <color rgba="0.266667 0.266667 0.266667 1"/>
      </material>
    </visual>
    <collision>
      <origin xyz="-0.0653899 -0.0079054 -0.0287863" rpy="-1.5708 -7.97973e-15 -1.5708"/>
      <geometry>
        <mesh filename="package://assets/mx_28.stl"/>
      </geometry>
    </collision>
  </link>
  <!-- Link left_lowerhand -->
  <link name="left_lowerhand">
    <inertial>
      <origin xyz="-0.00130389 -0.103918 0.0103596" rpy="0 0 0"/>
      <mass value="0.149258"/>
      <inertia ixx="0.000225269" ixy="-7.02224e-06" ixz="-1.20544e-07" iyy="5.61474e-05" iyz="-3.26703e-05" izz="0.000240431"/>
    </inertial>
    <!-- Part carbon_2mm_arm_kidsize_1_2 -->
    <visual>
      <origin xyz="1.38778e-17 -2.77556e-17 1.38778e-17" rpy="1.5708 1.5708 0"/>
      <geometry>
        <mesh filename="package://assets/carbon_2mm_arm_kidsize_1.stl"/>
      </geometry>
      <material name="carbon_2mm_arm_kidsize_1_2_material">
        <color rgba="0.74902 0.74902 0.74902 1"/>
      </material>
    </visual>
    <collision>
      <origin xyz="1.38778e-17 -2.77556e-17 1.38778e-17" rpy="1.5708 1.5708 0"/>
      <geometry>
        <mesh filename="package://assets/carbon_2mm_arm_kidsize_1.stl"/>
      </geometry>
    </collision>
    <!-- Part tpu_arm_kidsize_telapak_2 -->
    <visual>
      <origin xyz="-3.33067e-16 -0.14 0.0728" rpy="1.5708 -2.77556e-17 1.66533e-16"/>
      <geometry>
        <mesh filename="package://assets/tpu_arm_kidsize_telapak.stl"/>
      </geometry>
      <material name="tpu_arm_kidsize_telapak_2_material">
        <color rgba="0.74902 0.74902 0.74902 1"/>
      </material>
    </visual>
    <collision>
      <origin xyz="-3.33067e-16 -0.14 0.0728" rpy="1.5708 -2.77556e-17 1.66533e-16"/>
      <geometry>
        <mesh filename="package://assets/tpu_arm_kidsize_telapak.stl"/>
      </geometry>
    </collision>
    <!-- Part almi_4_5mm_connector_lower_arm_kidsize_2 -->
    <visual>
      <origin xyz="0.00225 -0.0405 1.17961e-16" rpy="1.5708 2.77556e-17 -3.14159"/>
      <geometry>
        <mesh filename="package://assets/almi_4_5mm_connector_lower_arm_kidsize.stl"/>
      </geometry>
      <material name="almi_4_5mm_connector_lower_arm_kidsize_2_material">
        <color rgba="0.74902 0.74902 0.74902 1"/>
      </material>
    </visual>
    <collision>
      <origin xyz="0.00225 -0.0405 1.17961e-16" rpy="1.5708 2.77556e-17 -3.14159"/>
      <geometry>
        <mesh filename="package://assets/almi_4_5mm_connector_lower_arm_kidsize.stl"/>
      </geometry>
    </collision>
    <!-- Part carbon_2mm_arm_kidsize_2_2 -->
    <visual>
      <origin xyz="-2.63678e-16 1.6237e-15 0.043" rpy="-1.66533e-16 1.5708 0"/>
      <geometry>
        <mesh filename="package://assets/carbon_2mm_arm_kidsize_2.stl"/>
      </geometry>
      <material name="carbon_2mm_arm_kidsize_2_2_material">
        <color rgba="0.74902 0.74902 0.74902 1"/>
      </material>
    </visual>
    <collision>
      <origin xyz="-2.63678e-16 1.6237e-15 0.043" rpy="-1.66533e-16 1.5708 0"/>
      <geometry>
        <mesh filename="package://assets/carbon_2mm_arm_kidsize_2.stl"/>
      </geometry>
    </collision>
  </link>
  <!-- Joint from left_upperhand to left_lowerhand -->
  <joint name="left_elbow" type="revolute">
    <origin xyz="-0.09951 -0.0205971 -0.0156" rpy="-1.5708 -1.5708 0"/>
    <parent link="left_upperhand"/>
    <child link="left_lowerhand"/>
    <axis xyz="0 0 1"/>
    <limit effort="10" velocity="10" lower="-3.141592653589793" upper="3.141592653589793"/>
  </joint>
  <!-- Joint from almi2_view_6_7__arm_bracket_2 to left_upperhand -->
  <joint name="left_shoulder_roll" type="revolute">
    <origin xyz="-0.0205 0.0147498 -0.0268034" rpy="-7.70372e-32 -1.5708 0"/>
    <parent link="almi2_view_6_7__arm_bracket_2"/>
    <child link="left_upperhand"/>
    <axis xyz="0 0 1"/>
    <limit effort="10" velocity="10" lower="-3.141592653589793" upper="3.141592653589793"/>
  </joint>
  <!-- Joint from torso_kidsize25 to almi2_view_6_7__arm_bracket_2 -->
  <joint name="left_shoulder_pitch" type="revolute">
    <origin xyz="0.102431 0.00278607 -0.0312954" rpy="1.5708 -1.73472e-15 -3.14159"/>
    <parent link="torso_kidsize25"/>
    <child link="almi2_view_6_7__arm_bracket_2"/>
    <axis xyz="0 0 1"/>
    <limit effort="10" velocity="10" lower="-3.141592653589793" upper="3.141592653589793"/>
  </joint>
  <!-- Link stainless_steel_2mm_upper_leg_bracket -->
  <link name="stainless_steel_2mm_upper_leg_bracket">
    <inertial>
      <origin xyz="-0.00421162 -1.80642e-07 -0.00839045" rpy="0 0 0"/>
      <mass value="0.0521561"/>
      <inertia ixx="1.13163e-05" ixy="-2.66522e-10" ixz="-2.03733e-07" iyy="2.97089e-05" iyz="3.66542e-11" izz="2.98236e-05"/>
    </inertial>
    <!-- Part stainless_steel_2mm_upper_leg_bracket -->
    <visual>
      <origin xyz="-0.03298 0.016 0" rpy="-3.14159 -6.40949e-31 -1.61778e-32"/>
      <geometry>
        <mesh filename="package://assets/stainless_steel_2mm_upper_leg_bracket.stl"/>
      </geometry>
      <material name="stainless_steel_2mm_upper_leg_bracket_material">
        <color rgba="0.745098 0.737255 0.729412 1"/>
      </material>
    </visual>
    <collision>
      <origin xyz="-0.03298 0.016 0" rpy="-3.14159 -6.40949e-31 -1.61778e-32"/>
      <geometry>
        <mesh filename="package://assets/stainless_steel_2mm_upper_leg_bracket.stl"/>
      </geometry>
    </collision>
  </link>
  <!-- Link foot_right_1 -->
  <link name="foot_right_1">
    <inertial>
      <origin xyz="-0.000121825 -0.0144674 0.00397654" rpy="0 0 0"/>
      <mass value="0.292396"/>
      <inertia ixx="0.000302471" ixy="-1.95767e-07" ixz="7.69534e-07" iyy="0.00026243" iyz="-1.25976e-05" izz="0.000113113"/>
    </inertial>
    <!-- Part mx_64t_2 -->
    <visual>
      <origin xyz="0 -5.55112e-17 -0.0235" rpy="-1.84889e-32 9.61424e-31 -2.95823e-31"/>
      <geometry>
        <mesh filename="package://assets/mx_64t_2.stl"/>
      </geometry>
      <material name="mx_64t_2_material">
        <color rgba="0.211765 0.211765 0.211765 1"/>
      </material>
    </visual>
    <collision>
      <origin xyz="0 -5.55112e-17 -0.0235" rpy="-1.84889e-32 9.61424e-31 -2.95823e-31"/>
      <geometry>
        <mesh filename="package://assets/mx_64t_2.stl"/>
      </geometry>
    </collision>
    <!-- Part almi_2mm_fr05_f101k_set -->
    <visual>
      <origin xyz="-2.63678e-16 -5.55112e-16 0.04958" rpy="-1.5708 1.84889e-31 1.5708"/>
      <geometry>
        <mesh filename="package://assets/almi_2mm_fr05_f101k_set.stl"/>
      </geometry>
      <material name="almi_2mm_fr05_f101k_set_material">
        <color rgba="0 0 0 1"/>
      </material>
    </visual>
    <collision>
      <origin xyz="-2.63678e-16 -5.55112e-16 0.04958" rpy="-1.5708 1.84889e-31 1.5708"/>
      <geometry>
        <mesh filename="package://assets/almi_2mm_fr05_f101k_set.stl"/>
      </geometry>
    </collision>
    <!-- Part almi_2mm_connector_mx64 -->
    <visual>
      <origin xyz="-0.019 -0.043 0.01058" rpy="-9.27036e-15 -2.31112e-31 -1.5708"/>
      <geometry>
        <mesh filename="package://assets/almi_2mm_connector_mx64.stl"/>
      </geometry>
      <material name="almi_2mm_connector_mx64_material">
        <color rgba="0.74902 0.74902 0.74902 1"/>
      </material>
    </visual>
    <collision>
      <origin xyz="-0.019 -0.043 0.01058" rpy="-9.27036e-15 -2.31112e-31 -1.5708"/>
      <geometry>
        <mesh filename="package://assets/almi_2mm_connector_mx64.stl"/>
      </geometry>
    </collision>
    <!-- Part almi_2mm_connector_mx64_2 -->
    <visual>
      <origin xyz="0.019 -0.015 0.01058" rpy="8.82627e-15 1.38778e-17 1.5708"/>
      <geometry>
        <mesh filename="package://assets/almi_2mm_connector_mx64.stl"/>
      </geometry>
      <material name="almi_2mm_connector_mx64_2_material">
        <color rgba="0.74902 0.74902 0.74902 1"/>
      </material>
    </visual>
    <collision>
      <origin xyz="0.019 -0.015 0.01058" rpy="8.82627e-15 1.38778e-17 1.5708"/>
      <geometry>
        <mesh filename="package://assets/almi_2mm_connector_mx64.stl"/>
      </geometry>
    </collision>
    <!-- Part fr05_f101k_set -->
    <visual>
      <origin xyz="-4.996e-16 -4.996e-16 0.04938" rpy="-8.65974e-15 -0 -1.5708"/>
      <geometry>
        <mesh filename="package://assets/fr05_f101k_set.stl"/>
      </geometry>
      <material name="fr05_f101k_set_material">
        <color rgba="0.376471 0.376471 0.376471 1"/>
      </material>
    </visual>
    <collision>
      <origin xyz="-4.996e-16 -4.996e-16 0.04938" rpy="-8.65974e-15 -0 -1.5708"/>
      <geometry>
        <mesh filename="package://assets/fr05_f101k_set.stl"/>
      </geometry>
    </collision>
    <!-- Part mx_64t_2_2 -->
    <visual>
      <origin xyz="-2.63678e-16 -3.05311e-16 0.02558" rpy="-2.8505e-14 1.5708 0"/>
      <geometry>
        <mesh filename="package://assets/mx_64t_2.stl"/>
      </geometry>
      <material name="mx_64t_2_2_material">
        <color rgba="0.211765 0.211765 0.211765 1"/>
      </material>
    </visual>
    <collision>
      <origin xyz="-2.63678e-16 -3.05311e-16 0.02558" rpy="-2.8505e-14 1.5708 0"/>
      <geometry>
        <mesh filename="package://assets/mx_64t_2.stl"/>
      </geometry>
    </collision>
    <!-- Part mf128zz_1 -->
    <visual>
      <origin xyz="-4.996e-16 -4.996e-16 0.0516" rpy="1.5708 6.16298e-33 1.5708"/>
      <geometry>
        <mesh filename="package://assets/mf128zz_1.stl"/>
      </geometry>
      <material name="mf128zz_1_material">
        <color rgba="0.74902 0.74902 0.74902 1"/>
      </material>
    </visual>
    <collision>
      <origin xyz="-4.996e-16 -4.996e-16 0.0516" rpy="1.5708 6.16298e-33 1.5708"/>
      <geometry>
        <mesh filename="package://assets/mf128zz_1.stl"/>
      </geometry>
    </collision>
    <!-- Part rx64_cap_1 -->
    <visual>
      <origin xyz="-4.996e-16 -5.55112e-16 0.05508" rpy="7.04992e-15 9.36772e-31 1.5708"/>
      <geometry>
        <mesh filename="package://assets/rx64_cap_1.stl"/>
      </geometry>
      <material name="rx64_cap_1_material">
        <color rgba="0.74902 0.74902 0.74902 1"/>
      </material>
    </visual>
    <collision>
      <origin xyz="-4.996e-16 -5.55112e-16 0.05508" rpy="7.04992e-15 9.36772e-31 1.5708"/>
      <geometry>
        <mesh filename="package://assets/rx64_cap_1.stl"/>
      </geometry>
    </collision>
    <!-- Part hn05_i101_1 -->
    <visual>
      <origin xyz="-5.13478e-16 -5.55112e-16 0.05532" rpy="1.5708 7.4572e-31 1.5708"/>
      <geometry>
        <mesh filename="package://assets/hn05_i101_1.stl"/>
      </geometry>
      <material name="hn05_i101_1_material">
        <color rgba="0.74902 0.74902 0.74902 1"/>
      </material>
    </visual>
    <collision>
      <origin xyz="-5.13478e-16 -5.55112e-16 0.05532" rpy="1.5708 7.4572e-31 1.5708"/>
      <geometry>
        <mesh filename="package://assets/hn05_i101_1.stl"/>
      </geometry>
    </collision>
    <!-- Part rx64_cap_1_2 -->
    <visual>
      <origin xyz="-0.0232 -9.71445e-16 0.02558" rpy="3.14159 1.5708 0"/>
      <geometry>
        <mesh filename="package://assets/rx64_cap_1.stl"/>
      </geometry>
      <material name="rx64_cap_1_2_material">
        <color rgba="0.74902 0.74902 0.74902 1"/>
      </material>
    </visual>
    <collision>
      <origin xyz="-0.0232 -9.71445e-16 0.02558" rpy="3.14159 1.5708 0"/>
      <geometry>
        <mesh filename="package://assets/rx64_cap_1.stl"/>
      </geometry>
    </collision>
    <!-- Part hn05_i101_1_2 -->
    <visual>
      <origin xyz="-0.02344 -9.71445e-16 0.02558" rpy="-1.5708 1.5708 0"/>
      <geometry>
        <mesh filename="package://assets/hn05_i101_1.stl"/>
      </geometry>
      <material name="hn05_i101_1_2_material">
        <color rgba="0.74902 0.74902 0.74902 1"/>
      </material>
    </visual>
    <collision>
      <origin xyz="-0.02344 -9.71445e-16 0.02558" rpy="-1.5708 1.5708 0"/>
      <geometry>
        <mesh filename="package://assets/hn05_i101_1.stl"/>
      </geometry>
    </collision>
    <!-- Part mf128zz_1_2 -->
    <visual>
      <origin xyz="-0.01972 -8.88178e-16 0.02558" rpy="-1.5708 1.5708 0"/>
      <geometry>
        <mesh filename="package://assets/mf128zz_1.stl"/>
      </geometry>
      <material name="mf128zz_1_2_material">
        <color rgba="0.74902 0.74902 0.74902 1"/>
      </material>
    </visual>
    <collision>
      <origin xyz="-0.01972 -8.88178e-16 0.02558" rpy="-1.5708 1.5708 0"/>
      <geometry>
        <mesh filename="package://assets/mf128zz_1.stl"/>
      </geometry>
    </collision>
  </link>
  <!-- Link foot_right_2 -->
  <link name="foot_right_2">
    <inertial>
      <origin xyz="0.00189202 -0.0890217 0.0236304" rpy="0 0 0"/>
      <mass value="0.273181"/>
      <inertia ixx="0.00054925" ixy="-3.23355e-06" ixz="6.73937e-08" iyy="0.000131243" iyz="8.86444e-07" izz="0.000472641"/>
    </inertial>
    <!-- Part stainless_steel_2mm__femur -->
    <visual>
      <origin xyz="-0.014 -0.07746 0.047" rpy="1.5708 5.55112e-17 -2.77556e-17"/>
      <geometry>
        <mesh filename="package://assets/stainless_steel_2mm__femur.stl"/>
      </geometry>
      <material name="stainless_steel_2mm__femur_material">
        <color rgba="0.74902 0.74902 0.74902 1"/>
      </material>
    </visual>
    <collision>
      <origin xyz="-0.014 -0.07746 0.047" rpy="1.5708 5.55112e-17 -2.77556e-17"/>
      <geometry>
        <mesh filename="package://assets/stainless_steel_2mm__femur.stl"/>
      </geometry>
    </collision>
    <!-- Part stainless_steel_2mm__femur_2 -->
    <visual>
      <origin xyz="-0.014 -0.07746 -0.003" rpy="1.5708 4.31408e-32 0"/>
      <geometry>
        <mesh filename="package://assets/stainless_steel_2mm__femur.stl"/>
      </geometry>
      <material name="stainless_steel_2mm__femur_2_material">
        <color rgba="0.74902 0.74902 0.74902 1"/>
      </material>
    </visual>
    <collision>
      <origin xyz="-0.014 -0.07746 -0.003" rpy="1.5708 4.31408e-32 0"/>
      <geometry>
        <mesh filename="package://assets/stainless_steel_2mm__femur.stl"/>
      </geometry>
    </collision>
    <!-- Part almi_6_5mm_l_mx64 -->
    <visual>
      <origin xyz="-0.0134121 -0.0859 0.047" rpy="-1.5708 9.42935e-31 3.14159"/>
      <geometry>
        <mesh filename="package://assets/almi_6_5mm_l_mx64.stl"/>
      </geometry>
      <material name="almi_6_5mm_l_mx64_material">
        <color rgba="0.74902 0.74902 0.74902 1"/>
      </material>
    </visual>
    <collision>
      <origin xyz="-0.0134121 -0.0859 0.047" rpy="-1.5708 9.42935e-31 3.14159"/>
      <geometry>
        <mesh filename="package://assets/almi_6_5mm_l_mx64.stl"/>
      </geometry>
    </collision>
    <!-- Part almi_6_5mm_l_mx64_2 -->
    <visual>
      <origin xyz="-0.0134121 -0.0859 0.0065" rpy="-1.5708 5.55112e-17 3.14159"/>
      <geometry>
        <mesh filename="package://assets/almi_6_5mm_l_mx64.stl"/>
      </geometry>
      <material name="almi_6_5mm_l_mx64_2_material">
        <color rgba="0.74902 0.74902 0.74902 1"/>
      </material>
    </visual>
    <collision>
      <origin xyz="-0.0134121 -0.0859 0.0065" rpy="-1.5708 5.55112e-17 3.14159"/>
      <geometry>
        <mesh filename="package://assets/almi_6_5mm_l_mx64.stl"/>
      </geometry>
    </collision>
    <!-- Part mx_64t_1 -->
    <visual>
      <origin xyz="-6.38378e-16 -0.134 0.0235" rpy="3.14159 -7.4572e-31 -3.15544e-29"/>
      <geometry>
        <mesh filename="package://assets/mx_64t_1.stl"/>
      </geometry>
      <material name="mx_64t_1_material">
        <color rgba="0.211765 0.211765 0.211765 1"/>
      </material>
    </visual>
    <collision>
      <origin xyz="-6.38378e-16 -0.134 0.0235" rpy="3.14159 -7.4572e-31 -3.15544e-29"/>
      <geometry>
        <mesh filename="package://assets/mx_64t_1.stl"/>
      </geometry>
    </collision>
    <!-- Part hn05_i101 -->
    <visual>
      <origin xyz="-6.52256e-16 -0.134 0.04694" rpy="1.5708 -1.41553e-15 -1.5708"/>
      <geometry>
        <mesh filename="package://assets/hn05_i101.stl"/>
      </geometry>
      <material name="hn05_i101_material">
        <color rgba="0.74902 0.74902 0.74902 1"/>
      </material>
    </visual>
    <collision>
      <origin xyz="-6.52256e-16 -0.134 0.04694" rpy="1.5708 -1.41553e-15 -1.5708"/>
      <geometry>
        <mesh filename="package://assets/hn05_i101.stl"/>
      </geometry>
    </collision>
    <!-- Part mf128zz -->
    <visual>
      <origin xyz="-6.52256e-16 -0.134 0.04322" rpy="1.5708 -9.71445e-16 -1.5708"/>
      <geometry>
        <mesh filename="package://assets/mf128zz.stl"/>
      </geometry>
      <material name="mf128zz_material">
        <color rgba="0.74902 0.74902 0.74902 1"/>
      </material>
    </visual>
    <collision>
      <origin xyz="-6.52256e-16 -0.134 0.04322" rpy="1.5708 -9.71445e-16 -1.5708"/>
      <geometry>
        <mesh filename="package://assets/mf128zz.stl"/>
      </geometry>
    </collision>
    <!-- Part rx64_cap -->
    <visual>
      <origin xyz="-6.66134e-16 -0.134 0.0467" rpy="-2.10942e-15 6.93889e-16 -1.5708"/>
      <geometry>
        <mesh filename="package://assets/rx64_cap.stl"/>
      </geometry>
      <material name="rx64_cap_material">
        <color rgba="0.74902 0.74902 0.74902 1"/>
      </material>
    </visual>
    <collision>
      <origin xyz="-6.66134e-16 -0.134 0.0467" rpy="-2.10942e-15 6.93889e-16 -1.5708"/>
      <geometry>
        <mesh filename="package://assets/rx64_cap.stl"/>
      </geometry>
    </collision>
  </link>
  <!-- Link foot_right_3 -->
  <link name="foot_right_3">
    <inertial>
      <origin xyz="0.00350206 -0.0535427 0.0235017" rpy="0 0 0"/>
      <mass value="0.157154"/>
      <inertia ixx="0.000266743" ixy="-8.33375e-06" ixz="-5.26492e-09" iyy="0.000115972" iyz="-6.48605e-09" izz="0.000200186"/>
    </inertial>
    <!-- Part stainless_steel_2mm_leg_spacer -->
    <visual>
      <origin xyz="0.024 -0.0190814 0.045" rpy="3.14159 -1.36835e-14 -1.5708"/>
      <geometry>
        <mesh filename="package://assets/stainless_steel_2mm_leg_spacer.stl"/>
      </geometry>
      <material name="stainless_steel_2mm_leg_spacer_material">
        <color rgba="0.74902 0.74902 0.74902 1"/>
      </material>
    </visual>
    <collision>
      <origin xyz="0.024 -0.0190814 0.045" rpy="3.14159 -1.36835e-14 -1.5708"/>
      <geometry>
        <mesh filename="package://assets/stainless_steel_2mm_leg_spacer.stl"/>
      </geometry>
    </collision>
    <!-- Part stainless_steel_2mm_shinebone -->
    <visual>
      <origin xyz="0.0135 -0.0197269 0.05" rpy="-1.5708 -3.88578e-16 -4.57967e-16"/>
      <geometry>
        <mesh filename="package://assets/stainless_steel_2mm_shinebone.stl"/>
      </geometry>
      <material name="stainless_steel_2mm_shinebone_material">
        <color rgba="0.74902 0.74902 0.74902 1"/>
      </material>
    </visual>
    <collision>
      <origin xyz="0.0135 -0.0197269 0.05" rpy="-1.5708 -3.88578e-16 -4.57967e-16"/>
      <geometry>
        <mesh filename="package://assets/stainless_steel_2mm_shinebone.stl"/>
      </geometry>
    </collision>
    <!-- Part stainless_steel_2mm_shinebone_2 -->
    <visual>
      <origin xyz="0.0135 -0.0197269 0" rpy="-1.5708 6.59438e-31 -1.39283e-30"/>
      <geometry>
        <mesh filename="package://assets/stainless_steel_2mm_shinebone.stl"/>
      </geometry>
      <material name="stainless_steel_2mm_shinebone_2_material">
        <color rgba="0.74902 0.74902 0.74902 1"/>
      </material>
    </visual>
    <collision>
      <origin xyz="0.0135 -0.0197269 0" rpy="-1.5708 6.59438e-31 -1.39283e-30"/>
      <geometry>
        <mesh filename="package://assets/stainless_steel_2mm_shinebone.stl"/>
      </geometry>
    </collision>
  </link>
  <!-- Link foot_right_4 -->
  <link name="foot_right_4">
    <inertial>
      <origin xyz="-0.0215978 -0.0144558 -0.0236219" rpy="0 0 0"/>
      <mass value="0.292143"/>
      <inertia ixx="0.000112946" ixy="-1.25976e-05" ixz="7.69336e-07" iyy="0.000262476" iyz="-2.05088e-07" izz="0.000302507"/>
    </inertial>
    <!-- Part mx_64t_3 -->
    <visual>
      <origin xyz="-0.04908 5.55112e-17 -0.0235" rpy="7.07767e-16 1.5708 0"/>
      <geometry>
        <mesh filename="package://assets/mx_64t_3.stl"/>
      </geometry>
      <material name="mx_64t_3_material">
        <color rgba="0.211765 0.211765 0.211765 1"/>
      </material>
    </visual>
    <collision>
      <origin xyz="-0.04908 5.55112e-17 -0.0235" rpy="7.07767e-16 1.5708 0"/>
      <geometry>
        <mesh filename="package://assets/mx_64t_3.stl"/>
      </geometry>
    </collision>
    <!-- Part fr05_f101k_set_1 -->
    <visual>
      <origin xyz="0.024 -4.58208e-05 -0.0235" rpy="-1.5708 2.02616e-15 -1.5708"/>
      <geometry>
        <mesh filename="package://assets/fr05_f101k_set_1.stl"/>
      </geometry>
      <material name="fr05_f101k_set_1_material">
        <color rgba="0.376471 0.376471 0.376471 1"/>
      </material>
    </visual>
    <collision>
      <origin xyz="0.024 -4.58208e-05 -0.0235" rpy="-1.5708 2.02616e-15 -1.5708"/>
      <geometry>
        <mesh filename="package://assets/fr05_f101k_set_1.stl"/>
      </geometry>
    </collision>
    <!-- Part almi_2mm_connector_mx64_1 -->
    <visual>
      <origin xyz="-0.015 -0.015 -0.0425" rpy="1.5708 -1.83187e-15 1.5708"/>
      <geometry>
        <mesh filename="package://assets/almi_2mm_connector_mx64_1.stl"/>
      </geometry>
      <material name="almi_2mm_connector_mx64_1_material">
        <color rgba="0.74902 0.74902 0.74902 1"/>
      </material>
    </visual>
    <collision>
      <origin xyz="-0.015 -0.015 -0.0425" rpy="1.5708 -1.83187e-15 1.5708"/>
      <geometry>
        <mesh filename="package://assets/almi_2mm_connector_mx64_1.stl"/>
      </geometry>
    </collision>
    <!-- Part almi_2mm_connector_mx64_1_2 -->
    <visual>
      <origin xyz="-0.015 -0.043 -0.0045" rpy="-1.5708 -8.60968e-30 -1.5708"/>
      <geometry>
        <mesh filename="package://assets/almi_2mm_connector_mx64_1.stl"/>
      </geometry>
      <material name="almi_2mm_connector_mx64_1_2_material">
        <color rgba="0.74902 0.74902 0.74902 1"/>
      </material>
    </visual>
    <collision>
      <origin xyz="-0.015 -0.043 -0.0045" rpy="-1.5708 -8.60968e-30 -1.5708"/>
      <geometry>
        <mesh filename="package://assets/almi_2mm_connector_mx64_1.stl"/>
      </geometry>
    </collision>
    <!-- Part mx_64t_3_2 -->
    <visual>
      <origin xyz="0 0 -0.0235" rpy="0 -1.00148e-32 0"/>
      <geometry>
        <mesh filename="package://assets/mx_64t_3.stl"/>
      </geometry>
      <material name="mx_64t_3_2_material">
        <color rgba="0.211765 0.211765 0.211765 1"/>
      </material>
    </visual>
    <collision>
      <origin xyz="0 0 -0.0235" rpy="0 -1.00148e-32 0"/>
      <geometry>
        <mesh filename="package://assets/mx_64t_3.stl"/>
      </geometry>
    </collision>
    <!-- Part almi_2mm_fr05_f101k_set_1 -->
    <visual>
      <origin xyz="0.024 5.55112e-17 -0.0235" rpy="-1.16573e-15 -1.97065e-15 1.5708"/>
      <geometry>
        <mesh filename="package://assets/almi_2mm_fr05_f101k_set_1.stl"/>
      </geometry>
      <material name="almi_2mm_fr05_f101k_set_1_material">
        <color rgba="0 0 0 1"/>
      </material>
    </visual>
    <collision>
      <origin xyz="0.024 5.55112e-17 -0.0235" rpy="-1.16573e-15 -1.97065e-15 1.5708"/>
      <geometry>
        <mesh filename="package://assets/almi_2mm_fr05_f101k_set_1.stl"/>
      </geometry>
    </collision>
    <!-- Part hn05_i101_2 -->
    <visual>
      <origin xyz="1.38778e-17 5.55112e-17 -0.04694" rpy="-1.5708 2.22045e-16 -2.77556e-17"/>
      <geometry>
        <mesh filename="package://assets/hn05_i101_2.stl"/>
      </geometry>
      <material name="hn05_i101_2_material">
        <color rgba="0.74902 0.74902 0.74902 1"/>
      </material>
    </visual>
    <collision>
      <origin xyz="1.38778e-17 5.55112e-17 -0.04694" rpy="-1.5708 2.22045e-16 -2.77556e-17"/>
      <geometry>
        <mesh filename="package://assets/hn05_i101_2.stl"/>
      </geometry>
    </collision>
    <!-- Part mf128zz_2 -->
    <visual>
      <origin xyz="2.77556e-17 5.55112e-17 -0.04322" rpy="-1.5708 -2.54993e-31 2.77556e-17"/>
      <geometry>
        <mesh filename="package://assets/mf128zz_2.stl"/>
      </geometry>
      <material name="mf128zz_2_material">
        <color rgba="0.74902 0.74902 0.74902 1"/>
      </material>
    </visual>
    <collision>
      <origin xyz="2.77556e-17 5.55112e-17 -0.04322" rpy="-1.5708 -2.54993e-31 2.77556e-17"/>
      <geometry>
        <mesh filename="package://assets/mf128zz_2.stl"/>
      </geometry>
    </collision>
    <!-- Part rx64_cap_2 -->
    <visual>
      <origin xyz="1.38778e-17 5.55112e-17 -0.0467" rpy="-3.14159 -5.55112e-17 1.38778e-17"/>
      <geometry>
        <mesh filename="package://assets/rx64_cap_2.stl"/>
      </geometry>
      <material name="rx64_cap_2_material">
        <color rgba="0.74902 0.74902 0.74902 1"/>
      </material>
    </visual>
    <collision>
      <origin xyz="1.38778e-17 5.55112e-17 -0.0467" rpy="-3.14159 -5.55112e-17 1.38778e-17"/>
      <geometry>
        <mesh filename="package://assets/rx64_cap_2.stl"/>
      </geometry>
    </collision>
    <!-- Part mf128zz_2_2 -->
    <visual>
      <origin xyz="0.02622 -4.58208e-05 -0.0235" rpy="1.22125e-15 1.94289e-15 -1.5708"/>
      <geometry>
        <mesh filename="package://assets/mf128zz_2.stl"/>
      </geometry>
      <material name="mf128zz_2_2_material">
        <color rgba="0.74902 0.74902 0.74902 1"/>
      </material>
    </visual>
    <collision>
      <origin xyz="0.02622 -4.58208e-05 -0.0235" rpy="1.22125e-15 1.94289e-15 -1.5708"/>
      <geometry>
        <mesh filename="package://assets/mf128zz_2.stl"/>
      </geometry>
    </collision>
    <!-- Part hn05_i101_2_2 -->
    <visual>
      <origin xyz="0.02994 -4.58208e-05 -0.0235" rpy="1.11022e-15 1.9984e-15 -1.5708"/>
      <geometry>
        <mesh filename="package://assets/hn05_i101_2.stl"/>
      </geometry>
      <material name="hn05_i101_2_2_material">
        <color rgba="0.74902 0.74902 0.74902 1"/>
      </material>
    </visual>
    <collision>
      <origin xyz="0.02994 -4.58208e-05 -0.0235" rpy="1.11022e-15 1.9984e-15 -1.5708"/>
      <geometry>
        <mesh filename="package://assets/hn05_i101_2.stl"/>
      </geometry>
    </collision>
    <!-- Part rx64_cap_2_2 -->
    <visual>
      <origin xyz="0.0297 -4.58208e-05 -0.0235" rpy="-1.5708 1.94289e-15 -1.5708"/>
      <geometry>
        <mesh filename="package://assets/rx64_cap_2.stl"/>
      </geometry>
      <material name="rx64_cap_2_2_material">
        <color rgba="0.74902 0.74902 0.74902 1"/>
      </material>
    </visual>
    <collision>
      <origin xyz="0.0297 -4.58208e-05 -0.0235" rpy="-1.5708 1.94289e-15 -1.5708"/>
      <geometry>
        <mesh filename="package://assets/rx64_cap_2.stl"/>
      </geometry>
    </collision>
  </link>
  <!-- Link foot_right_5 -->
  <link name="foot_right_5">
    <inertial>
      <origin xyz="-0.00431494 0.027932 -0.0410276" rpy="0 0 0"/>
      <mass value="0.132192"/>
      <inertia ixx="0.000177533" ixy="1.91248e-06" ixz="-5.63401e-06" iyy="0.000221544" iyz="8.6074e-07" izz="6.06598e-05"/>
    </inertial>
    <!-- Part pla_50__shoes -->
    <visual>
      <origin xyz="-0.04925 0.032 -0.10376" rpy="-3.14159 1.5708 0"/>
      <geometry>
        <mesh filename="package://assets/pla_50__shoes.stl"/>
      </geometry>
      <material name="pla_50__shoes_material">
        <color rgba="0.74902 0.74902 0.74902 1"/>
      </material>
    </visual>
    <collision>
      <origin xyz="-0.04925 0.032 -0.10376" rpy="-3.14159 1.5708 0"/>
      <geometry>
        <mesh filename="package://assets/pla_50__shoes.stl"/>
      </geometry>
    </collision>
    <!-- Part almi_2mm_lower_leg -->
    <visual>
      <origin xyz="-0.00775 0.032 -0.02876" rpy="-1.00475e-14 -1.5708 0"/>
      <geometry>
        <mesh filename="package://assets/almi_2mm_lower_leg.stl"/>
      </geometry>
      <material name="almi_2mm_lower_leg_material">
        <color rgba="0.74902 0.74902 0.74902 1"/>
      </material>
    </visual>
    <collision>
      <origin xyz="-0.00775 0.032 -0.02876" rpy="-1.00475e-14 -1.5708 0"/>
      <geometry>
        <mesh filename="package://assets/almi_2mm_lower_leg.stl"/>
      </geometry>
    </collision>
    <!-- Part stainless_steel_2mm_lower_leg_bracket -->
    <visual>
      <origin xyz="-0.016 0.032 -0.00052" rpy="1.5708 1.5708 0"/>
      <geometry>
        <mesh filename="package://assets/stainless_steel_2mm_lower_leg_bracket.stl"/>
      </geometry>
      <material name="stainless_steel_2mm_lower_leg_bracket_material">
        <color rgba="0.745098 0.737255 0.729412 1"/>
      </material>
    </visual>
    <collision>
      <origin xyz="-0.016 0.032 -0.00052" rpy="1.5708 1.5708 0"/>
      <geometry>
        <mesh filename="package://assets/stainless_steel_2mm_lower_leg_bracket.stl"/>
      </geometry>
    </collision>
  </link>
  <!-- Joint from foot_right_4 to foot_right_5 -->
  <joint name="right_ankle_roll" type="revolute">
    <origin xyz="-0.02558 0 -0.0235" rpy="-6.93889e-16 -1.5708 0"/>
    <parent link="foot_right_4"/>
    <child link="foot_right_5"/>
    <axis xyz="0 0 1"/>
    <limit effort="10" velocity="10" lower="-3.141592653589793" upper="3.141592653589793"/>
  </joint>
  <!-- Joint from foot_right_3 to foot_right_4 -->
  <joint name="right_ankle_pitch" type="revolute">
    <origin xyz="-9.71445e-17 -0.111702 1.38778e-17" rpy="3.14159 -1.70974e-14 4.18693e-14"/>
    <parent link="foot_right_3"/>
    <child link="foot_right_4"/>
    <axis xyz="0 0 1"/>
    <limit effort="10" velocity="10" lower="-3.141592653589793" upper="3.141592653589793"/>
  </joint>
  <!-- Joint from foot_right_2 to foot_right_3 -->
  <joint name="right_knee" type="revolute">
    <origin xyz="-6.38378e-16 -0.134 4.16334e-17" rpy="1.46549e-14 1.62648e-14 5.77316e-15"/>
    <parent link="foot_right_2"/>
    <child link="foot_right_3"/>
    <axis xyz="0 0 1"/>
    <limit effort="10" velocity="10" lower="-3.141592653589793" upper="3.141592653589793"/>
  </joint>
  <!-- Joint from foot_right_1 to foot_right_2 -->
  <joint name="right_hip_pitch" type="revolute">
    <origin xyz="0.0235 6.66134e-16 0.02558" rpy="2.78666e-14 -1.5708 0"/>
    <parent link="foot_right_1"/>
    <child link="foot_right_2"/>
    <axis xyz="0 0 1"/>
    <limit effort="10" velocity="10" lower="-3.141592653589793" upper="3.141592653589793"/>
  </joint>
  <!-- Joint from stainless_steel_2mm_upper_leg_bracket to foot_right_1 -->
  <joint name="right_hip_roll" type="revolute">
    <origin xyz="-0.0335 3.55965e-14 -0.032" rpy="1.5708 7.85483e-15 1.5708"/>
    <parent link="stainless_steel_2mm_upper_leg_bracket"/>
    <child link="foot_right_1"/>
    <axis xyz="0 0 1"/>
    <limit effort="10" velocity="10" lower="-3.141592653589793" upper="3.141592653589793"/>
  </joint>
  <!-- Joint from torso_kidsize25 to stainless_steel_2mm_upper_leg_bracket -->
  <joint name="right_hip_yaw" type="revolute">
    <origin xyz="0.0981644 0.124573 0.109005" rpy="3.14159 1.13382e-14 -2.44249e-15"/>
    <parent link="torso_kidsize25"/>
    <child link="stainless_steel_2mm_upper_leg_bracket"/>
    <axis xyz="0 0 1"/>
    <limit effort="10" velocity="10" lower="-3.141592653589793" upper="3.141592653589793"/>
  </joint>
  <!-- Link stainless_steel_2mm_upper_leg_bracket_mir -->
  <link name="stainless_steel_2mm_upper_leg_bracket_mir">
    <inertial>
      <origin xyz="-0.00421162 1.80642e-07 -0.00839045" rpy="0 0 0"/>
      <mass value="0.0521561"/>
      <inertia ixx="1.13163e-05" ixy="2.66522e-10" ixz="-2.03733e-07" iyy="2.97089e-05" iyz="-3.66542e-11" izz="2.98236e-05"/>
    </inertial>
    <!-- Part stainless_steel_2mm_upper_leg_bracket_mir -->
    <visual>
      <origin xyz="-0.03298 -0.016 1.38778e-17" rpy="-1.22027e-30 3.14312e-31 1.92593e-33"/>
      <geometry>
        <mesh filename="package://assets/stainless_steel_2mm_upper_leg_bracket_mir.stl"/>
      </geometry>
      <material name="stainless_steel_2mm_upper_leg_bracket_mir_material">
        <color rgba="0.74902 0.74902 0.74902 1"/>
      </material>
    </visual>
    <collision>
      <origin xyz="-0.03298 -0.016 1.38778e-17" rpy="-1.22027e-30 3.14312e-31 1.92593e-33"/>
      <geometry>
        <mesh filename="package://assets/stainless_steel_2mm_upper_leg_bracket_mir.stl"/>
      </geometry>
    </collision>
  </link>
  <!-- Link foot_left_1 -->
  <link name="foot_left_1">
    <inertial>
      <origin xyz="-0.000121924 0.0144559 0.00398223" rpy="0 0 0"/>
      <mass value="0.292143"/>
      <inertia ixx="0.000302507" ixy="1.96526e-07" ixz="7.69256e-07" iyy="0.000262475" iyz="1.25975e-05" izz="0.000112946"/>
    </inertial>
    <!-- Part mx_64t_mir_1 -->
    <visual>
      <origin xyz="0 2.77556e-17 -0.0235" rpy="-3.14159 -5.87794e-31 2.03378e-31"/>
      <geometry>
        <mesh filename="package://assets/mx_64t_mir_1.stl"/>
      </geometry>
      <material name="mx_64t_mir_1_material">
        <color rgba="0.74902 0.74902 0.74902 1"/>
      </material>
    </visual>
    <collision>
      <origin xyz="0 2.77556e-17 -0.0235" rpy="-3.14159 -5.87794e-31 2.03378e-31"/>
      <geometry>
        <mesh filename="package://assets/mx_64t_mir_1.stl"/>
      </geometry>
    </collision>
    <!-- Part almi_2mm_fr05_f101k_set_mir -->
    <visual>
      <origin xyz="3.1225e-17 -1.38778e-16 0.04958" rpy="-1.5708 -1.01627e-29 -1.5708"/>
      <geometry>
        <mesh filename="package://assets/almi_2mm_fr05_f101k_set_mir.stl"/>
      </geometry>
      <material name="almi_2mm_fr05_f101k_set_mir_material">
        <color rgba="0.74902 0.74902 0.74902 1"/>
      </material>
    </visual>
    <collision>
      <origin xyz="3.1225e-17 -1.38778e-16 0.04958" rpy="-1.5708 -1.01627e-29 -1.5708"/>
      <geometry>
        <mesh filename="package://assets/almi_2mm_fr05_f101k_set_mir.stl"/>
      </geometry>
    </collision>
    <!-- Part almi_2mm_connector_mx64_mir -->
    <visual>
      <origin xyz="-0.019 0.043 0.01058" rpy="3.14159 -3.14312e-31 1.5708"/>
      <geometry>
        <mesh filename="package://assets/almi_2mm_connector_mx64_mir.stl"/>
      </geometry>
      <material name="almi_2mm_connector_mx64_mir_material">
        <color rgba="0.74902 0.74902 0.74902 1"/>
      </material>
    </visual>
    <collision>
      <origin xyz="-0.019 0.043 0.01058" rpy="3.14159 -3.14312e-31 1.5708"/>
      <geometry>
        <mesh filename="package://assets/almi_2mm_connector_mx64_mir.stl"/>
      </geometry>
    </collision>
    <!-- Part fr05_f101k_set_mir -->
    <visual>
      <origin xyz="-2.08167e-16 4.58208e-05 0.04958" rpy="3.14159 1.19932e-29 1.5708"/>
      <geometry>
        <mesh filename="package://assets/fr05_f101k_set_mir.stl"/>
      </geometry>
      <material name="fr05_f101k_set_mir_material">
        <color rgba="0.74902 0.74902 0.74902 1"/>
      </material>
    </visual>
    <collision>
      <origin xyz="-2.08167e-16 4.58208e-05 0.04958" rpy="3.14159 1.19932e-29 1.5708"/>
      <geometry>
        <mesh filename="package://assets/fr05_f101k_set_mir.stl"/>
      </geometry>
    </collision>
    <!-- Part almi_2mm_connector_mx64_mir_2 -->
    <visual>
      <origin xyz="0.019 0.015 0.01058" rpy="-3.14159 1.18021e-29 -1.5708"/>
      <geometry>
        <mesh filename="package://assets/almi_2mm_connector_mx64_mir.stl"/>
      </geometry>
      <material name="almi_2mm_connector_mx64_mir_2_material">
        <color rgba="0.74902 0.74902 0.74902 1"/>
      </material>
    </visual>
    <collision>
      <origin xyz="0.019 0.015 0.01058" rpy="-3.14159 1.18021e-29 -1.5708"/>
      <geometry>
        <mesh filename="package://assets/almi_2mm_connector_mx64_mir.stl"/>
      </geometry>
    </collision>
    <!-- Part mx_64t_mir_1_2 -->
    <visual>
      <origin xyz="-2.08167e-17 3.33067e-16 0.02558" rpy="3.14159 1.5708 0"/>
      <geometry>
        <mesh filename="package://assets/mx_64t_mir_1.stl"/>
      </geometry>
      <material name="mx_64t_mir_1_2_material">
        <color rgba="0.74902 0.74902 0.74902 1"/>
      </material>
    </visual>
    <collision>
      <origin xyz="-2.08167e-17 3.33067e-16 0.02558" rpy="3.14159 1.5708 0"/>
      <geometry>
        <mesh filename="package://assets/mx_64t_mir_1.stl"/>
      </geometry>
    </collision>
    <!-- Part mf128zz_mir_1 -->
    <visual>
      <origin xyz="-2.11636e-16 4.58208e-05 0.0518" rpy="1.5708 -1.09824e-29 -1.5708"/>
      <geometry>
        <mesh filename="package://assets/mf128zz_mir_1.stl"/>
      </geometry>
      <material name="mf128zz_mir_1_material">
        <color rgba="0.74902 0.74902 0.74902 1"/>
      </material>
    </visual>
    <collision>
      <origin xyz="-2.11636e-16 4.58208e-05 0.0518" rpy="1.5708 -1.09824e-29 -1.5708"/>
      <geometry>
        <mesh filename="package://assets/mf128zz_mir_1.stl"/>
      </geometry>
    </collision>
    <!-- Part hn05_i101_mir_1 -->
    <visual>
      <origin xyz="-2.11636e-16 4.58208e-05 0.05552" rpy="1.5708 -9.84844e-30 -1.5708"/>
      <geometry>
        <mesh filename="package://assets/hn05_i101_mir_1.stl"/>
      </geometry>
      <material name="hn05_i101_mir_1_material">
        <color rgba="0.74902 0.74902 0.74902 1"/>
      </material>
    </visual>
    <collision>
      <origin xyz="-2.11636e-16 4.58208e-05 0.05552" rpy="1.5708 -9.84844e-30 -1.5708"/>
      <geometry>
        <mesh filename="package://assets/hn05_i101_mir_1.stl"/>
      </geometry>
    </collision>
    <!-- Part rx64_cap_mir_1 -->
    <visual>
      <origin xyz="-2.11636e-16 4.58208e-05 0.05528" rpy="-3.14159 -9.53412e-30 -1.5708"/>
      <geometry>
        <mesh filename="package://assets/rx64_cap_mir_1.stl"/>
      </geometry>
      <material name="rx64_cap_mir_1_material">
        <color rgba="0.74902 0.74902 0.74902 1"/>
      </material>
    </visual>
    <collision>
      <origin xyz="-2.11636e-16 4.58208e-05 0.05528" rpy="-3.14159 -9.53412e-30 -1.5708"/>
      <geometry>
        <mesh filename="package://assets/rx64_cap_mir_1.stl"/>
      </geometry>
    </collision>
    <!-- Part rx64_cap_mir_1_2 -->
    <visual>
      <origin xyz="-0.0232 -5.82867e-16 0.02558" rpy="1.5708 8.61276e-30 1.5708"/>
      <geometry>
        <mesh filename="package://assets/rx64_cap_mir_1.stl"/>
      </geometry>
      <material name="rx64_cap_mir_1_2_material">
        <color rgba="0.74902 0.74902 0.74902 1"/>
      </material>
    </visual>
    <collision>
      <origin xyz="-0.0232 -5.82867e-16 0.02558" rpy="1.5708 8.61276e-30 1.5708"/>
      <geometry>
        <mesh filename="package://assets/rx64_cap_mir_1.stl"/>
      </geometry>
    </collision>
    <!-- Part hn05_i101_mir_1_2 -->
    <visual>
      <origin xyz="-0.02344 -6.10623e-16 0.02558" rpy="-4.4964e-15 -7.95024e-30 1.5708"/>
      <geometry>
        <mesh filename="package://assets/hn05_i101_mir_1.stl"/>
      </geometry>
      <material name="hn05_i101_mir_1_2_material">
        <color rgba="0.74902 0.74902 0.74902 1"/>
      </material>
    </visual>
    <collision>
      <origin xyz="-0.02344 -6.10623e-16 0.02558" rpy="-4.4964e-15 -7.95024e-30 1.5708"/>
      <geometry>
        <mesh filename="package://assets/hn05_i101_mir_1.stl"/>
      </geometry>
    </collision>
    <!-- Part mf128zz_mir_1_2 -->
    <visual>
      <origin xyz="-0.01972 -4.44089e-16 0.02558" rpy="-4.38538e-15 -9.46633e-30 1.5708"/>
      <geometry>
        <mesh filename="package://assets/mf128zz_mir_1.stl"/>
      </geometry>
      <material name="mf128zz_mir_1_2_material">
        <color rgba="0.74902 0.74902 0.74902 1"/>
      </material>
    </visual>
    <collision>
      <origin xyz="-0.01972 -4.44089e-16 0.02558" rpy="-4.38538e-15 -9.46633e-30 1.5708"/>
      <geometry>
        <mesh filename="package://assets/mf128zz_mir_1.stl"/>
      </geometry>
    </collision>
  </link>
  <!-- Link foot_left_2 -->
  <link name="foot_left_2">
    <inertial>
      <origin xyz="0.00189202 0.0890217 0.0236304" rpy="0 0 0"/>
      <mass value="0.273181"/>
      <inertia ixx="0.00054925" ixy="3.23354e-06" ixz="6.73963e-08" iyy="0.000131243" iyz="-8.86436e-07" izz="0.000472641"/>
    </inertial>
    <!-- Part mx_64t_mir -->
    <visual>
      <origin xyz="-1.04083e-15 0.134 0.0235" rpy="-1.12133e-14 2.22045e-16 2.34193e-31"/>
      <geometry>
        <mesh filename="package://assets/mx_64t_mir.stl"/>
      </geometry>
      <material name="mx_64t_mir_material">
        <color rgba="0.74902 0.74902 0.74902 1"/>
      </material>
    </visual>
    <collision>
      <origin xyz="-1.04083e-15 0.134 0.0235" rpy="-1.12133e-14 2.22045e-16 2.34193e-31"/>
      <geometry>
        <mesh filename="package://assets/mx_64t_mir.stl"/>
      </geometry>
    </collision>
    <!-- Part stainless_steel_2mm__femur_mir -->
    <visual>
      <origin xyz="-0.014 0.07746 0.047" rpy="1.5708 1.11022e-16 3.69779e-32"/>
      <geometry>
        <mesh filename="package://assets/stainless_steel_2mm__femur_mir.stl"/>
      </geometry>
      <material name="stainless_steel_2mm__femur_mir_material">
        <color rgba="0.74902 0.74902 0.74902 1"/>
      </material>
    </visual>
    <collision>
      <origin xyz="-0.014 0.07746 0.047" rpy="1.5708 1.11022e-16 3.69779e-32"/>
      <geometry>
        <mesh filename="package://assets/stainless_steel_2mm__femur_mir.stl"/>
      </geometry>
    </collision>
    <!-- Part stainless_steel_2mm__femur_mir_2 -->
    <visual>
      <origin xyz="-0.014 0.07746 -0.003" rpy="1.5708 -1.27882e-31 -1.2326e-32"/>
      <geometry>
        <mesh filename="package://assets/stainless_steel_2mm__femur_mir.stl"/>
      </geometry>
      <material name="stainless_steel_2mm__femur_mir_2_material">
        <color rgba="0.74902 0.74902 0.74902 1"/>
      </material>
    </visual>
    <collision>
      <origin xyz="-0.014 0.07746 -0.003" rpy="1.5708 -1.27882e-31 -1.2326e-32"/>
      <geometry>
        <mesh filename="package://assets/stainless_steel_2mm__femur_mir.stl"/>
      </geometry>
    </collision>
    <!-- Part almi_6_5mm_l_mx64_mir -->
    <visual>
      <origin xyz="-0.0134121 0.0859 0.0065" rpy="-1.5708 1.27882e-31 3.14159"/>
      <geometry>
        <mesh filename="package://assets/almi_6_5mm_l_mx64_mir.stl"/>
      </geometry>
      <material name="almi_6_5mm_l_mx64_mir_material">
        <color rgba="0.74902 0.74902 0.74902 1"/>
      </material>
    </visual>
    <collision>
      <origin xyz="-0.0134121 0.0859 0.0065" rpy="-1.5708 1.27882e-31 3.14159"/>
      <geometry>
        <mesh filename="package://assets/almi_6_5mm_l_mx64_mir.stl"/>
      </geometry>
    </collision>
    <!-- Part almi_6_5mm_l_mx64_mir_2 -->
    <visual>
      <origin xyz="-0.0134121 0.0859 0.047" rpy="-1.5708 -1.11022e-16 -3.14159"/>
      <geometry>
        <mesh filename="package://assets/almi_6_5mm_l_mx64_mir.stl"/>
      </geometry>
      <material name="almi_6_5mm_l_mx64_mir_2_material">
        <color rgba="0.74902 0.74902 0.74902 1"/>
      </material>
    </visual>
    <collision>
      <origin xyz="-0.0134121 0.0859 0.047" rpy="-1.5708 -1.11022e-16 -3.14159"/>
      <geometry>
        <mesh filename="package://assets/almi_6_5mm_l_mx64_mir.stl"/>
      </geometry>
    </collision>
    <!-- Part hn05_i101_mir -->
    <visual>
      <origin xyz="-9.85323e-16 0.134 0.04694" rpy="1.5708 1.14353e-14 1.5708"/>
      <geometry>
        <mesh filename="package://assets/hn05_i101_mir.stl"/>
      </geometry>
      <material name="hn05_i101_mir_material">
        <color rgba="0.74902 0.74902 0.74902 1"/>
      </material>
    </visual>
    <collision>
      <origin xyz="-9.85323e-16 0.134 0.04694" rpy="1.5708 1.14353e-14 1.5708"/>
      <geometry>
        <mesh filename="package://assets/hn05_i101_mir.stl"/>
      </geometry>
    </collision>
    <!-- Part rx64_cap_mir -->
    <visual>
      <origin xyz="-9.85323e-16 0.134 0.0467" rpy="3.14159 9.63118e-15 1.5708"/>
      <geometry>
        <mesh filename="package://assets/rx64_cap_mir.stl"/>
      </geometry>
      <material name="rx64_cap_mir_material">
        <color rgba="0.74902 0.74902 0.74902 1"/>
      </material>
    </visual>
    <collision>
      <origin xyz="-9.85323e-16 0.134 0.0467" rpy="3.14159 9.63118e-15 1.5708"/>
      <geometry>
        <mesh filename="package://assets/rx64_cap_mir.stl"/>
      </geometry>
    </collision>
    <!-- Part mf128zz_mir -->
    <visual>
      <origin xyz="-9.99201e-16 0.134 0.04322" rpy="1.5708 1.09912e-14 1.5708"/>
      <geometry>
        <mesh filename="package://assets/mf128zz_mir.stl"/>
      </geometry>
      <material name="mf128zz_mir_material">
        <color rgba="0.74902 0.74902 0.74902 1"/>
      </material>
    </visual>
    <collision>
      <origin xyz="-9.99201e-16 0.134 0.04322" rpy="1.5708 1.09912e-14 1.5708"/>
      <geometry>
        <mesh filename="package://assets/mf128zz_mir.stl"/>
      </geometry>
    </collision>
  </link>
  <!-- Link foot_left_3 -->
  <link name="foot_left_3">
    <inertial>
      <origin xyz="0.00350206 0.0535427 0.0235017" rpy="0 0 0"/>
      <mass value="0.157154"/>
      <inertia ixx="0.000266743" ixy="8.33375e-06" ixz="-5.26492e-09" iyy="0.000115972" iyz="6.48605e-09" izz="0.000200186"/>
    </inertial>
    <!-- Part stainless_steel_2mm_shinebone_mir -->
    <visual>
      <origin xyz="0.0135 0.0197269 0.05" rpy="-1.5708 8.88178e-16 -7.97973e-15"/>
      <geometry>
        <mesh filename="package://assets/stainless_steel_2mm_shinebone_mir.stl"/>
      </geometry>
      <material name="stainless_steel_2mm_shinebone_mir_material">
        <color rgba="0.74902 0.74902 0.74902 1"/>
      </material>
    </visual>
    <collision>
      <origin xyz="0.0135 0.0197269 0.05" rpy="-1.5708 8.88178e-16 -7.97973e-15"/>
      <geometry>
        <mesh filename="package://assets/stainless_steel_2mm_shinebone_mir.stl"/>
      </geometry>
    </collision>
    <!-- Part stainless_steel_2mm_leg_spacer_mir -->
    <visual>
      <origin xyz="0.024 0.0190814 0.045" rpy="1.11022e-15 1.83187e-15 1.5708"/>
      <geometry>
        <mesh filename="package://assets/stainless_steel_2mm_leg_spacer_mir.stl"/>
      </geometry>
      <material name="stainless_steel_2mm_leg_spacer_mir_material">
        <color rgba="0.74902 0.74902 0.74902 1"/>
      </material>
    </visual>
    <collision>
      <origin xyz="0.024 0.0190814 0.045" rpy="1.11022e-15 1.83187e-15 1.5708"/>
      <geometry>
        <mesh filename="package://assets/stainless_steel_2mm_leg_spacer_mir.stl"/>
      </geometry>
    </collision>
    <!-- Part stainless_steel_2mm_shinebone_mir_2 -->
    <visual>
      <origin xyz="0.0135 0.0197269 6.93889e-18" rpy="-1.5708 -9.24446e-33 -1.2326e-31"/>
      <geometry>
        <mesh filename="package://assets/stainless_steel_2mm_shinebone_mir.stl"/>
      </geometry>
      <material name="stainless_steel_2mm_shinebone_mir_2_material">
        <color rgba="0.74902 0.74902 0.74902 1"/>
      </material>
    </visual>
    <collision>
      <origin xyz="0.0135 0.0197269 6.93889e-18" rpy="-1.5708 -9.24446e-33 -1.2326e-31"/>
      <geometry>
        <mesh filename="package://assets/stainless_steel_2mm_shinebone_mir.stl"/>
      </geometry>
    </collision>
  </link>
  <!-- Link foot_left_4 -->
  <link name="foot_left_4">
    <inertial>
      <origin xyz="-0.0215978 0.0144559 -0.0236219" rpy="0 0 0"/>
      <mass value="0.292143"/>
      <inertia ixx="0.000112946" ixy="1.25975e-05" ixz="7.69402e-07" iyy="0.000262475" iyz="2.05066e-07" izz="0.000302507"/>
    </inertial>
    <!-- Part mx_64t_mir_2 -->
    <visual>
      <origin xyz="-0.04908 -1.11022e-15 -0.0235" rpy="3.14159 1.5708 0"/>
      <geometry>
        <mesh filename="package://assets/mx_64t_mir_2.stl"/>
      </geometry>
      <material name="mx_64t_mir_2_material">
        <color rgba="0.74902 0.74902 0.74902 1"/>
      </material>
    </visual>
    <collision>
      <origin xyz="-0.04908 -1.11022e-15 -0.0235" rpy="3.14159 1.5708 0"/>
      <geometry>
        <mesh filename="package://assets/mx_64t_mir_2.stl"/>
      </geometry>
    </collision>
    <!-- Part almi_2mm_connector_mx64_mir_1 -->
    <visual>
      <origin xyz="-0.015 0.015 -0.0425" rpy="1.5708 -9.10383e-15 -1.5708"/>
      <geometry>
        <mesh filename="package://assets/almi_2mm_connector_mx64_mir_1.stl"/>
      </geometry>
      <material name="almi_2mm_connector_mx64_mir_1_material">
        <color rgba="0.74902 0.74902 0.74902 1"/>
      </material>
    </visual>
    <collision>
      <origin xyz="-0.015 0.015 -0.0425" rpy="1.5708 -9.10383e-15 -1.5708"/>
      <geometry>
        <mesh filename="package://assets/almi_2mm_connector_mx64_mir_1.stl"/>
      </geometry>
    </collision>
    <!-- Part fr05_f101k_set_mir_1 -->
    <visual>
      <origin xyz="0.024 4.58208e-05 -0.0235" rpy="-1.5708 -3.0137e-30 1.5708"/>
      <geometry>
        <mesh filename="package://assets/fr05_f101k_set_mir_1.stl"/>
      </geometry>
      <material name="fr05_f101k_set_mir_1_material">
        <color rgba="0.74902 0.74902 0.74902 1"/>
      </material>
    </visual>
    <collision>
      <origin xyz="0.024 4.58208e-05 -0.0235" rpy="-1.5708 -3.0137e-30 1.5708"/>
      <geometry>
        <mesh filename="package://assets/fr05_f101k_set_mir_1.stl"/>
      </geometry>
    </collision>
    <!-- Part mx_64t_mir_2_2 -->
    <visual>
      <origin xyz="0 5.55112e-17 -0.0235" rpy="-3.14159 -8.47409e-33 -3.38964e-32"/>
      <geometry>
        <mesh filename="package://assets/mx_64t_mir_2.stl"/>
      </geometry>
      <material name="mx_64t_mir_2_2_material">
        <color rgba="0.74902 0.74902 0.74902 1"/>
      </material>
    </visual>
    <collision>
      <origin xyz="0 5.55112e-17 -0.0235" rpy="-3.14159 -8.47409e-33 -3.38964e-32"/>
      <geometry>
        <mesh filename="package://assets/mx_64t_mir_2.stl"/>
      </geometry>
    </collision>
    <!-- Part almi_2mm_fr05_f101k_set_mir_1 -->
    <visual>
      <origin xyz="0.024 4.44089e-16 -0.0235" rpy="-3.14159 1.55923e-30 -1.5708"/>
      <geometry>
        <mesh filename="package://assets/almi_2mm_fr05_f101k_set_mir_1.stl"/>
      </geometry>
      <material name="almi_2mm_fr05_f101k_set_mir_1_material">
        <color rgba="0.74902 0.74902 0.74902 1"/>
      </material>
    </visual>
    <collision>
      <origin xyz="0.024 4.44089e-16 -0.0235" rpy="-3.14159 1.55923e-30 -1.5708"/>
      <geometry>
        <mesh filename="package://assets/almi_2mm_fr05_f101k_set_mir_1.stl"/>
      </geometry>
    </collision>
    <!-- Part almi_2mm_connector_mx64_mir_1_2 -->
    <visual>
      <origin xyz="-0.015 0.043 -0.0045" rpy="-1.5708 -5.55112e-17 1.5708"/>
      <geometry>
        <mesh filename="package://assets/almi_2mm_connector_mx64_mir_1.stl"/>
      </geometry>
      <material name="almi_2mm_connector_mx64_mir_1_2_material">
        <color rgba="0.74902 0.74902 0.74902 1"/>
      </material>
    </visual>
    <collision>
      <origin xyz="-0.015 0.043 -0.0045" rpy="-1.5708 -5.55112e-17 1.5708"/>
      <geometry>
        <mesh filename="package://assets/almi_2mm_connector_mx64_mir_1.stl"/>
      </geometry>
    </collision>
    <!-- Part hn05_i101_mir_2 -->
    <visual>
      <origin xyz="0 5.55112e-17 -0.04694" rpy="-1.5708 -5.55112e-17 1.38778e-17"/>
      <geometry>
        <mesh filename="package://assets/hn05_i101_mir_2.stl"/>
      </geometry>
      <material name="hn05_i101_mir_2_material">
        <color rgba="0.74902 0.74902 0.74902 1"/>
      </material>
    </visual>
    <collision>
      <origin xyz="0 5.55112e-17 -0.04694" rpy="-1.5708 -5.55112e-17 1.38778e-17"/>
      <geometry>
        <mesh filename="package://assets/hn05_i101_mir_2.stl"/>
      </geometry>
    </collision>
    <!-- Part mf128zz_mir_2 -->
    <visual>
      <origin xyz="0 5.55112e-17 -0.04322" rpy="-1.5708 -5.55112e-17 1.38778e-17"/>
      <geometry>
        <mesh filename="package://assets/mf128zz_mir_2.stl"/>
      </geometry>
      <material name="mf128zz_mir_2_material">
        <color rgba="0.74902 0.74902 0.74902 1"/>
      </material>
    </visual>
    <collision>
      <origin xyz="0 5.55112e-17 -0.04322" rpy="-1.5708 -5.55112e-17 1.38778e-17"/>
      <geometry>
        <mesh filename="package://assets/mf128zz_mir_2.stl"/>
      </geometry>
    </collision>
    <!-- Part rx64_cap_mir_2 -->
    <visual>
      <origin xyz="1.38778e-17 5.55112e-17 -0.0467" rpy="-7.93809e-15 -5.55112e-17 1.38778e-17"/>
      <geometry>
        <mesh filename="package://assets/rx64_cap_mir_2.stl"/>
      </geometry>
      <material name="rx64_cap_mir_2_material">
        <color rgba="0.74902 0.74902 0.74902 1"/>
      </material>
    </visual>
    <collision>
      <origin xyz="1.38778e-17 5.55112e-17 -0.0467" rpy="-7.93809e-15 -5.55112e-17 1.38778e-17"/>
      <geometry>
        <mesh filename="package://assets/rx64_cap_mir_2.stl"/>
      </geometry>
    </collision>
    <!-- Part mf128zz_mir_2_2 -->
    <visual>
      <origin xyz="0.02622 4.58208e-05 -0.0235" rpy="3.14159 -3.24789e-30 1.5708"/>
      <geometry>
        <mesh filename="package://assets/mf128zz_mir_2.stl"/>
      </geometry>
      <material name="mf128zz_mir_2_2_material">
        <color rgba="0.74902 0.74902 0.74902 1"/>
      </material>
    </visual>
    <collision>
      <origin xyz="0.02622 4.58208e-05 -0.0235" rpy="3.14159 -3.24789e-30 1.5708"/>
      <geometry>
        <mesh filename="package://assets/mf128zz_mir_2.stl"/>
      </geometry>
    </collision>
    <!-- Part hn05_i101_mir_2_2 -->
    <visual>
      <origin xyz="0.02994 4.58208e-05 -0.0235" rpy="3.14159 -6.10751e-30 1.5708"/>
      <geometry>
        <mesh filename="package://assets/hn05_i101_mir_2.stl"/>
      </geometry>
      <material name="hn05_i101_mir_2_2_material">
        <color rgba="0.74902 0.74902 0.74902 1"/>
      </material>
    </visual>
    <collision>
      <origin xyz="0.02994 4.58208e-05 -0.0235" rpy="3.14159 -6.10751e-30 1.5708"/>
      <geometry>
        <mesh filename="package://assets/hn05_i101_mir_2.stl"/>
      </geometry>
    </collision>
    <!-- Part rx64_cap_mir_2_2 -->
    <visual>
      <origin xyz="0.0297 4.58208e-05 -0.0235" rpy="-1.5708 -2.96439e-30 1.5708"/>
      <geometry>
        <mesh filename="package://assets/rx64_cap_mir_2.stl"/>
      </geometry>
      <material name="rx64_cap_mir_2_2_material">
        <color rgba="0.74902 0.74902 0.74902 1"/>
      </material>
    </visual>
    <collision>
      <origin xyz="0.0297 4.58208e-05 -0.0235" rpy="-1.5708 -2.96439e-30 1.5708"/>
      <geometry>
        <mesh filename="package://assets/rx64_cap_mir_2.stl"/>
      </geometry>
    </collision>
  </link>
  <!-- Link foot_left_5 -->
  <link name="foot_left_5">
    <inertial>
      <origin xyz="-0.00577513 -0.0300863 -0.0389132" rpy="0 0 0"/>
      <mass value="0.229936"/>
      <inertia ixx="0.000336096" ixy="-2.89074e-06" ixz="-4.67383e-06" iyy="0.000437543" iyz="5.55837e-07" izz="0.000121048"/>
    </inertial>
    <!-- Part almi_2mm_lower_leg_mir -->
    <visual>
      <origin xyz="-0.00775 -0.032 -0.02876" rpy="3.14159 -1.5708 0"/>
      <geometry>
        <mesh filename="package://assets/almi_2mm_lower_leg_mir.stl"/>
      </geometry>
      <material name="almi_2mm_lower_leg_mir_material">
        <color rgba="0.74902 0.74902 0.74902 1"/>
      </material>
    </visual>
    <collision>
      <origin xyz="-0.00775 -0.032 -0.02876" rpy="3.14159 -1.5708 0"/>
      <geometry>
        <mesh filename="package://assets/almi_2mm_lower_leg_mir.stl"/>
      </geometry>
    </collision>
    <!-- Part stainless_steel_2mm_lower_leg_bracket_mir -->
    <visual>
      <origin xyz="-0.016 -0.032 -0.00052" rpy="1.5708 1.5708 0"/>
      <geometry>
        <mesh filename="package://assets/stainless_steel_2mm_lower_leg_bracket_mir.stl"/>
      </geometry>
      <material name="stainless_steel_2mm_lower_leg_bracket_mir_material">
        <color rgba="0.74902 0.74902 0.74902 1"/>
      </material>
    </visual>
    <collision>
      <origin xyz="-0.016 -0.032 -0.00052" rpy="1.5708 1.5708 0"/>
      <geometry>
        <mesh filename="package://assets/stainless_steel_2mm_lower_leg_bracket_mir.stl"/>
      </geometry>
    </collision>
    <!-- Part pla_50__shoes_mir -->
    <visual>
      <origin xyz="-0.04925 -0.032 -0.10376" rpy="1.31006e-14 1.5708 0"/>
      <geometry>
        <mesh filename="package://assets/pla_50__shoes_mir.stl"/>
      </geometry>
      <material name="pla_50__shoes_mir_material">
        <color rgba="0.74902 0.74902 0.74902 1"/>
      </material>
    </visual>
    <collision>
      <origin xyz="-0.04925 -0.032 -0.10376" rpy="1.31006e-14 1.5708 0"/>
      <geometry>
        <mesh filename="package://assets/pla_50__shoes_mir.stl"/>
      </geometry>
    </collision>
  </link>
  <!-- Joint from foot_left_4 to foot_left_5 -->
  <joint name="left_ankle_roll" type="revolute">
    <origin xyz="-0.02558 -4.996e-16 -0.0235" rpy="2.67286e-14 -1.5708 0"/>
    <parent link="foot_left_4"/>
    <child link="foot_left_5"/>
    <axis xyz="0 0 1"/>
    <limit effort="10" velocity="10" lower="-3.141592653589793" upper="3.141592653589793"/>
  </joint>
  <!-- Joint from foot_left_3 to foot_left_4 -->
  <joint name="left_ankle_pitch" type="revolute">
    <origin xyz="-8.32667e-17 0.111702 6.93889e-18" rpy="-3.14159 -1.66533e-15 9.78384e-15"/>
    <parent link="foot_left_3"/>
    <child link="foot_left_4"/>
    <axis xyz="0 0 1"/>
    <limit effort="10" velocity="10" lower="-3.141592653589793" upper="3.141592653589793"/>
  </joint>
  <!-- Joint from foot_left_2 to foot_left_3 -->
  <joint name="left_knee" type="revolute">
    <origin xyz="-1.11022e-15 0.134 -4.996e-16" rpy="-8.18789e-15 -3.88578e-16 4.17721e-15"/>
    <parent link="foot_left_2"/>
    <child link="foot_left_3"/>
    <axis xyz="0 0 1"/>
    <limit effort="10" velocity="10" lower="-3.141592653589793" upper="3.141592653589793"/>
  </joint>
  <!-- Joint from foot_left_1 to foot_left_2 -->
  <joint name="left_hip_pitch" type="revolute">
    <origin xyz="0.0235 1.80411e-15 0.02558" rpy="3.91354e-14 -1.5708 0"/>
    <parent link="foot_left_1"/>
    <child link="foot_left_2"/>
    <axis xyz="0 0 1"/>
    <limit effort="10" velocity="10" lower="-3.141592653589793" upper="3.141592653589793"/>
  </joint>
  <!-- Joint from stainless_steel_2mm_upper_leg_bracket_mir to foot_left_1 -->
  <joint name="left_hip_roll" type="revolute">
    <origin xyz="-0.0335 -3.56e-14 -0.032" rpy="-1.5708 -1.39333e-14 -1.5708"/>
    <parent link="stainless_steel_2mm_upper_leg_bracket_mir"/>
    <child link="foot_left_1"/>
    <axis xyz="0 0 1"/>
    <limit effort="10" velocity="10" lower="-3.141592653589793" upper="3.141592653589793"/>
  </joint>
  <!-- Joint from torso_kidsize25 to stainless_steel_2mm_upper_leg_bracket_mir -->
  <joint name="left_hip_yaw" type="revolute">
    <origin xyz="0.0981628 0.0255728 0.109005" rpy="3.14159 1.81799e-15 -2.77556e-16"/>
    <parent link="torso_kidsize25"/>
    <child link="stainless_steel_2mm_upper_leg_bracket_mir"/>
    <axis xyz="0 0 1"/>
    <limit effort="10" velocity="10" lower="-3.141592653589793" upper="3.141592653589793"/>
  </joint>
</robot>
